{
  "groundLevel": 0,
  "home": [
    6,
    6,
    6
  ],
  "blocks": [
    {
      "x": 0,
      "y": 4,
      "z": 2,
      "fuzzy": false,
      "block": "minecraft:torch",
      "worldMeta": 2,
      "stackMeta": 0,
      "needsSupportBlock": true,
      "rotationMetaTransform": [
        3,
        2,
        4,
        1
      ]
    },
    {
      "x": 0,
      "y": 4,
      "z": 7,
      "fuzzy": false,
      "block": "minecraft:torch",
      "worldMeta": 2,
      "stackMeta": 0,
      "needsSupportBlock": true,
      "rotationMetaTransform": [
        3,
        2,
        4,
        1
      ]
    },
    {
      "x": 1,
      "y": 0,
      "z": 0,
      "fuzzy": false,
      "block": "minecraft:cobblestone",
      "worldMeta": 0,
      "stackMeta": 0,
      "needsSupportBlock": false
    },
    {
      "x": 1,
      "y": 0,
      "z": 1,
      "fuzzy": false,
      "block": "minecraft:cobblestone",
      "worldMeta": 0,
      "stackMeta": 0,
      "needsSupportBlock": false
    },
    {
      "x": 1,
      "y": 0,
      "z": 2,
      "fuzzy": false,
      "block": "minecraft:log",
      "worldMeta": 0,
      "stackMeta": 0,
      "needsSupportBlock": false
    },
    {
      "x": 1,
      "y": 0,
      "z": 3,
      "fuzzy": false,
      "block": "minecraft:cobblestone",
      "worldMeta": 0,
      "stackMeta": 0,
      "needsSupportBlock": false
    },
    {
      "x": 1,
      "y": 0,
      "z": 4,
      "fuzzy": false,
      "block": "minecraft:cobblestone",
      "worldMeta": 0,
      "stackMeta": 0,
      "needsSupportBlock": false
    },
    {
      "x": 1,
      "y": 0,
      "z": 5,
      "fuzzy": false,
      "block": "minecraft:cobblestone",
      "worldMeta": 0,
      "stackMeta": 0,
      "needsSupportBlock": false
    },
    {
      "x": 1,
      "y": 0,
      "z": 6,
      "fuzzy": false,
      "block": "minecraft:cobblestone",
      "worldMeta": 0,
      "stackMeta": 0,
      "needsSupportBlock": false
    },
    {
      "x": 1,
      "y": 0,
      "z": 7,
      "fuzzy": false,
      "block": "minecraft:log",
      "worldMeta": 0,
      "stackMeta": 0,
      "needsSupportBlock": false
    },
    {
      "x": 1,
      "y": 1,
      "z": 0,
      "fuzzy": false,
      "block": "minecraft:cobblestone",
      "worldMeta": 0,
      "stackMeta": 0,
      "needsSupportBlock": false
    },
    {
      "x": 1,
      "y": 1,
      "z": 1,
      "fuzzy": false,
      "block": "minecraft:cobblestone",
      "worldMeta": 0,
      "stackMeta": 0,
      "needsSupportBlock": false
    },
    {
      "x": 1,
      "y": 1,
      "z": 2,
      "fuzzy": false,
      "block": "minecraft:log",
      "worldMeta": 0,
      "stackMeta": 0,
      "needsSupportBlock": false
    },
    {
      "x": 1,
      "y": 1,
      "z": 3,
      "fuzzy": false,
      "block": "minecraft:cobblestone",
      "worldMeta": 0,
      "stackMeta": 0,
      "needsSupportBlock": false
    },
    {
      "x": 1,
      "y": 1,
      "z": 4,
      "fuzzy": false,
      "block": "minecraft:cobblestone",
      "worldMeta": 0,
      "stackMeta": 0,
      "needsSupportBlock": false
    },
    {
      "x": 1,
      "y": 1,
      "z": 5,
      "fuzzy": false,
      "block": "minecraft:cobblestone",
      "worldMeta": 0,
      "stackMeta": 0,
      "needsSupportBlock": false
    },
    {
      "x": 1,
      "y": 1,
      "z": 6,
      "fuzzy": false,
      "block": "minecraft:cobblestone",
      "worldMeta": 0,
      "stackMeta": 0,
      "needsSupportBlock": false
    },
    {
      "x": 1,
      "y": 1,
      "z": 7,
      "fuzzy": false,
      "block": "minecraft:log",
      "worldMeta": 0,
      "stackMeta": 0,
      "needsSupportBlock": false
    },
    {
      "x": 1,
      "y": 2,
      "z": 0,
      "fuzzy": false,
      "block": "minecraft:planks",
      "worldMeta": 0,
      "stackMeta": 0,
      "needsSupportBlock": false
    },
    {
      "x": 1,
      "y": 2,
      "z": 1,
      "fuzzy": false,
      "block": "minecraft:oak_stairs",
      "worldMeta": 2,
      "stackMeta": 0,
      "needsSupportBlock": false,
      "rotationMetaTransform": [
        2,
        1,
        3,
        0
      ]
    },
    {
      "x": 1,
      "y": 2,
      "z": 2,
      "fuzzy": false,
      "block": "minecraft:log",
      "worldMeta": 0,
      "stackMeta": 0,
      "needsSupportBlock": false
    },
    {
      "x": 1,
      "y": 2,
      "z": 3,
      "fuzzy": false,
      "block": "minecraft:oak_stairs",
      "worldMeta": 3,
      "stackMeta": 0,
      "needsSupportBlock": false,
      "rotationMetaTransform": [
        2,
        1,
        3,
        0
      ]
    },
    {
      "x": 1,
      "y": 2,
      "z": 4,
      "fuzzy": false,
      "block": "minecraft:planks",
      "worldMeta": 0,
      "stackMeta": 0,
      "needsSupportBlock": false
    },
    {
      "x": 1,
      "y": 2,
      "z": 5,
      "fuzzy": false,
      "block": "minecraft:planks",
      "worldMeta": 0,
      "stackMeta": 0,
      "needsSupportBlock": false
    },
    {
      "x": 1,
      "y": 2,
      "z": 6,
      "fuzzy": false,
      "block": "minecraft:oak_stairs",
      "worldMeta": 2,
      "stackMeta": 0,
      "needsSupportBlock": false,
      "rotationMetaTransform": [
        2,
        1,
        3,
        0
      ]
    },
    {
      "x": 1,
      "y": 2,
      "z": 7,
      "fuzzy": false,
      "block": "minecraft:log",
      "worldMeta": 0,
      "stackMeta": 0,
      "needsSupportBlock": false
    },
    {
      "x": 1,
      "y": 3,
      "z": 0,
      "fuzzy": false,
      "block": "minecraft:planks",
      "worldMeta": 0,
      "stackMeta": 0,
      "needsSupportBlock": false
    },
    {
      "x": 1,
      "y": 3,
      "z": 1,
      "fuzzy": false,
      "block": "minecraft:oak_stairs",
      "worldMeta": 6,
      "stackMeta": 0,
      "needsSupportBlock": false,
      "rotationMetaTransform": [
        6,
        5,
        7,
        4
      ]
    },
    {
      "x": 1,
      "y": 3,
      "z": 2,
      "fuzzy": false,
      "block": "minecraft:log",
      "worldMeta": 0,
      "stackMeta": 0,
      "needsSupportBlock": false
    },
    {
      "x": 1,
      "y": 3,
      "z": 3,
      "fuzzy": false,
      "block": "minecraft:oak_stairs",
      "worldMeta": 7,
      "stackMeta": 0,
      "needsSupportBlock": false,
      "rotationMetaTransform": [
        6,
        5,
        7,
        4
      ]
    },
    {
      "x": 1,
      "y": 3,
      "z": 4,
      "fuzzy": false,
      "block": "minecraft:planks",
      "worldMeta": 0,
      "stackMeta": 0,
      "needsSupportBlock": false
    },
    {
      "x": 1,
      "y": 3,
      "z": 5,
      "fuzzy": false,
      "block": "minecraft:planks",
      "worldMeta": 0,
      "stackMeta": 0,
      "needsSupportBlock": false
    },
    {
      "x": 1,
      "y": 3,
      "z": 6,
      "fuzzy": false,
      "block": "minecraft:oak_stairs",
      "worldMeta": 6,
      "stackMeta": 0,
      "needsSupportBlock": false,
      "rotationMetaTransform": [
        6,
        5,
        7,
        4
      ]
    },
    {
      "x": 1,
      "y": 3,
      "z": 7,
      "fuzzy": false,
      "block": "minecraft:log",
      "worldMeta": 0,
      "stackMeta": 0,
      "needsSupportBlock": false
    },
    {
      "x": 1,
      "y": 4,
      "z": 0,
      "fuzzy": false,
      "block": "minecraft:log",
      "worldMeta": 8,
      "stackMeta": 0,
      "needsSupportBlock": false,
      "rotationMetaTransform": [
        4,
        8,
        4,
        8
      ]
    },
    {
      "x": 1,
      "y": 4,
      "z": 1,
      "fuzzy": false,
      "block": "minecraft:log",
      "worldMeta": 8,
      "stackMeta": 0,
      "needsSupportBlock": false,
      "rotationMetaTransform": [
        4,
        8,
        4,
        8
      ]
    },
    {
      "x": 1,
      "y": 4,
      "z": 2,
      "fuzzy": false,
      "block": "minecraft:log",
      "worldMeta": 4,
      "stackMeta": 0,
      "needsSupportBlock": false,
      "rotationMetaTransform": [
        4,
        8,
        4,
        8
      ]
    },
    {
      "x": 1,
      "y": 4,
      "z": 3,
      "fuzzy": false,
      "block": "minecraft:log",
      "worldMeta": 8,
      "stackMeta": 0,
      "needsSupportBlock": false,
      "rotationMetaTransform": [
        4,
        8,
        4,
        8
      ]
    },
    {
      "x": 1,
      "y": 4,
      "z": 4,
      "fuzzy": false,
      "block": "minecraft:log",
      "worldMeta": 8,
      "stackMeta": 0,
      "needsSupportBlock": false,
      "rotationMetaTransform": [
        4,
        8,
        4,
        8
      ]
    },
    {
      "x": 1,
      "y": 4,
      "z": 5,
      "fuzzy": false,
      "block": "minecraft:log",
      "worldMeta": 8,
      "stackMeta": 0,
      "needsSupportBlock": false,
      "rotationMetaTransform": [
        4,
        8,
        4,
        8
      ]
    },
    {
      "x": 1,
      "y": 4,
      "z": 6,
      "fuzzy": false,
      "block": "minecraft:log",
      "worldMeta": 8,
      "stackMeta": 0,
      "needsSupportBlock": false,
      "rotationMetaTransform": [
        4,
        8,
        4,
        8
      ]
    },
    {
      "x": 1,
      "y": 4,
      "z": 7,
      "fuzzy": false,
      "block": "minecraft:log",
      "worldMeta": 0,
      "stackMeta": 0,
      "needsSupportBlock": false
    },
    {
      "x": 1,
      "y": 4,
      "z": 8,
      "fuzzy": false,
      "block": "minecraft:torch",
      "worldMeta": 3,
      "stackMeta": 0,
      "needsSupportBlock": true,
      "rotationMetaTransform": [
        3,
        2,
        4,
        1
      ]
    },
    {
      "x": 2,
      "y": 0,
      "z": 0,
      "fuzzy": false,
      "block": "minecraft:cobblestone",
      "worldMeta": 0,
      "stackMeta": 0,
      "needsSupportBlock": false
    },
    {
      "x": 2,
      "y": 0,
      "z": 1,
      "fuzzy": false,
      "block": "minecraft:cobblestone",
      "worldMeta": 0,
      "stackMeta": 0,
      "needsSupportBlock": false
    },
    {
      "x": 2,
      "y": 0,
      "z": 2,
      "fuzzy": false,
      "block": "minecraft:cobblestone",
      "worldMeta": 0,
      "stackMeta": 0,
      "needsSupportBlock": false
    },
    {
      "x": 2,
      "y": 0,
      "z": 3,
      "fuzzy": false,
      "block": "minecraft:cobblestone",
      "worldMeta": 0,
      "stackMeta": 0,
      "needsSupportBlock": false
    },
    {
      "x": 2,
      "y": 0,
      "z": 4,
      "fuzzy": false,
      "block": "minecraft:cobblestone",
      "worldMeta": 0,
      "stackMeta": 0,
      "needsSupportBlock": false
    },
    {
      "x": 2,
      "y": 0,
      "z": 5,
      "fuzzy": false,
      "block": "minecraft:cobblestone",
      "worldMeta": 0,
      "stackMeta": 0,
      "needsSupportBlock": false
    },
    {
      "x": 2,
      "y": 0,
      "z": 6,
      "fuzzy": false,
      "block": "minecraft:cobblestone",
      "worldMeta": 0,
      "stackMeta": 0,
      "needsSupportBlock": false
    },
    {
      "x": 2,
      "y": 0,
      "z": 7,
      "fuzzy": false,
      "block": "minecraft:cobblestone",
      "worldMeta": 0,
      "stackMeta": 0,
      "needsSupportBlock": false
    },
    {
      "x": 2,
      "y": 1,
      "z": 7,
      "fuzzy": false,
      "block": "minecraft:cobblestone",
      "worldMeta": 0,
      "stackMeta": 0,
      "needsSupportBlock": false
    },
    {
      "x": 2,
      "y": 2,
      "z": 7,
      "fuzzy": false,
      "block": "minecraft:oak_stairs",
      "worldMeta": 1,
      "stackMeta": 0,
      "needsSupportBlock": false,
      "rotationMetaTransform": [
        2,
        1,
        3,
        0
      ]
    },
    {
      "x": 2,
      "y": 3,
      "z": 7,
      "fuzzy": false,
      "block": "minecraft:oak_stairs",
      "worldMeta": 5,
      "stackMeta": 0,
      "needsSupportBlock": false,
      "rotationMetaTransform": [
        6,
        5,
        7,
        4
      ]
    },
    {
      "x": 2,
      "y": 4,
      "z": 0,
      "fuzzy": false,
      "block": "minecraft:planks",
      "worldMeta": 0,
      "stackMeta": 0,
      "needsSupportBlock": false
    },
    {
      "x": 2,
      "y": 4,
      "z": 1,
      "fuzzy": false,
      "block": "minecraft:planks",
      "worldMeta": 0,
      "stackMeta": 0,
      "needsSupportBlock": false
    },
    {
      "x": 2,
      "y": 4,
      "z": 2,
      "fuzzy": false,
      "block": "minecraft:log",
      "worldMeta": 4,
      "stackMeta": 0,
      "needsSupportBlock": false,
      "rotationMetaTransform": [
        4,
        8,
        4,
        8
      ]
    },
    {
      "x": 2,
      "y": 4,
      "z": 3,
      "fuzzy": false,
      "block": "minecraft:planks",
      "worldMeta": 0,
      "stackMeta": 0,
      "needsSupportBlock": false
    },
    {
      "x": 2,
      "y": 4,
      "z": 4,
      "fuzzy": false,
      "block": "minecraft:planks",
      "worldMeta": 0,
      "stackMeta": 0,
      "needsSupportBlock": false
    },
    {
      "x": 2,
      "y": 4,
      "z": 5,
      "fuzzy": false,
      "block": "minecraft:planks",
      "worldMeta": 0,
      "stackMeta": 0,
      "needsSupportBlock": false
    },
    {
      "x": 2,
      "y": 4,
      "z": 6,
      "fuzzy": false,
      "block": "minecraft:planks",
      "worldMeta": 0,
      "stackMeta": 0,
      "needsSupportBlock": false
    },
    {
      "x": 2,
      "y": 4,
      "z": 7,
      "fuzzy": false,
      "block": "minecraft:log",
      "worldMeta": 4,
      "stackMeta": 0,
      "needsSupportBlock": false,
      "rotationMetaTransform": [
        4,
        8,
        4,
        8
      ]
    },
    {
      "x": 3,
      "y": 0,
      "z": 0,
      "fuzzy": false,
      "block": "minecraft:cobblestone",
      "worldMeta": 0,
      "stackMeta": 0,
      "needsSupportBlock": false
    },
    {
      "x": 3,
      "y": 0,
      "z": 1,
      "fuzzy": false,
      "block": "minecraft:cobblestone",
      "worldMeta": 0,
      "stackMeta": 0,
      "needsSupportBlock": false
    },
    {
      "x": 3,
      "y": 0,
      "z": 2,
      "fuzzy": false,
      "block": "minecraft:cobblestone",
      "worldMeta": 0,
      "stackMeta": 0,
      "needsSupportBlock": false
    },
    {
      "x": 3,
      "y": 0,
      "z": 3,
      "fuzzy": false,
      "block": "minecraft:cobblestone",
      "worldMeta": 0,
      "stackMeta": 0,
      "needsSupportBlock": false
    },
    {
      "x": 3,
      "y": 0,
      "z": 4,
      "fuzzy": false,
      "block": "minecraft:cobblestone",
      "worldMeta": 0,
      "stackMeta": 0,
      "needsSupportBlock": false
    },
    {
      "x": 3,
      "y": 0,
      "z": 5,
      "fuzzy": false,
      "block": "minecraft:cobblestone",
      "worldMeta": 0,
      "stackMeta": 0,
      "needsSupportBlock": false
    },
    {
      "x": 3,
      "y": 0,
      "z": 6,
      "fuzzy": false,
      "block": "minecraft:cobblestone",
      "worldMeta": 0,
      "stackMeta": 0,
      "needsSupportBlock": false
    },
    {
      "x": 3,
      "y": 0,
      "z": 7,
      "fuzzy": false,
      "block": "minecraft:cobblestone",
      "worldMeta": 0,
      "stackMeta": 0,
      "needsSupportBlock": false
    },
    {
      "x": 3,
      "y": 1,
      "z": 0,
      "fuzzy": false,
      "block": "minecraft:stone_stairs",
      "worldMeta": 0,
      "stackMeta": 0,
      "needsSupportBlock": false,
      "rotationMetaTransform": [
        2,
        1,
        3,
        0
      ]
    },
    {
      "x": 3,
      "y": 1,
      "z": 1,
      "fuzzy": false,
      "block": "minecraft:stone_stairs",
      "worldMeta": 0,
      "stackMeta": 0,
      "needsSupportBlock": false,
      "rotationMetaTransform": [
        2,
        1,
        3,
        0
      ]
    },
    {
      "x": 3,
      "y": 1,
      "z": 2,
      "fuzzy": false,
      "block": "minecraft:stone_stairs",
      "worldMeta": 0,
      "stackMeta": 0,
      "needsSupportBlock": false,
      "rotationMetaTransform": [
        2,
        1,
        3,
        0
      ]
    },
    {
      "x": 3,
      "y": 1,
      "z": 3,
      "fuzzy": false,
      "block": "minecraft:stone_stairs",
      "worldMeta": 0,
      "stackMeta": 0,
      "needsSupportBlock": false,
      "rotationMetaTransform": [
        2,
        1,
        3,
        0
      ]
    },
    {
      "x": 3,
      "y": 1,
      "z": 4,
      "fuzzy": false,
      "block": "minecraft:stone_stairs",
      "worldMeta": 0,
      "stackMeta": 0,
      "needsSupportBlock": false,
      "rotationMetaTransform": [
        2,
        1,
        3,
        0
      ]
    },
    {
      "x": 3,
      "y": 1,
      "z": 5,
      "fuzzy": false,
      "block": "minecraft:stone_stairs",
      "worldMeta": 0,
      "stackMeta": 0,
      "needsSupportBlock": false,
      "rotationMetaTransform": [
        2,
        1,
        3,
        0
      ]
    },
    {
      "x": 3,
      "y": 1,
      "z": 7,
      "fuzzy": false,
      "block": "minecraft:cobblestone",
      "worldMeta": 0,
      "stackMeta": 0,
      "needsSupportBlock": false
    },
    {
      "x": 3,
      "y": 2,
      "z": 1,
      "fuzzy": false,
      "block": "minecraft:ladder",
      "worldMeta": 4,
      "stackMeta": 0,
      "needsSupportBlock": true,
      "rotationMetaTransform": [
        5,
        3,
        4,
        2
      ]
    },
    {
      "x": 3,
      "y": 2,
      "z": 7,
      "fuzzy": false,
      "block": "minecraft:planks",
      "worldMeta": 0,
      "stackMeta": 0,
      "needsSupportBlock": false
    },
    {
      "x": 3,
      "y": 3,
      "z": 1,
      "fuzzy": false,
      "block": "minecraft:ladder",
      "worldMeta": 4,
      "stackMeta": 0,
      "needsSupportBlock": true,
      "rotationMetaTransform": [
        5,
        3,
        4,
        2
      ]
    },
    {
      "x": 3,
      "y": 3,
      "z": 2,
      "fuzzy": false,
      "block": "minecraft:torch",
      "worldMeta": 2,
      "stackMeta": 0,
      "needsSupportBlock": true,
      "rotationMetaTransform": [
        3,
        2,
        4,
        1
      ]
    },
    {
      "x": 3,
      "y": 3,
      "z": 4,
      "fuzzy": false,
      "block": "minecraft:torch",
      "worldMeta": 2,
      "stackMeta": 0,
      "needsSupportBlock": true,
      "rotationMetaTransform": [
        3,
        2,
        4,
        1
      ]
    },
    {
      "x": 3,
      "y": 3,
      "z": 7,
      "fuzzy": false,
      "block": "minecraft:planks",
      "worldMeta": 0,
      "stackMeta": 0,
      "needsSupportBlock": false
    },
    {
      "x": 3,
      "y": 4,
      "z": 0,
      "fuzzy": false,
      "block": "minecraft:planks",
      "worldMeta": 0,
      "stackMeta": 0,
      "needsSupportBlock": false
    },
    {
      "x": 3,
      "y": 4,
      "z": 1,
      "fuzzy": false,
      "block": "minecraft:ladder",
      "worldMeta": 4,
      "stackMeta": 0,
      "needsSupportBlock": true,
      "rotationMetaTransform": [
        5,
        3,
        4,
        2
      ]
    },
    {
      "x": 3,
      "y": 4,
      "z": 2,
      "fuzzy": false,
      "block": "minecraft:log",
      "worldMeta": 4,
      "stackMeta": 0,
      "needsSupportBlock": false,
      "rotationMetaTransform": [
        4,
        8,
        4,
        8
      ]
    },
    {
      "x": 3,
      "y": 4,
      "z": 3,
      "fuzzy": false,
      "block": "minecraft:planks",
      "worldMeta": 0,
      "stackMeta": 0,
      "needsSupportBlock": false
    },
    {
      "x": 3,
      "y": 4,
      "z": 4,
      "fuzzy": false,
      "block": "minecraft:planks",
      "worldMeta": 0,
      "stackMeta": 0,
      "needsSupportBlock": false
    },
    {
      "x": 3,
      "y": 4,
      "z": 5,
      "fuzzy": false,
      "block": "minecraft:planks",
      "worldMeta": 0,
      "stackMeta": 0,
      "needsSupportBlock": false
    },
    {
      "x": 3,
      "y": 4,
      "z": 6,
      "fuzzy": false,
      "block": "minecraft:planks",
      "worldMeta": 0,
      "stackMeta": 0,
      "needsSupportBlock": false
    },
    {
      "x": 3,
      "y": 4,
      "z": 7,
      "fuzzy": false,
      "block": "minecraft:log",
      "worldMeta": 4,
      "stackMeta": 0,
      "needsSupportBlock": false,
      "rotationMetaTransform": [
        4,
        8,
        4,
        8
      ]
    },
    {
      "x": 4,
      "y": 0,
      "z": 0,
      "fuzzy": false,
      "block": "minecraft:cobblestone",
      "worldMeta": 0,
      "stackMeta": 0,
      "needsSupportBlock": false
    },
    {
      "x": 4,
      "y": 0,
      "z": 1,
      "fuzzy": false,
      "block": "minecraft:cobblestone",
      "worldMeta": 0,
      "stackMeta": 0,
      "needsSupportBlock": false
    },
    {
      "x": 4,
      "y": 0,
      "z": 2,
      "fuzzy": false,
      "block": "minecraft:log",
      "worldMeta": 0,
      "stackMeta": 0,
      "needsSupportBlock": false
    },
    {
      "x": 4,
      "y": 0,
      "z": 3,
      "fuzzy": false,
      "block": "minecraft:cobblestone",
      "worldMeta": 0,
      "stackMeta": 0,
      "needsSupportBlock": false
    },
    {
      "x": 4,
      "y": 0,
      "z": 4,
      "fuzzy": false,
      "block": "minecraft:log",
      "worldMeta": 0,
      "stackMeta": 0,
      "needsSupportBlock": false
    },
    {
      "x": 4,
      "y": 0,
      "z": 5,
      "fuzzy": false,
      "block": "minecraft:cobblestone",
      "worldMeta": 0,
      "stackMeta": 0,
      "needsSupportBlock": false
    },
    {
      "x": 4,
      "y": 0,
      "z": 6,
      "fuzzy": false,
      "block": "minecraft:cobblestone",
      "worldMeta": 0,
      "stackMeta": 0,
      "needsSupportBlock": false
    },
    {
      "x": 4,
      "y": 0,
      "z": 7,
      "fuzzy": false,
      "block": "minecraft:cobblestone",
      "worldMeta": 0,
      "stackMeta": 0,
      "needsSupportBlock": false
    },
    {
      "x": 4,
      "y": 1,
      "z": 0,
      "fuzzy": false,
      "block": "minecraft:cobblestone",
      "worldMeta": 0,
      "stackMeta": 0,
      "needsSupportBlock": false
    },
    {
      "x": 4,
      "y": 1,
      "z": 1,
      "fuzzy": false,
      "block": "minecraft:cobblestone",
      "worldMeta": 0,
      "stackMeta": 0,
      "needsSupportBlock": false
    },
    {
      "x": 4,
      "y": 1,
      "z": 2,
      "fuzzy": false,
      "block": "minecraft:log",
      "worldMeta": 0,
      "stackMeta": 0,
      "needsSupportBlock": false
    },
    {
      "x": 4,
      "y": 1,
      "z": 3,
      "fuzzy": false,
      "block": "minecraft:cobblestone",
      "worldMeta": 0,
      "stackMeta": 0,
      "needsSupportBlock": false
    },
    {
      "x": 4,
      "y": 1,
      "z": 4,
      "fuzzy": false,
      "block": "minecraft:log",
      "worldMeta": 0,
      "stackMeta": 0,
      "needsSupportBlock": false
    },
    {
      "x": 4,
      "y": 1,
      "z": 5,
      "fuzzy": false,
      "block": "minecraft:stone_stairs",
      "worldMeta": 3,
      "stackMeta": 0,
      "needsSupportBlock": false,
      "rotationMetaTransform": [
        2,
        1,
        3,
        0
      ]
    },
    {
      "x": 4,
      "y": 1,
      "z": 7,
      "fuzzy": false,
      "block": "minecraft:cobblestone",
      "worldMeta": 0,
      "stackMeta": 0,
      "needsSupportBlock": false
    },
    {
      "x": 4,
      "y": 2,
      "z": 0,
      "fuzzy": false,
      "block": "minecraft:cobblestone",
      "worldMeta": 0,
      "stackMeta": 0,
      "needsSupportBlock": false
    },
    {
      "x": 4,
      "y": 2,
      "z": 1,
      "fuzzy": false,
      "block": "minecraft:cobblestone",
      "worldMeta": 0,
      "stackMeta": 0,
      "needsSupportBlock": false
    },
    {
      "x": 4,
      "y": 2,
      "z": 2,
      "fuzzy": false,
      "block": "minecraft:log",
      "worldMeta": 0,
      "stackMeta": 0,
      "needsSupportBlock": false
    },
    {
      "x": 4,
      "y": 2,
      "z": 3,
      "fuzzy": false,
      "block": "minecraft:cobblestone",
      "worldMeta": 0,
      "stackMeta": 0,
      "needsSupportBlock": false
    },
    {
      "x": 4,
      "y": 2,
      "z": 4,
      "fuzzy": false,
      "block": "minecraft:log",
      "worldMeta": 0,
      "stackMeta": 0,
      "needsSupportBlock": false
    },
    {
      "x": 4,
      "y": 2,
      "z": 7,
      "fuzzy": false,
      "block": "minecraft:planks",
      "worldMeta": 0,
      "stackMeta": 0,
      "needsSupportBlock": false
    },
    {
      "x": 4,
      "y": 3,
      "z": 0,
      "fuzzy": false,
      "block": "minecraft:log",
      "worldMeta": 8,
      "stackMeta": 0,
      "needsSupportBlock": false,
      "rotationMetaTransform": [
        4,
        8,
        4,
        8
      ]
    },
    {
      "x": 4,
      "y": 3,
      "z": 1,
      "fuzzy": false,
      "block": "minecraft:log",
      "worldMeta": 8,
      "stackMeta": 0,
      "needsSupportBlock": false,
      "rotationMetaTransform": [
        4,
        8,
        4,
        8
      ]
    },
    {
      "x": 4,
      "y": 3,
      "z": 2,
      "fuzzy": false,
      "block": "minecraft:log",
      "worldMeta": 0,
      "stackMeta": 0,
      "needsSupportBlock": false
    },
    {
      "x": 4,
      "y": 3,
      "z": 3,
      "fuzzy": false,
      "block": "minecraft:log",
      "worldMeta": 8,
      "stackMeta": 0,
      "needsSupportBlock": false,
      "rotationMetaTransform": [
        4,
        8,
        4,
        8
      ]
    },
    {
      "x": 4,
      "y": 3,
      "z": 4,
      "fuzzy": false,
      "block": "minecraft:log",
      "worldMeta": 0,
      "stackMeta": 0,
      "needsSupportBlock": false
    },
    {
      "x": 4,
      "y": 3,
      "z": 5,
      "fuzzy": false,
      "block": "minecraft:torch",
      "worldMeta": 3,
      "stackMeta": 0,
      "needsSupportBlock": true,
      "rotationMetaTransform": [
        3,
        2,
        4,
        1
      ]
    },
    {
      "x": 4,
      "y": 3,
      "z": 7,
      "fuzzy": false,
      "block": "minecraft:planks",
      "worldMeta": 0,
      "stackMeta": 0,
      "needsSupportBlock": false
    },
    {
      "x": 4,
      "y": 4,
      "z": 0,
      "fuzzy": false,
      "block": "minecraft:planks",
      "worldMeta": 0,
      "stackMeta": 0,
      "needsSupportBlock": false
    },
    {
      "x": 4,
      "y": 4,
      "z": 1,
      "fuzzy": false,
      "block": "minecraft:planks",
      "worldMeta": 0,
      "stackMeta": 0,
      "needsSupportBlock": false
    },
    {
      "x": 4,
      "y": 4,
      "z": 2,
      "fuzzy": false,
      "block": "minecraft:log",
      "worldMeta": 0,
      "stackMeta": 0,
      "needsSupportBlock": false
    },
    {
      "x": 4,
      "y": 4,
      "z": 3,
      "fuzzy": false,
      "block": "minecraft:planks",
      "worldMeta": 0,
      "stackMeta": 0,
      "needsSupportBlock": false
    },
    {
      "x": 4,
      "y": 4,
      "z": 4,
      "fuzzy": false,
      "block": "minecraft:planks",
      "worldMeta": 0,
      "stackMeta": 0,
      "needsSupportBlock": false
    },
    {
      "x": 4,
      "y": 4,
      "z": 5,
      "fuzzy": false,
      "block": "minecraft:planks",
      "worldMeta": 0,
      "stackMeta": 0,
      "needsSupportBlock": false
    },
    {
      "x": 4,
      "y": 4,
      "z": 6,
      "fuzzy": false,
      "block": "minecraft:planks",
      "worldMeta": 0,
      "stackMeta": 0,
      "needsSupportBlock": false
    },
    {
      "x": 4,
      "y": 4,
      "z": 7,
      "fuzzy": false,
      "block": "minecraft:log",
      "worldMeta": 4,
      "stackMeta": 0,
      "needsSupportBlock": false,
      "rotationMetaTransform": [
        4,
        8,
        4,
        8
      ]
    },
    {
      "x": 4,
      "y": 5,
      "z": 0,
      "fuzzy": false,
      "block": "minecraft:fence",
      "worldMeta": 0,
      "stackMeta": 0,
      "needsSupportBlock": false
    },
    {
      "x": 4,
      "y": 5,
      "z": 1,
      "fuzzy": false,
      "block": "minecraft:fence",
      "worldMeta": 0,
      "stackMeta": 0,
      "needsSupportBlock": false
    },
    {
      "x": 4,
      "y": 5,
      "z": 2,
      "fuzzy": false,
      "block": "minecraft:log",
      "worldMeta": 0,
      "stackMeta": 0,
      "needsSupportBlock": false
    },
    {
      "x": 4,
      "y": 5,
      "z": 3,
      "fuzzy": false,
      "block": "minecraft:fence",
      "worldMeta": 0,
      "stackMeta": 0,
      "needsSupportBlock": false
    },
    {
      "x": 4,
      "y": 5,
      "z": 4,
      "fuzzy": false,
      "block": "minecraft:fence",
      "worldMeta": 0,
      "stackMeta": 0,
      "needsSupportBlock": false
    },
    {
      "x": 4,
      "y": 6,
      "z": 2,
      "fuzzy": false,
      "block": "minecraft:torch",
      "worldMeta": 5,
      "stackMeta": 0,
      "needsSupportBlock": true
    },
    {
      "x": 5,
      "y": 0,
      "z": 0,
      "fuzzy": false,
      "block": "minecraft:grass",
      "worldMeta": 0,
      "stackMeta": 0,
      "needsSupportBlock": false
    },
    {
      "x": 5,
      "y": 0,
      "z": 1,
      "fuzzy": false,
      "block": "minecraft:grass",
      "worldMeta": 0,
      "stackMeta": 0,
      "needsSupportBlock": false
    },
    {
      "x": 5,
      "y": 0,
      "z": 2,
      "fuzzy": false,
      "block": "minecraft:grass",
      "worldMeta": 0,
      "stackMeta": 0,
      "needsSupportBlock": false
    },
    {
      "x": 5,
      "y": 0,
      "z": 3,
      "fuzzy": false,
      "block": "minecraft:grass",
      "worldMeta": 0,
      "stackMeta": 0,
      "needsSupportBlock": false
    },
    {
      "x": 5,
      "y": 0,
      "z": 4,
      "fuzzy": false,
      "block": "minecraft:cobblestone",
      "worldMeta": 0,
      "stackMeta": 0,
      "needsSupportBlock": false
    },
    {
      "x": 5,
      "y": 0,
      "z": 5,
      "fuzzy": false,
      "block": "minecraft:cobblestone",
      "worldMeta": 0,
      "stackMeta": 0,
      "needsSupportBlock": false
    },
    {
      "x": 5,
      "y": 0,
      "z": 6,
      "fuzzy": false,
      "block": "minecraft:cobblestone",
      "worldMeta": 0,
      "stackMeta": 0,
      "needsSupportBlock": false
    },
    {
      "x": 5,
      "y": 0,
      "z": 7,
      "fuzzy": false,
      "block": "minecraft:cobblestone",
      "worldMeta": 0,
      "stackMeta": 0,
      "needsSupportBlock": false
    },
    {
      "x": 5,
      "y": 1,
      "z": 4,
      "fuzzy": false,
      "block": "minecraft:cobblestone",
      "worldMeta": 0,
      "stackMeta": 0,
      "needsSupportBlock": false
    },
    {
      "x": 5,
      "y": 1,
      "z": 5,
      "fuzzy": false,
      "block": "minecraft:stone_stairs",
      "worldMeta": 3,
      "stackMeta": 0,
      "needsSupportBlock": false,
      "rotationMetaTransform": [
        2,
        1,
        3,
        0
      ]
    },
    {
      "x": 5,
      "y": 1,
      "z": 7,
      "fuzzy": false,
      "block": "minecraft:cobblestone",
      "worldMeta": 0,
      "stackMeta": 0,
      "needsSupportBlock": false
    },
    {
      "x": 5,
      "y": 2,
      "z": 0,
      "fuzzy": false,
      "block": "minecraft:trapdoor",
      "worldMeta": 15,
      "stackMeta": 0,
      "needsSupportBlock": true,
      "rotationMetaTransform": [
        15,
        13,
        14,
        12
      ]
    },
    {
      "x": 5,
      "y": 2,
      "z": 1,
      "fuzzy": false,
      "block": "minecraft:trapdoor",
      "worldMeta": 15,
      "stackMeta": 0,
      "needsSupportBlock": true,
      "rotationMetaTransform": [
        15,
        13,
        14,
        12
      ]
    },
    {
      "x": 5,
      "y": 2,
      "z": 2,
      "fuzzy": false,
      "block": "minecraft:torch",
      "worldMeta": 1,
      "stackMeta": 0,
      "needsSupportBlock": true,
      "rotationMetaTransform": [
        3,
        2,
        4,
        1
      ]
    },
    {
      "x": 5,
      "y": 2,
      "z": 3,
      "fuzzy": false,
      "block": "minecraft:fence",
      "worldMeta": 0,
      "stackMeta": 0,
      "needsSupportBlock": false
    },
    {
      "x": 5,
      "y": 2,
      "z": 4,
      "fuzzy": false,
      "block": "minecraft:cobblestone",
      "worldMeta": 0,
      "stackMeta": 0,
      "needsSupportBlock": false
    },
    {
      "x": 5,
      "y": 2,
      "z": 5,
      "fuzzy": false,
      "block": "minecraft:ladder",
      "worldMeta": 3,
      "stackMeta": 0,
      "needsSupportBlock": true,
      "rotationMetaTransform": [
        5,
        3,
        4,
        2
      ]
    },
    {
      "x": 5,
      "y": 2,
      "z": 7,
      "fuzzy": false,
      "block": "minecraft:oak_stairs",
      "worldMeta": 0,
      "stackMeta": 0,
      "needsSupportBlock": false,
      "rotationMetaTransform": [
        2,
        1,
        3,
        0
      ]
    },
    {
      "x": 5,
      "y": 3,
      "z": 2,
      "fuzzy": false,
      "block": "minecraft:log",
      "worldMeta": 4,
      "stackMeta": 0,
      "needsSupportBlock": false,
      "rotationMetaTransform": [
        4,
        8,
        4,
        8
      ]
    },
    {
      "x": 5,
      "y": 3,
      "z": 4,
      "fuzzy": false,
      "block": "minecraft:log",
      "worldMeta": 4,
      "stackMeta": 0,
      "needsSupportBlock": false,
      "rotationMetaTransform": [
        4,
        8,
        4,
        8
      ]
    },
    {
      "x": 5,
      "y": 3,
      "z": 5,
      "fuzzy": false,
      "block": "minecraft:ladder",
      "worldMeta": 3,
      "stackMeta": 0,
      "needsSupportBlock": true,
      "rotationMetaTransform": [
        5,
        3,
        4,
        2
      ]
    },
    {
      "x": 5,
      "y": 3,
      "z": 7,
      "fuzzy": false,
      "block": "minecraft:oak_stairs",
      "worldMeta": 4,
      "stackMeta": 0,
      "needsSupportBlock": false,
      "rotationMetaTransform": [
        6,
        5,
        7,
        4
      ]
    },
    {
      "x": 5,
      "y": 4,
      "z": 0,
      "fuzzy": false,
      "block": "minecraft:brick_stairs",
      "worldMeta": 1,
      "stackMeta": 0,
      "needsSupportBlock": false,
      "rotationMetaTransform": [
        2,
        1,
        3,
        0
      ]
    },
    {
      "x": 5,
      "y": 4,
      "z": 1,
      "fuzzy": false,
      "block": "minecraft:brick_stairs",
      "worldMeta": 1,
      "stackMeta": 0,
      "needsSupportBlock": false,
      "rotationMetaTransform": [
        2,
        1,
        3,
        0
      ]
    },
    {
      "x": 5,
      "y": 4,
      "z": 2,
      "fuzzy": false,
      "block": "minecraft:brick_stairs",
      "worldMeta": 1,
      "stackMeta": 0,
      "needsSupportBlock": false,
      "rotationMetaTransform": [
        2,
        1,
        3,
        0
      ]
    },
    {
      "x": 5,
      "y": 4,
      "z": 3,
      "fuzzy": false,
      "block": "minecraft:brick_stairs",
      "worldMeta": 2,
      "stackMeta": 0,
      "needsSupportBlock": false,
      "rotationMetaTransform": [
        2,
        1,
        3,
        0
      ]
    },
    {
      "x": 5,
      "y": 4,
      "z": 4,
      "fuzzy": false,
      "block": "minecraft:planks",
      "worldMeta": 0,
      "stackMeta": 0,
      "needsSupportBlock": false
    },
    {
      "x": 5,
      "y": 4,
      "z": 5,
      "fuzzy": false,
      "block": "minecraft:ladder",
      "worldMeta": 3,
      "stackMeta": 0,
      "needsSupportBlock": true,
      "rotationMetaTransform": [
        5,
        3,
        4,
        2
      ]
    },
    {
      "x": 5,
      "y": 4,
      "z": 6,
      "fuzzy": false,
      "block": "minecraft:planks",
      "worldMeta": 0,
      "stackMeta": 0,
      "needsSupportBlock": false
    },
    {
      "x": 5,
      "y": 4,
      "z": 7,
      "fuzzy": false,
      "block": "minecraft:log",
      "worldMeta": 4,
      "stackMeta": 0,
      "needsSupportBlock": false,
      "rotationMetaTransform": [
        4,
        8,
        4,
        8
      ]
    },
    {
      "x": 5,
      "y": 5,
      "z": 4,
      "fuzzy": false,
      "block": "minecraft:fence",
      "worldMeta": 0,
      "stackMeta": 0,
      "needsSupportBlock": false
    },
    {
      "x": 6,
      "y": 0,
      "z": 3,
      "fuzzy": false,
      "block": "minecraft:grass",
      "worldMeta": 0,
      "stackMeta": 0,
      "needsSupportBlock": false
    },
    {
      "x": 6,
      "y": 0,
      "z": 4,
      "fuzzy": false,
      "block": "minecraft:log",
      "worldMeta": 0,
      "stackMeta": 0,
      "needsSupportBlock": false
    },
    {
      "x": 6,
      "y": 0,
      "z": 5,
      "fuzzy": false,
      "block": "minecraft:cobblestone",
      "worldMeta": 0,
      "stackMeta": 0,
      "needsSupportBlock": false
    },
    {
      "x": 6,
      "y": 0,
      "z": 6,
      "fuzzy": false,
      "block": "minecraft:cobblestone",
      "worldMeta": 0,
      "stackMeta": 0,
      "needsSupportBlock": false
    },
    {
      "x": 6,
      "y": 0,
      "z": 7,
      "fuzzy": false,
      "block": "minecraft:log",
      "worldMeta": 0,
      "stackMeta": 0,
      "needsSupportBlock": false
    },
    {
      "x": 6,
      "y": 1,
      "z": 4,
      "fuzzy": false,
      "block": "minecraft:log",
      "worldMeta": 0,
      "stackMeta": 0,
      "needsSupportBlock": false
    },
    {
      "x": 6,
      "y": 1,
      "z": 5,
      "fuzzy": false,
      "block": "minecraft:stone_stairs",
      "worldMeta": 3,
      "stackMeta": 0,
      "needsSupportBlock": false,
      "rotationMetaTransform": [
        2,
        1,
        3,
        0
      ]
    },
    {
      "x": 6,
      "y": 1,
      "z": 7,
      "fuzzy": false,
      "block": "minecraft:log",
      "worldMeta": 0,
      "stackMeta": 0,
      "needsSupportBlock": false
    },
    {
      "x": 6,
      "y": 2,
      "z": 3,
      "fuzzy": false,
      "block": "minecraft:torch",
      "worldMeta": 4,
      "stackMeta": 0,
      "needsSupportBlock": true,
      "rotationMetaTransform": [
        3,
        2,
        4,
        1
      ]
    },
    {
      "x": 6,
      "y": 2,
      "z": 4,
      "fuzzy": false,
      "block": "minecraft:log",
      "worldMeta": 0,
      "stackMeta": 0,
      "needsSupportBlock": false
    },
    {
      "x": 6,
      "y": 2,
      "z": 7,
      "fuzzy": false,
      "block": "minecraft:log",
      "worldMeta": 0,
      "stackMeta": 0,
      "needsSupportBlock": false
    },
    {
      "x": 6,
      "y": 3,
      "z": 3,
      "fuzzy": false,
      "block": "minecraft:log",
      "worldMeta": 8,
      "stackMeta": 0,
      "needsSupportBlock": false,
      "rotationMetaTransform": [
        4,
        8,
        4,
        8
      ]
    },
    {
      "x": 6,
      "y": 3,
      "z": 4,
      "fuzzy": false,
      "block": "minecraft:log",
      "worldMeta": 0,
      "stackMeta": 0,
      "needsSupportBlock": false
    },
    {
      "x": 6,
      "y": 3,
      "z": 5,
      "fuzzy": false,
      "block": "minecraft:torch",
      "worldMeta": 3,
      "stackMeta": 0,
      "needsSupportBlock": true,
      "rotationMetaTransform": [
        3,
        2,
        4,
        1
      ]
    },
    {
      "x": 6,
      "y": 3,
      "z": 7,
      "fuzzy": false,
      "block": "minecraft:log",
      "worldMeta": 0,
      "stackMeta": 0,
      "needsSupportBlock": false
    },
    {
      "x": 6,
      "y": 4,
      "z": 3,
      "fuzzy": false,
      "block": "minecraft:brick_stairs",
      "worldMeta": 2,
      "stackMeta": 0,
      "needsSupportBlock": false,
      "rotationMetaTransform": [
        2,
        1,
        3,
        0
      ]
    },
    {
      "x": 6,
      "y": 4,
      "z": 4,
      "fuzzy": false,
      "block": "minecraft:log",
      "worldMeta": 0,
      "stackMeta": 0,
      "needsSupportBlock": false
    },
    {
      "x": 6,
      "y": 4,
      "z": 5,
      "fuzzy": false,
      "block": "minecraft:log",
      "worldMeta": 8,
      "stackMeta": 0,
      "needsSupportBlock": false,
      "rotationMetaTransform": [
        4,
        8,
        4,
        8
      ]
    },
    {
      "x": 6,
      "y": 4,
      "z": 6,
      "fuzzy": false,
      "block": "minecraft:log",
      "worldMeta": 8,
      "stackMeta": 0,
      "needsSupportBlock": false,
      "rotationMetaTransform": [
        4,
        8,
        4,
        8
      ]
    },
    {
      "x": 6,
      "y": 4,
      "z": 7,
      "fuzzy": false,
      "block": "minecraft:log",
      "worldMeta": 8,
      "stackMeta": 0,
      "needsSupportBlock": false,
      "rotationMetaTransform": [
        4,
        8,
        4,
        8
      ]
    },
    {
      "x": 6,
      "y": 4,
      "z": 8,
      "fuzzy": false,
      "block": "minecraft:torch",
      "worldMeta": 3,
      "stackMeta": 0,
      "needsSupportBlock": true,
      "rotationMetaTransform": [
        3,
        2,
        4,
        1
      ]
    },
    {
      "x": 6,
      "y": 5,
      "z": 4,
      "fuzzy": false,
      "block": "minecraft:log",
      "worldMeta": 0,
      "stackMeta": 0,
      "needsSupportBlock": false
    },
    {
      "x": 6,
      "y": 6,
      "z": 4,
      "fuzzy": false,
      "block": "minecraft:torch",
      "worldMeta": 5,
      "stackMeta": 0,
      "needsSupportBlock": true
    },
    {
      "x": 7,
      "y": 0,
      "z": 3,
      "fuzzy": false,
      "block": "minecraft:grass",
      "worldMeta": 0,
      "stackMeta": 0,
      "needsSupportBlock": false
    },
    {
      "x": 7,
      "y": 0,
      "z": 4,
      "fuzzy": false,
      "block": "minecraft:cobblestone",
      "worldMeta": 0,
      "stackMeta": 0,
      "needsSupportBlock": false
    },
    {
      "x": 7,
      "y": 0,
      "z": 5,
      "fuzzy": false,
      "block": "minecraft:cobblestone",
      "worldMeta": 0,
      "stackMeta": 0,
      "needsSupportBlock": false
    },
    {
      "x": 7,
      "y": 0,
      "z": 6,
      "fuzzy": false,
      "block": "minecraft:cobblestone",
      "worldMeta": 0,
      "stackMeta": 0,
      "needsSupportBlock": false
    },
    {
      "x": 7,
      "y": 0,
      "z": 7,
      "fuzzy": false,
      "block": "minecraft:cobblestone",
      "worldMeta": 0,
      "stackMeta": 0,
      "needsSupportBlock": false
    },
    {
      "x": 7,
      "y": 1,
      "z": 4,
      "fuzzy": false,
      "block": "minecraft:cobblestone",
      "worldMeta": 0,
      "stackMeta": 0,
      "needsSupportBlock": false
    },
    {
      "x": 7,
      "y": 1,
      "z": 5,
      "fuzzy": false,
      "block": "minecraft:stone_stairs",
      "worldMeta": 3,
      "stackMeta": 0,
      "needsSupportBlock": false,
      "rotationMetaTransform": [
        2,
        1,
        3,
        0
      ]
    },
    {
      "x": 7,
      "y": 1,
      "z": 7,
      "fuzzy": false,
      "block": "minecraft:cobblestone",
      "worldMeta": 0,
      "stackMeta": 0,
      "needsSupportBlock": false
    },
    {
      "x": 7,
      "y": 2,
      "z": 3,
      "fuzzy": false,
      "block": "minecraft:trapdoor",
      "worldMeta": 12,
      "stackMeta": 0,
      "needsSupportBlock": true,
      "rotationMetaTransform": [
        15,
        13,
        14,
        12
      ]
    },
    {
      "x": 7,
      "y": 2,
      "z": 4,
      "fuzzy": false,
      "block": "minecraft:cobblestone",
      "worldMeta": 0,
      "stackMeta": 0,
      "needsSupportBlock": false
    },
    {
      "x": 7,
      "y": 2,
      "z": 7,
      "fuzzy": false,
      "block": "minecraft:oak_stairs",
      "worldMeta": 1,
      "stackMeta": 0,
      "needsSupportBlock": false,
      "rotationMetaTransform": [
        2,
        1,
        3,
        0
      ]
    },
    {
      "x": 7,
      "y": 3,
      "z": 4,
      "fuzzy": false,
      "block": "minecraft:log",
      "worldMeta": 4,
      "stackMeta": 0,
      "needsSupportBlock": false,
      "rotationMetaTransform": [
        4,
        8,
        4,
        8
      ]
    },
    {
      "x": 7,
      "y": 3,
      "z": 7,
      "fuzzy": false,
      "block": "minecraft:oak_stairs",
      "worldMeta": 5,
      "stackMeta": 0,
      "needsSupportBlock": false,
      "rotationMetaTransform": [
        6,
        5,
        7,
        4
      ]
    },
    {
      "x": 7,
      "y": 4,
      "z": 3,
      "fuzzy": false,
      "block": "minecraft:brick_stairs",
      "worldMeta": 2,
      "stackMeta": 0,
      "needsSupportBlock": false,
      "rotationMetaTransform": [
        2,
        1,
        3,
        0
      ]
    },
    {
      "x": 7,
      "y": 4,
      "z": 4,
      "fuzzy": false,
      "block": "minecraft:planks",
      "worldMeta": 0,
      "stackMeta": 0,
      "needsSupportBlock": false
    },
    {
      "x": 7,
      "y": 4,
      "z": 5,
      "fuzzy": false,
      "block": "minecraft:planks",
      "worldMeta": 0,
      "stackMeta": 0,
      "needsSupportBlock": false
    },
    {
      "x": 7,
      "y": 4,
      "z": 6,
      "fuzzy": false,
      "block": "minecraft:planks",
      "worldMeta": 0,
      "stackMeta": 0,
      "needsSupportBlock": false
    },
    {
      "x": 7,
      "y": 4,
      "z": 7,
      "fuzzy": false,
      "block": "minecraft:log",
      "worldMeta": 4,
      "stackMeta": 0,
      "needsSupportBlock": false,
      "rotationMetaTransform": [
        4,
        8,
        4,
        8
      ]
    },
    {
      "x": 7,
      "y": 5,
      "z": 4,
      "fuzzy": false,
      "block": "minecraft:fence",
      "worldMeta": 0,
      "stackMeta": 0,
      "needsSupportBlock": false
    },
    {
      "x": 8,
      "y": 0,
      "z": 3,
      "fuzzy": false,
      "block": "minecraft:grass",
      "worldMeta": 0,
      "stackMeta": 0,
      "needsSupportBlock": false
    },
    {
      "x": 8,
      "y": 0,
      "z": 4,
      "fuzzy": false,
      "block": "minecraft:cobblestone",
      "worldMeta": 0,
      "stackMeta": 0,
      "needsSupportBlock": false
    },
    {
      "x": 8,
      "y": 0,
      "z": 5,
      "fuzzy": false,
      "block": "minecraft:cobblestone",
      "worldMeta": 0,
      "stackMeta": 0,
      "needsSupportBlock": false
    },
    {
      "x": 8,
      "y": 0,
      "z": 6,
      "fuzzy": false,
      "block": "minecraft:cobblestone",
      "worldMeta": 0,
      "stackMeta": 0,
      "needsSupportBlock": false
    },
    {
      "x": 8,
      "y": 0,
      "z": 7,
      "fuzzy": false,
      "block": "minecraft:cobblestone",
      "worldMeta": 0,
      "stackMeta": 0,
      "needsSupportBlock": false
    },
    {
      "x": 8,
      "y": 1,
      "z": 4,
      "fuzzy": false,
      "block": "minecraft:cobblestone",
      "worldMeta": 0,
      "stackMeta": 0,
      "needsSupportBlock": false
    },
    {
      "x": 8,
      "y": 1,
      "z": 5,
      "fuzzy": false,
      "block": "minecraft:stone_stairs",
      "worldMeta": 3,
      "stackMeta": 0,
      "needsSupportBlock": false,
      "rotationMetaTransform": [
        2,
        1,
        3,
        0
      ]
    },
    {
      "x": 8,
      "y": 1,
      "z": 7,
      "fuzzy": false,
      "block": "minecraft:cobblestone",
      "worldMeta": 0,
      "stackMeta": 0,
      "needsSupportBlock": false
    },
    {
      "x": 8,
      "y": 2,
      "z": 3,
      "fuzzy": false,
      "block": "minecraft:trapdoor",
      "worldMeta": 12,
      "stackMeta": 0,
      "needsSupportBlock": true,
      "rotationMetaTransform": [
        15,
        13,
        14,
        12
      ]
    },
    {
      "x": 8,
      "y": 2,
      "z": 4,
      "fuzzy": false,
      "block": "minecraft:cobblestone",
      "worldMeta": 0,
      "stackMeta": 0,
      "needsSupportBlock": false
    },
    {
      "x": 8,
      "y": 2,
      "z": 7,
      "fuzzy": false,
      "block": "minecraft:planks",
      "worldMeta": 0,
      "stackMeta": 0,
      "needsSupportBlock": false
    },
    {
      "x": 8,
      "y": 3,
      "z": 4,
      "fuzzy": false,
      "block": "minecraft:log",
      "worldMeta": 4,
      "stackMeta": 0,
      "needsSupportBlock": false,
      "rotationMetaTransform": [
        4,
        8,
        4,
        8
      ]
    },
    {
      "x": 8,
      "y": 3,
      "z": 7,
      "fuzzy": false,
      "block": "minecraft:planks",
      "worldMeta": 0,
      "stackMeta": 0,
      "needsSupportBlock": false
    },
    {
      "x": 8,
      "y": 4,
      "z": 3,
      "fuzzy": false,
      "block": "minecraft:brick_stairs",
      "worldMeta": 2,
      "stackMeta": 0,
      "needsSupportBlock": false,
      "rotationMetaTransform": [
        2,
        1,
        3,
        0
      ]
    },
    {
      "x": 8,
      "y": 4,
      "z": 4,
      "fuzzy": false,
      "block": "minecraft:planks",
      "worldMeta": 0,
      "stackMeta": 0,
      "needsSupportBlock": false
    },
    {
      "x": 8,
      "y": 4,
      "z": 5,
      "fuzzy": false,
      "block": "minecraft:planks",
      "worldMeta": 0,
      "stackMeta": 0,
      "needsSupportBlock": false
    },
    {
      "x": 8,
      "y": 4,
      "z": 6,
      "fuzzy": false,
      "block": "minecraft:planks",
      "worldMeta": 0,
      "stackMeta": 0,
      "needsSupportBlock": false
    },
    {
      "x": 8,
      "y": 4,
      "z": 7,
      "fuzzy": false,
      "block": "minecraft:log",
      "worldMeta": 4,
      "stackMeta": 0,
      "needsSupportBlock": false,
      "rotationMetaTransform": [
        4,
        8,
        4,
        8
      ]
    },
    {
      "x": 8,
      "y": 5,
      "z": 4,
      "fuzzy": false,
      "block": "minecraft:fence",
      "worldMeta": 0,
      "stackMeta": 0,
      "needsSupportBlock": false
    }
  ]
}