{
  "groundLevel": 0,
  "home": [
    15,
    1,
    8
  ],
  "blocks": [
    {
      "x": 0,
      "y": 0,
      "z": 4,
      "fuzzy": false,
      "block": "minecraft:trapdoor",
      "worldMeta": 14,
      "stackMeta": 0,
      "needsSupportBlock": true,
      "rotationMetaTransform": [
        15,
        13,
        14,
        12
      ]
    },
    {
      "x": 0,
      "y": 0,
      "z": 5,
      "fuzzy": false,
      "block": "minecraft:trapdoor",
      "worldMeta": 14,
      "stackMeta": 0,
      "needsSupportBlock": true,
      "rotationMetaTransform": [
        15,
        13,
        14,
        12
      ]
    },
    {
      "x": 0,
      "y": 0,
      "z": 9,
      "fuzzy": false,
      "block": "minecraft:trapdoor",
      "worldMeta": 14,
      "stackMeta": 0,
      "needsSupportBlock": true,
      "rotationMetaTransform": [
        15,
        13,
        14,
        12
      ]
    },
    {
      "x": 0,
      "y": 0,
      "z": 10,
      "fuzzy": false,
      "block": "minecraft:trapdoor",
      "worldMeta": 14,
      "stackMeta": 0,
      "needsSupportBlock": true,
      "rotationMetaTransform": [
        15,
        13,
        14,
        12
      ]
    },
    {
      "x": 1,
      "y": 0,
      "z": 3,
      "fuzzy": false,
      "block": "minecraft:trapdoor",
      "worldMeta": 12,
      "stackMeta": 0,
      "needsSupportBlock": true,
      "rotationMetaTransform": [
        15,
        13,
        14,
        12
      ]
    },
    {
      "x": 1,
      "y": 0,
      "z": 4,
      "fuzzy": false,
      "block": "minecraft:grass",
      "worldMeta": 0,
      "stackMeta": 0,
      "needsSupportBlock": false
    },
    {
      "x": 1,
      "y": 0,
      "z": 5,
      "fuzzy": false,
      "block": "minecraft:grass",
      "worldMeta": 0,
      "stackMeta": 0,
      "needsSupportBlock": false
    },
    {
      "x": 1,
      "y": 0,
      "z": 6,
      "fuzzy": false,
      "block": "minecraft:trapdoor",
      "worldMeta": 13,
      "stackMeta": 0,
      "needsSupportBlock": true,
      "rotationMetaTransform": [
        15,
        13,
        14,
        12
      ]
    },
    {
      "x": 1,
      "y": 0,
      "z": 8,
      "fuzzy": false,
      "block": "minecraft:trapdoor",
      "worldMeta": 12,
      "stackMeta": 0,
      "needsSupportBlock": true,
      "rotationMetaTransform": [
        15,
        13,
        14,
        12
      ]
    },
    {
      "x": 1,
      "y": 0,
      "z": 9,
      "fuzzy": false,
      "block": "minecraft:grass",
      "worldMeta": 0,
      "stackMeta": 0,
      "needsSupportBlock": false
    },
    {
      "x": 1,
      "y": 0,
      "z": 10,
      "fuzzy": false,
      "block": "minecraft:grass",
      "worldMeta": 0,
      "stackMeta": 0,
      "needsSupportBlock": false
    },
    {
      "x": 1,
      "y": 0,
      "z": 11,
      "fuzzy": false,
      "block": "minecraft:trapdoor",
      "worldMeta": 13,
      "stackMeta": 0,
      "needsSupportBlock": true,
      "rotationMetaTransform": [
        15,
        13,
        14,
        12
      ]
    },
    {
      "x": 1,
      "y": 4,
      "z": 2,
      "fuzzy": false,
      "block": "minecraft:torch",
      "worldMeta": 2,
      "stackMeta": 0,
      "needsSupportBlock": true,
      "rotationMetaTransform": [
        3,
        2,
        4,
        1
      ]
    },
    {
      "x": 1,
      "y": 4,
      "z": 7,
      "fuzzy": false,
      "block": "minecraft:torch",
      "worldMeta": 2,
      "stackMeta": 0,
      "needsSupportBlock": true,
      "rotationMetaTransform": [
        3,
        2,
        4,
        1
      ]
    },
    {
      "x": 1,
      "y": 4,
      "z": 12,
      "fuzzy": false,
      "block": "minecraft:torch",
      "worldMeta": 2,
      "stackMeta": 0,
      "needsSupportBlock": true,
      "rotationMetaTransform": [
        3,
        2,
        4,
        1
      ]
    },
    {
      "x": 1,
      "y": 6,
      "z": 1,
      "fuzzy": false,
      "block": "minecraft:brick_stairs",
      "worldMeta": 0,
      "stackMeta": 0,
      "needsSupportBlock": false,
      "rotationMetaTransform": [
        2,
        1,
        3,
        0
      ]
    },
    {
      "x": 1,
      "y": 6,
      "z": 2,
      "fuzzy": false,
      "block": "minecraft:brick_stairs",
      "worldMeta": 0,
      "stackMeta": 0,
      "needsSupportBlock": false,
      "rotationMetaTransform": [
        2,
        1,
        3,
        0
      ]
    },
    {
      "x": 1,
      "y": 6,
      "z": 3,
      "fuzzy": false,
      "block": "minecraft:brick_stairs",
      "worldMeta": 0,
      "stackMeta": 0,
      "needsSupportBlock": false,
      "rotationMetaTransform": [
        2,
        1,
        3,
        0
      ]
    },
    {
      "x": 1,
      "y": 6,
      "z": 4,
      "fuzzy": false,
      "block": "minecraft:brick_stairs",
      "worldMeta": 0,
      "stackMeta": 0,
      "needsSupportBlock": false,
      "rotationMetaTransform": [
        2,
        1,
        3,
        0
      ]
    },
    {
      "x": 1,
      "y": 6,
      "z": 5,
      "fuzzy": false,
      "block": "minecraft:brick_stairs",
      "worldMeta": 0,
      "stackMeta": 0,
      "needsSupportBlock": false,
      "rotationMetaTransform": [
        2,
        1,
        3,
        0
      ]
    },
    {
      "x": 1,
      "y": 6,
      "z": 6,
      "fuzzy": false,
      "block": "minecraft:brick_stairs",
      "worldMeta": 0,
      "stackMeta": 0,
      "needsSupportBlock": false,
      "rotationMetaTransform": [
        2,
        1,
        3,
        0
      ]
    },
    {
      "x": 1,
      "y": 6,
      "z": 7,
      "fuzzy": false,
      "block": "minecraft:brick_stairs",
      "worldMeta": 0,
      "stackMeta": 0,
      "needsSupportBlock": false,
      "rotationMetaTransform": [
        2,
        1,
        3,
        0
      ]
    },
    {
      "x": 1,
      "y": 6,
      "z": 8,
      "fuzzy": false,
      "block": "minecraft:brick_stairs",
      "worldMeta": 0,
      "stackMeta": 0,
      "needsSupportBlock": false,
      "rotationMetaTransform": [
        2,
        1,
        3,
        0
      ]
    },
    {
      "x": 1,
      "y": 6,
      "z": 9,
      "fuzzy": false,
      "block": "minecraft:brick_stairs",
      "worldMeta": 0,
      "stackMeta": 0,
      "needsSupportBlock": false,
      "rotationMetaTransform": [
        2,
        1,
        3,
        0
      ]
    },
    {
      "x": 1,
      "y": 6,
      "z": 10,
      "fuzzy": false,
      "block": "minecraft:brick_stairs",
      "worldMeta": 0,
      "stackMeta": 0,
      "needsSupportBlock": false,
      "rotationMetaTransform": [
        2,
        1,
        3,
        0
      ]
    },
    {
      "x": 1,
      "y": 6,
      "z": 11,
      "fuzzy": false,
      "block": "minecraft:brick_stairs",
      "worldMeta": 0,
      "stackMeta": 0,
      "needsSupportBlock": false,
      "rotationMetaTransform": [
        2,
        1,
        3,
        0
      ]
    },
    {
      "x": 1,
      "y": 6,
      "z": 12,
      "fuzzy": false,
      "block": "minecraft:brick_stairs",
      "worldMeta": 0,
      "stackMeta": 0,
      "needsSupportBlock": false,
      "rotationMetaTransform": [
        2,
        1,
        3,
        0
      ]
    },
    {
      "x": 1,
      "y": 6,
      "z": 13,
      "fuzzy": false,
      "block": "minecraft:brick_stairs",
      "worldMeta": 0,
      "stackMeta": 0,
      "needsSupportBlock": false,
      "rotationMetaTransform": [
        2,
        1,
        3,
        0
      ]
    },
    {
      "x": 2,
      "y": 0,
      "z": 2,
      "fuzzy": false,
      "block": "minecraft:log",
      "worldMeta": 0,
      "stackMeta": 0,
      "needsSupportBlock": false
    },
    {
      "x": 2,
      "y": 0,
      "z": 3,
      "fuzzy": false,
      "block": "minecraft:cobblestone",
      "worldMeta": 0,
      "stackMeta": 0,
      "needsSupportBlock": false
    },
    {
      "x": 2,
      "y": 0,
      "z": 4,
      "fuzzy": false,
      "block": "minecraft:cobblestone",
      "worldMeta": 0,
      "stackMeta": 0,
      "needsSupportBlock": false
    },
    {
      "x": 2,
      "y": 0,
      "z": 5,
      "fuzzy": false,
      "block": "minecraft:cobblestone",
      "worldMeta": 0,
      "stackMeta": 0,
      "needsSupportBlock": false
    },
    {
      "x": 2,
      "y": 0,
      "z": 6,
      "fuzzy": false,
      "block": "minecraft:cobblestone",
      "worldMeta": 0,
      "stackMeta": 0,
      "needsSupportBlock": false
    },
    {
      "x": 2,
      "y": 0,
      "z": 7,
      "fuzzy": false,
      "block": "minecraft:log",
      "worldMeta": 0,
      "stackMeta": 0,
      "needsSupportBlock": false
    },
    {
      "x": 2,
      "y": 0,
      "z": 8,
      "fuzzy": false,
      "block": "minecraft:cobblestone",
      "worldMeta": 0,
      "stackMeta": 0,
      "needsSupportBlock": false
    },
    {
      "x": 2,
      "y": 0,
      "z": 9,
      "fuzzy": false,
      "block": "minecraft:cobblestone",
      "worldMeta": 0,
      "stackMeta": 0,
      "needsSupportBlock": false
    },
    {
      "x": 2,
      "y": 0,
      "z": 10,
      "fuzzy": false,
      "block": "minecraft:cobblestone",
      "worldMeta": 0,
      "stackMeta": 0,
      "needsSupportBlock": false
    },
    {
      "x": 2,
      "y": 0,
      "z": 11,
      "fuzzy": false,
      "block": "minecraft:cobblestone",
      "worldMeta": 0,
      "stackMeta": 0,
      "needsSupportBlock": false
    },
    {
      "x": 2,
      "y": 0,
      "z": 12,
      "fuzzy": false,
      "block": "minecraft:log",
      "worldMeta": 0,
      "stackMeta": 0,
      "needsSupportBlock": false
    },
    {
      "x": 2,
      "y": 1,
      "z": 2,
      "fuzzy": false,
      "block": "minecraft:log",
      "worldMeta": 0,
      "stackMeta": 0,
      "needsSupportBlock": false
    },
    {
      "x": 2,
      "y": 1,
      "z": 3,
      "fuzzy": false,
      "block": "minecraft:planks",
      "worldMeta": 0,
      "stackMeta": 0,
      "needsSupportBlock": false
    },
    {
      "x": 2,
      "y": 1,
      "z": 4,
      "fuzzy": false,
      "block": "minecraft:oak_stairs",
      "worldMeta": 0,
      "stackMeta": 0,
      "needsSupportBlock": false,
      "rotationMetaTransform": [
        2,
        1,
        3,
        0
      ]
    },
    {
      "x": 2,
      "y": 1,
      "z": 5,
      "fuzzy": false,
      "block": "minecraft:oak_stairs",
      "worldMeta": 0,
      "stackMeta": 0,
      "needsSupportBlock": false,
      "rotationMetaTransform": [
        2,
        1,
        3,
        0
      ]
    },
    {
      "x": 2,
      "y": 1,
      "z": 6,
      "fuzzy": false,
      "block": "minecraft:planks",
      "worldMeta": 0,
      "stackMeta": 0,
      "needsSupportBlock": false
    },
    {
      "x": 2,
      "y": 1,
      "z": 7,
      "fuzzy": false,
      "block": "minecraft:log",
      "worldMeta": 0,
      "stackMeta": 0,
      "needsSupportBlock": false
    },
    {
      "x": 2,
      "y": 1,
      "z": 8,
      "fuzzy": false,
      "block": "minecraft:planks",
      "worldMeta": 0,
      "stackMeta": 0,
      "needsSupportBlock": false
    },
    {
      "x": 2,
      "y": 1,
      "z": 9,
      "fuzzy": false,
      "block": "minecraft:oak_stairs",
      "worldMeta": 0,
      "stackMeta": 0,
      "needsSupportBlock": false,
      "rotationMetaTransform": [
        2,
        1,
        3,
        0
      ]
    },
    {
      "x": 2,
      "y": 1,
      "z": 10,
      "fuzzy": false,
      "block": "minecraft:oak_stairs",
      "worldMeta": 0,
      "stackMeta": 0,
      "needsSupportBlock": false,
      "rotationMetaTransform": [
        2,
        1,
        3,
        0
      ]
    },
    {
      "x": 2,
      "y": 1,
      "z": 11,
      "fuzzy": false,
      "block": "minecraft:planks",
      "worldMeta": 0,
      "stackMeta": 0,
      "needsSupportBlock": false
    },
    {
      "x": 2,
      "y": 1,
      "z": 12,
      "fuzzy": false,
      "block": "minecraft:log",
      "worldMeta": 0,
      "stackMeta": 0,
      "needsSupportBlock": false
    },
    {
      "x": 2,
      "y": 2,
      "z": 2,
      "fuzzy": false,
      "block": "minecraft:log",
      "worldMeta": 0,
      "stackMeta": 0,
      "needsSupportBlock": false
    },
    {
      "x": 2,
      "y": 2,
      "z": 3,
      "fuzzy": false,
      "block": "minecraft:planks",
      "worldMeta": 0,
      "stackMeta": 0,
      "needsSupportBlock": false
    },
    {
      "x": 2,
      "y": 2,
      "z": 4,
      "fuzzy": false,
      "block": "minecraft:glass_pane",
      "worldMeta": 0,
      "stackMeta": 0,
      "needsSupportBlock": false
    },
    {
      "x": 2,
      "y": 2,
      "z": 5,
      "fuzzy": false,
      "block": "minecraft:glass_pane",
      "worldMeta": 0,
      "stackMeta": 0,
      "needsSupportBlock": false
    },
    {
      "x": 2,
      "y": 2,
      "z": 6,
      "fuzzy": false,
      "block": "minecraft:planks",
      "worldMeta": 0,
      "stackMeta": 0,
      "needsSupportBlock": false
    },
    {
      "x": 2,
      "y": 2,
      "z": 7,
      "fuzzy": false,
      "block": "minecraft:log",
      "worldMeta": 0,
      "stackMeta": 0,
      "needsSupportBlock": false
    },
    {
      "x": 2,
      "y": 2,
      "z": 8,
      "fuzzy": false,
      "block": "minecraft:planks",
      "worldMeta": 0,
      "stackMeta": 0,
      "needsSupportBlock": false
    },
    {
      "x": 2,
      "y": 2,
      "z": 9,
      "fuzzy": false,
      "block": "minecraft:glass_pane",
      "worldMeta": 0,
      "stackMeta": 0,
      "needsSupportBlock": false
    },
    {
      "x": 2,
      "y": 2,
      "z": 10,
      "fuzzy": false,
      "block": "minecraft:glass_pane",
      "worldMeta": 0,
      "stackMeta": 0,
      "needsSupportBlock": false
    },
    {
      "x": 2,
      "y": 2,
      "z": 11,
      "fuzzy": false,
      "block": "minecraft:planks",
      "worldMeta": 0,
      "stackMeta": 0,
      "needsSupportBlock": false
    },
    {
      "x": 2,
      "y": 2,
      "z": 12,
      "fuzzy": false,
      "block": "minecraft:log",
      "worldMeta": 0,
      "stackMeta": 0,
      "needsSupportBlock": false
    },
    {
      "x": 2,
      "y": 3,
      "z": 2,
      "fuzzy": false,
      "block": "minecraft:log",
      "worldMeta": 0,
      "stackMeta": 0,
      "needsSupportBlock": false
    },
    {
      "x": 2,
      "y": 3,
      "z": 3,
      "fuzzy": false,
      "block": "minecraft:planks",
      "worldMeta": 0,
      "stackMeta": 0,
      "needsSupportBlock": false
    },
    {
      "x": 2,
      "y": 3,
      "z": 4,
      "fuzzy": false,
      "block": "minecraft:oak_stairs",
      "worldMeta": 4,
      "stackMeta": 0,
      "needsSupportBlock": false,
      "rotationMetaTransform": [
        6,
        5,
        7,
        4
      ]
    },
    {
      "x": 2,
      "y": 3,
      "z": 5,
      "fuzzy": false,
      "block": "minecraft:oak_stairs",
      "worldMeta": 4,
      "stackMeta": 0,
      "needsSupportBlock": false,
      "rotationMetaTransform": [
        6,
        5,
        7,
        4
      ]
    },
    {
      "x": 2,
      "y": 3,
      "z": 6,
      "fuzzy": false,
      "block": "minecraft:planks",
      "worldMeta": 0,
      "stackMeta": 0,
      "needsSupportBlock": false
    },
    {
      "x": 2,
      "y": 3,
      "z": 7,
      "fuzzy": false,
      "block": "minecraft:log",
      "worldMeta": 0,
      "stackMeta": 0,
      "needsSupportBlock": false
    },
    {
      "x": 2,
      "y": 3,
      "z": 8,
      "fuzzy": false,
      "block": "minecraft:planks",
      "worldMeta": 0,
      "stackMeta": 0,
      "needsSupportBlock": false
    },
    {
      "x": 2,
      "y": 3,
      "z": 9,
      "fuzzy": false,
      "block": "minecraft:oak_stairs",
      "worldMeta": 4,
      "stackMeta": 0,
      "needsSupportBlock": false,
      "rotationMetaTransform": [
        6,
        5,
        7,
        4
      ]
    },
    {
      "x": 2,
      "y": 3,
      "z": 10,
      "fuzzy": false,
      "block": "minecraft:oak_stairs",
      "worldMeta": 4,
      "stackMeta": 0,
      "needsSupportBlock": false,
      "rotationMetaTransform": [
        6,
        5,
        7,
        4
      ]
    },
    {
      "x": 2,
      "y": 3,
      "z": 11,
      "fuzzy": false,
      "block": "minecraft:planks",
      "worldMeta": 0,
      "stackMeta": 0,
      "needsSupportBlock": false
    },
    {
      "x": 2,
      "y": 3,
      "z": 12,
      "fuzzy": false,
      "block": "minecraft:log",
      "worldMeta": 0,
      "stackMeta": 0,
      "needsSupportBlock": false
    },
    {
      "x": 2,
      "y": 4,
      "z": 1,
      "fuzzy": false,
      "block": "minecraft:torch",
      "worldMeta": 4,
      "stackMeta": 0,
      "needsSupportBlock": true,
      "rotationMetaTransform": [
        3,
        2,
        4,
        1
      ]
    },
    {
      "x": 2,
      "y": 4,
      "z": 2,
      "fuzzy": false,
      "block": "minecraft:log",
      "worldMeta": 0,
      "stackMeta": 0,
      "needsSupportBlock": false
    },
    {
      "x": 2,
      "y": 4,
      "z": 3,
      "fuzzy": false,
      "block": "minecraft:log",
      "worldMeta": 8,
      "stackMeta": 0,
      "needsSupportBlock": false,
      "rotationMetaTransform": [
        4,
        8,
        4,
        8
      ]
    },
    {
      "x": 2,
      "y": 4,
      "z": 4,
      "fuzzy": false,
      "block": "minecraft:log",
      "worldMeta": 8,
      "stackMeta": 0,
      "needsSupportBlock": false,
      "rotationMetaTransform": [
        4,
        8,
        4,
        8
      ]
    },
    {
      "x": 2,
      "y": 4,
      "z": 5,
      "fuzzy": false,
      "block": "minecraft:log",
      "worldMeta": 8,
      "stackMeta": 0,
      "needsSupportBlock": false,
      "rotationMetaTransform": [
        4,
        8,
        4,
        8
      ]
    },
    {
      "x": 2,
      "y": 4,
      "z": 6,
      "fuzzy": false,
      "block": "minecraft:log",
      "worldMeta": 8,
      "stackMeta": 0,
      "needsSupportBlock": false,
      "rotationMetaTransform": [
        4,
        8,
        4,
        8
      ]
    },
    {
      "x": 2,
      "y": 4,
      "z": 7,
      "fuzzy": false,
      "block": "minecraft:log",
      "worldMeta": 0,
      "stackMeta": 0,
      "needsSupportBlock": false
    },
    {
      "x": 2,
      "y": 4,
      "z": 8,
      "fuzzy": false,
      "block": "minecraft:log",
      "worldMeta": 8,
      "stackMeta": 0,
      "needsSupportBlock": false,
      "rotationMetaTransform": [
        4,
        8,
        4,
        8
      ]
    },
    {
      "x": 2,
      "y": 4,
      "z": 9,
      "fuzzy": false,
      "block": "minecraft:log",
      "worldMeta": 8,
      "stackMeta": 0,
      "needsSupportBlock": false,
      "rotationMetaTransform": [
        4,
        8,
        4,
        8
      ]
    },
    {
      "x": 2,
      "y": 4,
      "z": 10,
      "fuzzy": false,
      "block": "minecraft:log",
      "worldMeta": 8,
      "stackMeta": 0,
      "needsSupportBlock": false,
      "rotationMetaTransform": [
        4,
        8,
        4,
        8
      ]
    },
    {
      "x": 2,
      "y": 4,
      "z": 11,
      "fuzzy": false,
      "block": "minecraft:log",
      "worldMeta": 8,
      "stackMeta": 0,
      "needsSupportBlock": false,
      "rotationMetaTransform": [
        4,
        8,
        4,
        8
      ]
    },
    {
      "x": 2,
      "y": 4,
      "z": 12,
      "fuzzy": false,
      "block": "minecraft:log",
      "worldMeta": 0,
      "stackMeta": 0,
      "needsSupportBlock": false
    },
    {
      "x": 2,
      "y": 4,
      "z": 13,
      "fuzzy": false,
      "block": "minecraft:torch",
      "worldMeta": 3,
      "stackMeta": 0,
      "needsSupportBlock": true,
      "rotationMetaTransform": [
        3,
        2,
        4,
        1
      ]
    },
    {
      "x": 2,
      "y": 5,
      "z": 2,
      "fuzzy": false,
      "block": "minecraft:log",
      "worldMeta": 0,
      "stackMeta": 0,
      "needsSupportBlock": false
    },
    {
      "x": 2,
      "y": 5,
      "z": 3,
      "fuzzy": false,
      "block": "minecraft:planks",
      "worldMeta": 0,
      "stackMeta": 0,
      "needsSupportBlock": false
    },
    {
      "x": 2,
      "y": 5,
      "z": 4,
      "fuzzy": false,
      "block": "minecraft:planks",
      "worldMeta": 0,
      "stackMeta": 0,
      "needsSupportBlock": false
    },
    {
      "x": 2,
      "y": 5,
      "z": 5,
      "fuzzy": false,
      "block": "minecraft:planks",
      "worldMeta": 0,
      "stackMeta": 0,
      "needsSupportBlock": false
    },
    {
      "x": 2,
      "y": 5,
      "z": 6,
      "fuzzy": false,
      "block": "minecraft:planks",
      "worldMeta": 0,
      "stackMeta": 0,
      "needsSupportBlock": false
    },
    {
      "x": 2,
      "y": 5,
      "z": 7,
      "fuzzy": false,
      "block": "minecraft:log",
      "worldMeta": 0,
      "stackMeta": 0,
      "needsSupportBlock": false
    },
    {
      "x": 2,
      "y": 5,
      "z": 8,
      "fuzzy": false,
      "block": "minecraft:planks",
      "worldMeta": 0,
      "stackMeta": 0,
      "needsSupportBlock": false
    },
    {
      "x": 2,
      "y": 5,
      "z": 9,
      "fuzzy": false,
      "block": "minecraft:planks",
      "worldMeta": 0,
      "stackMeta": 0,
      "needsSupportBlock": false
    },
    {
      "x": 2,
      "y": 5,
      "z": 10,
      "fuzzy": false,
      "block": "minecraft:planks",
      "worldMeta": 0,
      "stackMeta": 0,
      "needsSupportBlock": false
    },
    {
      "x": 2,
      "y": 5,
      "z": 11,
      "fuzzy": false,
      "block": "minecraft:planks",
      "worldMeta": 0,
      "stackMeta": 0,
      "needsSupportBlock": false
    },
    {
      "x": 2,
      "y": 5,
      "z": 12,
      "fuzzy": false,
      "block": "minecraft:log",
      "worldMeta": 0,
      "stackMeta": 0,
      "needsSupportBlock": false
    },
    {
      "x": 2,
      "y": 6,
      "z": 1,
      "fuzzy": false,
      "block": "minecraft:brick_stairs",
      "worldMeta": 5,
      "stackMeta": 0,
      "needsSupportBlock": false,
      "rotationMetaTransform": [
        6,
        5,
        7,
        4
      ]
    },
    {
      "x": 2,
      "y": 6,
      "z": 2,
      "fuzzy": false,
      "block": "minecraft:log",
      "worldMeta": 0,
      "stackMeta": 0,
      "needsSupportBlock": false
    },
    {
      "x": 2,
      "y": 6,
      "z": 3,
      "fuzzy": false,
      "block": "minecraft:planks",
      "worldMeta": 0,
      "stackMeta": 0,
      "needsSupportBlock": false
    },
    {
      "x": 2,
      "y": 6,
      "z": 4,
      "fuzzy": false,
      "block": "minecraft:planks",
      "worldMeta": 0,
      "stackMeta": 0,
      "needsSupportBlock": false
    },
    {
      "x": 2,
      "y": 6,
      "z": 5,
      "fuzzy": false,
      "block": "minecraft:planks",
      "worldMeta": 0,
      "stackMeta": 0,
      "needsSupportBlock": false
    },
    {
      "x": 2,
      "y": 6,
      "z": 6,
      "fuzzy": false,
      "block": "minecraft:planks",
      "worldMeta": 0,
      "stackMeta": 0,
      "needsSupportBlock": false
    },
    {
      "x": 2,
      "y": 6,
      "z": 7,
      "fuzzy": false,
      "block": "minecraft:log",
      "worldMeta": 0,
      "stackMeta": 0,
      "needsSupportBlock": false
    },
    {
      "x": 2,
      "y": 6,
      "z": 8,
      "fuzzy": false,
      "block": "minecraft:planks",
      "worldMeta": 0,
      "stackMeta": 0,
      "needsSupportBlock": false
    },
    {
      "x": 2,
      "y": 6,
      "z": 9,
      "fuzzy": false,
      "block": "minecraft:planks",
      "worldMeta": 0,
      "stackMeta": 0,
      "needsSupportBlock": false
    },
    {
      "x": 2,
      "y": 6,
      "z": 10,
      "fuzzy": false,
      "block": "minecraft:planks",
      "worldMeta": 0,
      "stackMeta": 0,
      "needsSupportBlock": false
    },
    {
      "x": 2,
      "y": 6,
      "z": 11,
      "fuzzy": false,
      "block": "minecraft:planks",
      "worldMeta": 0,
      "stackMeta": 0,
      "needsSupportBlock": false
    },
    {
      "x": 2,
      "y": 6,
      "z": 12,
      "fuzzy": false,
      "block": "minecraft:log",
      "worldMeta": 0,
      "stackMeta": 0,
      "needsSupportBlock": false
    },
    {
      "x": 2,
      "y": 6,
      "z": 13,
      "fuzzy": false,
      "block": "minecraft:brick_stairs",
      "worldMeta": 5,
      "stackMeta": 0,
      "needsSupportBlock": false,
      "rotationMetaTransform": [
        6,
        5,
        7,
        4
      ]
    },
    {
      "x": 2,
      "y": 7,
      "z": 1,
      "fuzzy": false,
      "block": "minecraft:brick_stairs",
      "worldMeta": 0,
      "stackMeta": 0,
      "needsSupportBlock": false,
      "rotationMetaTransform": [
        2,
        1,
        3,
        0
      ]
    },
    {
      "x": 2,
      "y": 7,
      "z": 2,
      "fuzzy": false,
      "block": "minecraft:brick_stairs",
      "worldMeta": 0,
      "stackMeta": 0,
      "needsSupportBlock": false,
      "rotationMetaTransform": [
        2,
        1,
        3,
        0
      ]
    },
    {
      "x": 2,
      "y": 7,
      "z": 3,
      "fuzzy": false,
      "block": "minecraft:brick_stairs",
      "worldMeta": 0,
      "stackMeta": 0,
      "needsSupportBlock": false,
      "rotationMetaTransform": [
        2,
        1,
        3,
        0
      ]
    },
    {
      "x": 2,
      "y": 7,
      "z": 4,
      "fuzzy": false,
      "block": "minecraft:brick_stairs",
      "worldMeta": 0,
      "stackMeta": 0,
      "needsSupportBlock": false,
      "rotationMetaTransform": [
        2,
        1,
        3,
        0
      ]
    },
    {
      "x": 2,
      "y": 7,
      "z": 5,
      "fuzzy": false,
      "block": "minecraft:brick_stairs",
      "worldMeta": 0,
      "stackMeta": 0,
      "needsSupportBlock": false,
      "rotationMetaTransform": [
        2,
        1,
        3,
        0
      ]
    },
    {
      "x": 2,
      "y": 7,
      "z": 6,
      "fuzzy": false,
      "block": "minecraft:brick_stairs",
      "worldMeta": 0,
      "stackMeta": 0,
      "needsSupportBlock": false,
      "rotationMetaTransform": [
        2,
        1,
        3,
        0
      ]
    },
    {
      "x": 2,
      "y": 7,
      "z": 7,
      "fuzzy": false,
      "block": "minecraft:brick_stairs",
      "worldMeta": 0,
      "stackMeta": 0,
      "needsSupportBlock": false,
      "rotationMetaTransform": [
        2,
        1,
        3,
        0
      ]
    },
    {
      "x": 2,
      "y": 7,
      "z": 8,
      "fuzzy": false,
      "block": "minecraft:brick_stairs",
      "worldMeta": 0,
      "stackMeta": 0,
      "needsSupportBlock": false,
      "rotationMetaTransform": [
        2,
        1,
        3,
        0
      ]
    },
    {
      "x": 2,
      "y": 7,
      "z": 9,
      "fuzzy": false,
      "block": "minecraft:brick_stairs",
      "worldMeta": 0,
      "stackMeta": 0,
      "needsSupportBlock": false,
      "rotationMetaTransform": [
        2,
        1,
        3,
        0
      ]
    },
    {
      "x": 2,
      "y": 7,
      "z": 10,
      "fuzzy": false,
      "block": "minecraft:brick_stairs",
      "worldMeta": 0,
      "stackMeta": 0,
      "needsSupportBlock": false,
      "rotationMetaTransform": [
        2,
        1,
        3,
        0
      ]
    },
    {
      "x": 2,
      "y": 7,
      "z": 11,
      "fuzzy": false,
      "block": "minecraft:brick_stairs",
      "worldMeta": 0,
      "stackMeta": 0,
      "needsSupportBlock": false,
      "rotationMetaTransform": [
        2,
        1,
        3,
        0
      ]
    },
    {
      "x": 2,
      "y": 7,
      "z": 12,
      "fuzzy": false,
      "block": "minecraft:brick_stairs",
      "worldMeta": 0,
      "stackMeta": 0,
      "needsSupportBlock": false,
      "rotationMetaTransform": [
        2,
        1,
        3,
        0
      ]
    },
    {
      "x": 2,
      "y": 7,
      "z": 13,
      "fuzzy": false,
      "block": "minecraft:brick_stairs",
      "worldMeta": 0,
      "stackMeta": 0,
      "needsSupportBlock": false,
      "rotationMetaTransform": [
        2,
        1,
        3,
        0
      ]
    },
    {
      "x": 3,
      "y": 0,
      "z": 1,
      "fuzzy": false,
      "block": "minecraft:trapdoor",
      "worldMeta": 14,
      "stackMeta": 0,
      "needsSupportBlock": true,
      "rotationMetaTransform": [
        15,
        13,
        14,
        12
      ]
    },
    {
      "x": 3,
      "y": 0,
      "z": 2,
      "fuzzy": false,
      "block": "minecraft:cobblestone",
      "worldMeta": 0,
      "stackMeta": 0,
      "needsSupportBlock": false
    },
    {
      "x": 3,
      "y": 0,
      "z": 3,
      "fuzzy": false,
      "block": "minecraft:cobblestone",
      "worldMeta": 0,
      "stackMeta": 0,
      "needsSupportBlock": false
    },
    {
      "x": 3,
      "y": 0,
      "z": 4,
      "fuzzy": false,
      "block": "minecraft:cobblestone",
      "worldMeta": 0,
      "stackMeta": 0,
      "needsSupportBlock": false
    },
    {
      "x": 3,
      "y": 0,
      "z": 5,
      "fuzzy": false,
      "block": "minecraft:cobblestone",
      "worldMeta": 0,
      "stackMeta": 0,
      "needsSupportBlock": false
    },
    {
      "x": 3,
      "y": 0,
      "z": 6,
      "fuzzy": false,
      "block": "minecraft:cobblestone",
      "worldMeta": 0,
      "stackMeta": 0,
      "needsSupportBlock": false
    },
    {
      "x": 3,
      "y": 0,
      "z": 7,
      "fuzzy": false,
      "block": "minecraft:cobblestone",
      "worldMeta": 0,
      "stackMeta": 0,
      "needsSupportBlock": false
    },
    {
      "x": 3,
      "y": 0,
      "z": 8,
      "fuzzy": false,
      "block": "minecraft:cobblestone",
      "worldMeta": 0,
      "stackMeta": 0,
      "needsSupportBlock": false
    },
    {
      "x": 3,
      "y": 0,
      "z": 9,
      "fuzzy": false,
      "block": "minecraft:cobblestone",
      "worldMeta": 0,
      "stackMeta": 0,
      "needsSupportBlock": false
    },
    {
      "x": 3,
      "y": 0,
      "z": 10,
      "fuzzy": false,
      "block": "minecraft:cobblestone",
      "worldMeta": 0,
      "stackMeta": 0,
      "needsSupportBlock": false
    },
    {
      "x": 3,
      "y": 0,
      "z": 11,
      "fuzzy": false,
      "block": "minecraft:cobblestone",
      "worldMeta": 0,
      "stackMeta": 0,
      "needsSupportBlock": false
    },
    {
      "x": 3,
      "y": 0,
      "z": 12,
      "fuzzy": false,
      "block": "minecraft:cobblestone",
      "worldMeta": 0,
      "stackMeta": 0,
      "needsSupportBlock": false
    },
    {
      "x": 3,
      "y": 0,
      "z": 13,
      "fuzzy": false,
      "block": "minecraft:trapdoor",
      "worldMeta": 14,
      "stackMeta": 0,
      "needsSupportBlock": true,
      "rotationMetaTransform": [
        15,
        13,
        14,
        12
      ]
    },
    {
      "x": 3,
      "y": 1,
      "z": 2,
      "fuzzy": false,
      "block": "minecraft:planks",
      "worldMeta": 0,
      "stackMeta": 0,
      "needsSupportBlock": false
    },
    {
      "x": 3,
      "y": 1,
      "z": 3,
      "fuzzy": false,
      "block": "minecraft:chest",
      "worldMeta": 3,
      "stackMeta": 0,
      "needsSupportBlock": false,
      "rotationMetaTransform": [
        5,
        3,
        4,
        2
      ],
      "nbtString": "{x:-1667,y:5,z:-31,Items:[],id:\"Chest\",Lock:\"\"}"
    },
    {
      "x": 3,
      "y": 1,
      "z": 4,
      "fuzzy": false,
      "block": "minecraft:carpet",
      "worldMeta": 14,
      "stackMeta": 14,
      "needsSupportBlock": false
    },
    {
      "x": 3,
      "y": 1,
      "z": 5,
      "fuzzy": false,
      "block": "minecraft:carpet",
      "worldMeta": 14,
      "stackMeta": 14,
      "needsSupportBlock": false
    },
    {
      "x": 3,
      "y": 1,
      "z": 6,
      "fuzzy": false,
      "block": "minecraft:carpet",
      "worldMeta": 14,
      "stackMeta": 14,
      "needsSupportBlock": false
    },
    {
      "x": 3,
      "y": 1,
      "z": 7,
      "fuzzy": false,
      "block": "minecraft:carpet",
      "worldMeta": 14,
      "stackMeta": 14,
      "needsSupportBlock": false
    },
    {
      "x": 3,
      "y": 1,
      "z": 8,
      "fuzzy": false,
      "block": "minecraft:carpet",
      "worldMeta": 14,
      "stackMeta": 14,
      "needsSupportBlock": false
    },
    {
      "x": 3,
      "y": 1,
      "z": 9,
      "fuzzy": false,
      "block": "minecraft:carpet",
      "worldMeta": 14,
      "stackMeta": 14,
      "needsSupportBlock": false
    },
    {
      "x": 3,
      "y": 1,
      "z": 10,
      "fuzzy": false,
      "block": "minecraft:stone_stairs",
      "worldMeta": 6,
      "stackMeta": 0,
      "needsSupportBlock": false,
      "rotationMetaTransform": [
        6,
        5,
        7,
        4
      ]
    },
    {
      "x": 3,
      "y": 1,
      "z": 11,
      "fuzzy": false,
      "block": "minecraft:dirt",
      "worldMeta": 0,
      "stackMeta": 0,
      "needsSupportBlock": false
    },
    {
      "x": 3,
      "y": 1,
      "z": 12,
      "fuzzy": false,
      "block": "minecraft:planks",
      "worldMeta": 0,
      "stackMeta": 0,
      "needsSupportBlock": false
    },
    {
      "x": 3,
      "y": 2,
      "z": 2,
      "fuzzy": false,
      "block": "minecraft:planks",
      "worldMeta": 0,
      "stackMeta": 0,
      "needsSupportBlock": false
    },
    {
      "x": 3,
      "y": 2,
      "z": 3,
      "fuzzy": false,
      "block": "minecraft:trapdoor",
      "worldMeta": 15,
      "stackMeta": 0,
      "needsSupportBlock": true,
      "rotationMetaTransform": [
        15,
        13,
        14,
        12
      ]
    },
    {
      "x": 3,
      "y": 2,
      "z": 6,
      "fuzzy": false,
      "block": "minecraft:trapdoor",
      "worldMeta": 15,
      "stackMeta": 0,
      "needsSupportBlock": true,
      "rotationMetaTransform": [
        15,
        13,
        14,
        12
      ]
    },
    {
      "x": 3,
      "y": 2,
      "z": 8,
      "fuzzy": false,
      "block": "minecraft:trapdoor",
      "worldMeta": 15,
      "stackMeta": 0,
      "needsSupportBlock": true,
      "rotationMetaTransform": [
        15,
        13,
        14,
        12
      ]
    },
    {
      "x": 3,
      "y": 2,
      "z": 11,
      "fuzzy": false,
      "block": "minecraft:double_plant",
      "worldMeta": 4,
      "stackMeta": 4,
      "needsSupportBlock": false
    },
    {
      "x": 3,
      "y": 2,
      "z": 12,
      "fuzzy": false,
      "block": "minecraft:planks",
      "worldMeta": 0,
      "stackMeta": 0,
      "needsSupportBlock": false
    },
    {
      "x": 3,
      "y": 3,
      "z": 2,
      "fuzzy": false,
      "block": "minecraft:planks",
      "worldMeta": 0,
      "stackMeta": 0,
      "needsSupportBlock": false
    },
    {
      "x": 3,
      "y": 3,
      "z": 7,
      "fuzzy": false,
      "block": "minecraft:torch",
      "worldMeta": 1,
      "stackMeta": 0,
      "needsSupportBlock": true,
      "rotationMetaTransform": [
        3,
        2,
        4,
        1
      ]
    },
    {
      "x": 3,
      "y": 3,
      "z": 11,
      "fuzzy": false,
      "block": "minecraft:double_plant",
      "worldMeta": 10,
      "stackMeta": 0,
      "needsSupportBlock": false
    },
    {
      "x": 3,
      "y": 3,
      "z": 12,
      "fuzzy": false,
      "block": "minecraft:planks",
      "worldMeta": 0,
      "stackMeta": 0,
      "needsSupportBlock": false
    },
    {
      "x": 3,
      "y": 4,
      "z": 2,
      "fuzzy": false,
      "block": "minecraft:log",
      "worldMeta": 4,
      "stackMeta": 0,
      "needsSupportBlock": false,
      "rotationMetaTransform": [
        4,
        8,
        4,
        8
      ]
    },
    {
      "x": 3,
      "y": 4,
      "z": 3,
      "fuzzy": false,
      "block": "minecraft:wooden_slab",
      "worldMeta": 8,
      "stackMeta": 0,
      "needsSupportBlock": false
    },
    {
      "x": 3,
      "y": 4,
      "z": 4,
      "fuzzy": false,
      "block": "minecraft:wooden_slab",
      "worldMeta": 8,
      "stackMeta": 0,
      "needsSupportBlock": false
    },
    {
      "x": 3,
      "y": 4,
      "z": 5,
      "fuzzy": false,
      "block": "minecraft:wooden_slab",
      "worldMeta": 8,
      "stackMeta": 0,
      "needsSupportBlock": false
    },
    {
      "x": 3,
      "y": 4,
      "z": 6,
      "fuzzy": false,
      "block": "minecraft:wooden_slab",
      "worldMeta": 8,
      "stackMeta": 0,
      "needsSupportBlock": false
    },
    {
      "x": 3,
      "y": 4,
      "z": 7,
      "fuzzy": false,
      "block": "minecraft:wooden_slab",
      "worldMeta": 8,
      "stackMeta": 0,
      "needsSupportBlock": false
    },
    {
      "x": 3,
      "y": 4,
      "z": 8,
      "fuzzy": false,
      "block": "minecraft:wooden_slab",
      "worldMeta": 8,
      "stackMeta": 0,
      "needsSupportBlock": false
    },
    {
      "x": 3,
      "y": 4,
      "z": 9,
      "fuzzy": false,
      "block": "minecraft:wooden_slab",
      "worldMeta": 8,
      "stackMeta": 0,
      "needsSupportBlock": false
    },
    {
      "x": 3,
      "y": 4,
      "z": 10,
      "fuzzy": false,
      "block": "minecraft:wooden_slab",
      "worldMeta": 8,
      "stackMeta": 0,
      "needsSupportBlock": false
    },
    {
      "x": 3,
      "y": 4,
      "z": 11,
      "fuzzy": false,
      "block": "minecraft:wooden_slab",
      "worldMeta": 8,
      "stackMeta": 0,
      "needsSupportBlock": false
    },
    {
      "x": 3,
      "y": 4,
      "z": 12,
      "fuzzy": false,
      "block": "minecraft:log",
      "worldMeta": 4,
      "stackMeta": 0,
      "needsSupportBlock": false,
      "rotationMetaTransform": [
        4,
        8,
        4,
        8
      ]
    },
    {
      "x": 3,
      "y": 5,
      "z": 2,
      "fuzzy": false,
      "block": "minecraft:planks",
      "worldMeta": 0,
      "stackMeta": 0,
      "needsSupportBlock": false
    },
    {
      "x": 3,
      "y": 5,
      "z": 3,
      "fuzzy": false,
      "block": "minecraft:carpet",
      "worldMeta": 14,
      "stackMeta": 14,
      "needsSupportBlock": false
    },
    {
      "x": 3,
      "y": 5,
      "z": 4,
      "fuzzy": false,
      "block": "minecraft:carpet",
      "worldMeta": 14,
      "stackMeta": 14,
      "needsSupportBlock": false
    },
    {
      "x": 3,
      "y": 5,
      "z": 5,
      "fuzzy": false,
      "block": "minecraft:carpet",
      "worldMeta": 14,
      "stackMeta": 14,
      "needsSupportBlock": false
    },
    {
      "x": 3,
      "y": 5,
      "z": 6,
      "fuzzy": false,
      "block": "minecraft:carpet",
      "worldMeta": 14,
      "stackMeta": 14,
      "needsSupportBlock": false
    },
    {
      "x": 3,
      "y": 5,
      "z": 7,
      "fuzzy": false,
      "block": "minecraft:carpet",
      "worldMeta": 14,
      "stackMeta": 14,
      "needsSupportBlock": false
    },
    {
      "x": 3,
      "y": 5,
      "z": 8,
      "fuzzy": false,
      "block": "minecraft:carpet",
      "worldMeta": 14,
      "stackMeta": 14,
      "needsSupportBlock": false
    },
    {
      "x": 3,
      "y": 5,
      "z": 9,
      "fuzzy": false,
      "block": "minecraft:carpet",
      "worldMeta": 14,
      "stackMeta": 14,
      "needsSupportBlock": false
    },
    {
      "x": 3,
      "y": 5,
      "z": 10,
      "fuzzy": false,
      "block": "minecraft:carpet",
      "worldMeta": 14,
      "stackMeta": 14,
      "needsSupportBlock": false
    },
    {
      "x": 3,
      "y": 5,
      "z": 11,
      "fuzzy": false,
      "block": "minecraft:carpet",
      "worldMeta": 14,
      "stackMeta": 14,
      "needsSupportBlock": false
    },
    {
      "x": 3,
      "y": 5,
      "z": 12,
      "fuzzy": false,
      "block": "minecraft:planks",
      "worldMeta": 0,
      "stackMeta": 0,
      "needsSupportBlock": false
    },
    {
      "x": 3,
      "y": 6,
      "z": 2,
      "fuzzy": false,
      "block": "minecraft:planks",
      "worldMeta": 0,
      "stackMeta": 0,
      "needsSupportBlock": false
    },
    {
      "x": 3,
      "y": 6,
      "z": 3,
      "fuzzy": false,
      "block": "minecraft:trapdoor",
      "worldMeta": 13,
      "stackMeta": 0,
      "needsSupportBlock": true,
      "rotationMetaTransform": [
        15,
        13,
        14,
        12
      ]
    },
    {
      "x": 3,
      "y": 6,
      "z": 11,
      "fuzzy": false,
      "block": "minecraft:trapdoor",
      "worldMeta": 12,
      "stackMeta": 0,
      "needsSupportBlock": true,
      "rotationMetaTransform": [
        15,
        13,
        14,
        12
      ]
    },
    {
      "x": 3,
      "y": 6,
      "z": 12,
      "fuzzy": false,
      "block": "minecraft:planks",
      "worldMeta": 0,
      "stackMeta": 0,
      "needsSupportBlock": false
    },
    {
      "x": 3,
      "y": 7,
      "z": 1,
      "fuzzy": false,
      "block": "minecraft:brick_stairs",
      "worldMeta": 5,
      "stackMeta": 0,
      "needsSupportBlock": false,
      "rotationMetaTransform": [
        6,
        5,
        7,
        4
      ]
    },
    {
      "x": 3,
      "y": 7,
      "z": 2,
      "fuzzy": false,
      "block": "minecraft:planks",
      "worldMeta": 0,
      "stackMeta": 0,
      "needsSupportBlock": false
    },
    {
      "x": 3,
      "y": 7,
      "z": 3,
      "fuzzy": false,
      "block": "minecraft:brick_stairs",
      "worldMeta": 5,
      "stackMeta": 0,
      "needsSupportBlock": false,
      "rotationMetaTransform": [
        6,
        5,
        7,
        4
      ]
    },
    {
      "x": 3,
      "y": 7,
      "z": 4,
      "fuzzy": false,
      "block": "minecraft:brick_stairs",
      "worldMeta": 5,
      "stackMeta": 0,
      "needsSupportBlock": false,
      "rotationMetaTransform": [
        6,
        5,
        7,
        4
      ]
    },
    {
      "x": 3,
      "y": 7,
      "z": 5,
      "fuzzy": false,
      "block": "minecraft:brick_stairs",
      "worldMeta": 5,
      "stackMeta": 0,
      "needsSupportBlock": false,
      "rotationMetaTransform": [
        6,
        5,
        7,
        4
      ]
    },
    {
      "x": 3,
      "y": 7,
      "z": 6,
      "fuzzy": false,
      "block": "minecraft:brick_stairs",
      "worldMeta": 5,
      "stackMeta": 0,
      "needsSupportBlock": false,
      "rotationMetaTransform": [
        6,
        5,
        7,
        4
      ]
    },
    {
      "x": 3,
      "y": 7,
      "z": 7,
      "fuzzy": false,
      "block": "minecraft:brick_stairs",
      "worldMeta": 5,
      "stackMeta": 0,
      "needsSupportBlock": false,
      "rotationMetaTransform": [
        6,
        5,
        7,
        4
      ]
    },
    {
      "x": 3,
      "y": 7,
      "z": 8,
      "fuzzy": false,
      "block": "minecraft:brick_stairs",
      "worldMeta": 5,
      "stackMeta": 0,
      "needsSupportBlock": false,
      "rotationMetaTransform": [
        6,
        5,
        7,
        4
      ]
    },
    {
      "x": 3,
      "y": 7,
      "z": 9,
      "fuzzy": false,
      "block": "minecraft:brick_stairs",
      "worldMeta": 5,
      "stackMeta": 0,
      "needsSupportBlock": false,
      "rotationMetaTransform": [
        6,
        5,
        7,
        4
      ]
    },
    {
      "x": 3,
      "y": 7,
      "z": 10,
      "fuzzy": false,
      "block": "minecraft:brick_stairs",
      "worldMeta": 5,
      "stackMeta": 0,
      "needsSupportBlock": false,
      "rotationMetaTransform": [
        6,
        5,
        7,
        4
      ]
    },
    {
      "x": 3,
      "y": 7,
      "z": 11,
      "fuzzy": false,
      "block": "minecraft:brick_stairs",
      "worldMeta": 5,
      "stackMeta": 0,
      "needsSupportBlock": false,
      "rotationMetaTransform": [
        6,
        5,
        7,
        4
      ]
    },
    {
      "x": 3,
      "y": 7,
      "z": 12,
      "fuzzy": false,
      "block": "minecraft:planks",
      "worldMeta": 0,
      "stackMeta": 0,
      "needsSupportBlock": false
    },
    {
      "x": 3,
      "y": 7,
      "z": 13,
      "fuzzy": false,
      "block": "minecraft:brick_stairs",
      "worldMeta": 5,
      "stackMeta": 0,
      "needsSupportBlock": false,
      "rotationMetaTransform": [
        6,
        5,
        7,
        4
      ]
    },
    {
      "x": 3,
      "y": 8,
      "z": 1,
      "fuzzy": false,
      "block": "minecraft:brick_stairs",
      "worldMeta": 0,
      "stackMeta": 0,
      "needsSupportBlock": false,
      "rotationMetaTransform": [
        2,
        1,
        3,
        0
      ]
    },
    {
      "x": 3,
      "y": 8,
      "z": 2,
      "fuzzy": false,
      "block": "minecraft:brick_stairs",
      "worldMeta": 0,
      "stackMeta": 0,
      "needsSupportBlock": false,
      "rotationMetaTransform": [
        2,
        1,
        3,
        0
      ]
    },
    {
      "x": 3,
      "y": 8,
      "z": 3,
      "fuzzy": false,
      "block": "minecraft:brick_stairs",
      "worldMeta": 0,
      "stackMeta": 0,
      "needsSupportBlock": false,
      "rotationMetaTransform": [
        2,
        1,
        3,
        0
      ]
    },
    {
      "x": 3,
      "y": 8,
      "z": 4,
      "fuzzy": false,
      "block": "minecraft:brick_stairs",
      "worldMeta": 0,
      "stackMeta": 0,
      "needsSupportBlock": false,
      "rotationMetaTransform": [
        2,
        1,
        3,
        0
      ]
    },
    {
      "x": 3,
      "y": 8,
      "z": 5,
      "fuzzy": false,
      "block": "minecraft:brick_stairs",
      "worldMeta": 0,
      "stackMeta": 0,
      "needsSupportBlock": false,
      "rotationMetaTransform": [
        2,
        1,
        3,
        0
      ]
    },
    {
      "x": 3,
      "y": 8,
      "z": 6,
      "fuzzy": false,
      "block": "minecraft:brick_stairs",
      "worldMeta": 0,
      "stackMeta": 0,
      "needsSupportBlock": false,
      "rotationMetaTransform": [
        2,
        1,
        3,
        0
      ]
    },
    {
      "x": 3,
      "y": 8,
      "z": 7,
      "fuzzy": false,
      "block": "minecraft:brick_stairs",
      "worldMeta": 0,
      "stackMeta": 0,
      "needsSupportBlock": false,
      "rotationMetaTransform": [
        2,
        1,
        3,
        0
      ]
    },
    {
      "x": 3,
      "y": 8,
      "z": 8,
      "fuzzy": false,
      "block": "minecraft:brick_stairs",
      "worldMeta": 0,
      "stackMeta": 0,
      "needsSupportBlock": false,
      "rotationMetaTransform": [
        2,
        1,
        3,
        0
      ]
    },
    {
      "x": 3,
      "y": 8,
      "z": 9,
      "fuzzy": false,
      "block": "minecraft:brick_stairs",
      "worldMeta": 0,
      "stackMeta": 0,
      "needsSupportBlock": false,
      "rotationMetaTransform": [
        2,
        1,
        3,
        0
      ]
    },
    {
      "x": 3,
      "y": 8,
      "z": 10,
      "fuzzy": false,
      "block": "minecraft:brick_stairs",
      "worldMeta": 0,
      "stackMeta": 0,
      "needsSupportBlock": false,
      "rotationMetaTransform": [
        2,
        1,
        3,
        0
      ]
    },
    {
      "x": 3,
      "y": 8,
      "z": 11,
      "fuzzy": false,
      "block": "minecraft:brick_stairs",
      "worldMeta": 0,
      "stackMeta": 0,
      "needsSupportBlock": false,
      "rotationMetaTransform": [
        2,
        1,
        3,
        0
      ]
    },
    {
      "x": 3,
      "y": 8,
      "z": 12,
      "fuzzy": false,
      "block": "minecraft:brick_stairs",
      "worldMeta": 0,
      "stackMeta": 0,
      "needsSupportBlock": false,
      "rotationMetaTransform": [
        2,
        1,
        3,
        0
      ]
    },
    {
      "x": 3,
      "y": 8,
      "z": 13,
      "fuzzy": false,
      "block": "minecraft:brick_stairs",
      "worldMeta": 0,
      "stackMeta": 0,
      "needsSupportBlock": false,
      "rotationMetaTransform": [
        2,
        1,
        3,
        0
      ]
    },
    {
      "x": 4,
      "y": 0,
      "z": 0,
      "fuzzy": false,
      "block": "minecraft:trapdoor",
      "worldMeta": 12,
      "stackMeta": 0,
      "needsSupportBlock": true,
      "rotationMetaTransform": [
        15,
        13,
        14,
        12
      ]
    },
    {
      "x": 4,
      "y": 0,
      "z": 1,
      "fuzzy": false,
      "block": "minecraft:grass",
      "worldMeta": 0,
      "stackMeta": 0,
      "needsSupportBlock": false
    },
    {
      "x": 4,
      "y": 0,
      "z": 2,
      "fuzzy": false,
      "block": "minecraft:cobblestone",
      "worldMeta": 0,
      "stackMeta": 0,
      "needsSupportBlock": false
    },
    {
      "x": 4,
      "y": 0,
      "z": 3,
      "fuzzy": false,
      "block": "minecraft:cobblestone",
      "worldMeta": 0,
      "stackMeta": 0,
      "needsSupportBlock": false
    },
    {
      "x": 4,
      "y": 0,
      "z": 4,
      "fuzzy": false,
      "block": "minecraft:cobblestone",
      "worldMeta": 0,
      "stackMeta": 0,
      "needsSupportBlock": false
    },
    {
      "x": 4,
      "y": 0,
      "z": 5,
      "fuzzy": false,
      "block": "minecraft:cobblestone",
      "worldMeta": 0,
      "stackMeta": 0,
      "needsSupportBlock": false
    },
    {
      "x": 4,
      "y": 0,
      "z": 6,
      "fuzzy": false,
      "block": "minecraft:cobblestone",
      "worldMeta": 0,
      "stackMeta": 0,
      "needsSupportBlock": false
    },
    {
      "x": 4,
      "y": 0,
      "z": 7,
      "fuzzy": false,
      "block": "minecraft:cobblestone",
      "worldMeta": 0,
      "stackMeta": 0,
      "needsSupportBlock": false
    },
    {
      "x": 4,
      "y": 0,
      "z": 8,
      "fuzzy": false,
      "block": "minecraft:cobblestone",
      "worldMeta": 0,
      "stackMeta": 0,
      "needsSupportBlock": false
    },
    {
      "x": 4,
      "y": 0,
      "z": 9,
      "fuzzy": false,
      "block": "minecraft:cobblestone",
      "worldMeta": 0,
      "stackMeta": 0,
      "needsSupportBlock": false
    },
    {
      "x": 4,
      "y": 0,
      "z": 10,
      "fuzzy": false,
      "block": "minecraft:cobblestone",
      "worldMeta": 0,
      "stackMeta": 0,
      "needsSupportBlock": false
    },
    {
      "x": 4,
      "y": 0,
      "z": 11,
      "fuzzy": false,
      "block": "minecraft:cobblestone",
      "worldMeta": 0,
      "stackMeta": 0,
      "needsSupportBlock": false
    },
    {
      "x": 4,
      "y": 0,
      "z": 12,
      "fuzzy": false,
      "block": "minecraft:cobblestone",
      "worldMeta": 0,
      "stackMeta": 0,
      "needsSupportBlock": false
    },
    {
      "x": 4,
      "y": 0,
      "z": 13,
      "fuzzy": false,
      "block": "minecraft:grass",
      "worldMeta": 0,
      "stackMeta": 0,
      "needsSupportBlock": false
    },
    {
      "x": 4,
      "y": 0,
      "z": 14,
      "fuzzy": false,
      "block": "minecraft:trapdoor",
      "worldMeta": 13,
      "stackMeta": 0,
      "needsSupportBlock": true,
      "rotationMetaTransform": [
        15,
        13,
        14,
        12
      ]
    },
    {
      "x": 4,
      "y": 1,
      "z": 2,
      "fuzzy": false,
      "block": "minecraft:oak_stairs",
      "worldMeta": 2,
      "stackMeta": 0,
      "needsSupportBlock": false,
      "rotationMetaTransform": [
        2,
        1,
        3,
        0
      ]
    },
    {
      "x": 4,
      "y": 1,
      "z": 3,
      "fuzzy": false,
      "block": "minecraft:chest",
      "worldMeta": 3,
      "stackMeta": 0,
      "needsSupportBlock": false,
      "rotationMetaTransform": [
        5,
        3,
        4,
        2
      ],
      "nbtString": "{x:-1666,y:5,z:-31,Items:[],id:\"Chest\",Lock:\"\"}"
    },
    {
      "x": 4,
      "y": 1,
      "z": 4,
      "fuzzy": false,
      "block": "minecraft:carpet",
      "worldMeta": 14,
      "stackMeta": 14,
      "needsSupportBlock": false
    },
    {
      "x": 4,
      "y": 1,
      "z": 5,
      "fuzzy": false,
      "block": "minecraft:carpet",
      "worldMeta": 14,
      "stackMeta": 14,
      "needsSupportBlock": false
    },
    {
      "x": 4,
      "y": 1,
      "z": 7,
      "fuzzy": false,
      "block": "minecraft:oak_stairs",
      "worldMeta": 6,
      "stackMeta": 0,
      "needsSupportBlock": false,
      "rotationMetaTransform": [
        6,
        5,
        7,
        4
      ]
    },
    {
      "x": 4,
      "y": 1,
      "z": 8,
      "fuzzy": false,
      "block": "minecraft:oak_stairs",
      "worldMeta": 3,
      "stackMeta": 0,
      "needsSupportBlock": false,
      "rotationMetaTransform": [
        2,
        1,
        3,
        0
      ]
    },
    {
      "x": 4,
      "y": 1,
      "z": 9,
      "fuzzy": false,
      "block": "minecraft:carpet",
      "worldMeta": 14,
      "stackMeta": 14,
      "needsSupportBlock": false
    },
    {
      "x": 4,
      "y": 1,
      "z": 10,
      "fuzzy": false,
      "block": "minecraft:carpet",
      "worldMeta": 14,
      "stackMeta": 14,
      "needsSupportBlock": false
    },
    {
      "x": 4,
      "y": 1,
      "z": 11,
      "fuzzy": false,
      "block": "minecraft:stone_stairs",
      "worldMeta": 5,
      "stackMeta": 0,
      "needsSupportBlock": false,
      "rotationMetaTransform": [
        6,
        5,
        7,
        4
      ]
    },
    {
      "x": 4,
      "y": 1,
      "z": 12,
      "fuzzy": false,
      "block": "minecraft:oak_stairs",
      "worldMeta": 3,
      "stackMeta": 0,
      "needsSupportBlock": false,
      "rotationMetaTransform": [
        2,
        1,
        3,
        0
      ]
    },
    {
      "x": 4,
      "y": 2,
      "z": 2,
      "fuzzy": false,
      "block": "minecraft:glass_pane",
      "worldMeta": 0,
      "stackMeta": 0,
      "needsSupportBlock": false
    },
    {
      "x": 4,
      "y": 2,
      "z": 6,
      "fuzzy": false,
      "block": "minecraft:oak_stairs",
      "worldMeta": 6,
      "stackMeta": 0,
      "needsSupportBlock": false,
      "rotationMetaTransform": [
        6,
        5,
        7,
        4
      ]
    },
    {
      "x": 4,
      "y": 2,
      "z": 7,
      "fuzzy": false,
      "block": "minecraft:oak_stairs",
      "worldMeta": 3,
      "stackMeta": 0,
      "needsSupportBlock": false,
      "rotationMetaTransform": [
        2,
        1,
        3,
        0
      ]
    },
    {
      "x": 4,
      "y": 2,
      "z": 12,
      "fuzzy": false,
      "block": "minecraft:glass_pane",
      "worldMeta": 0,
      "stackMeta": 0,
      "needsSupportBlock": false
    },
    {
      "x": 4,
      "y": 3,
      "z": 2,
      "fuzzy": false,
      "block": "minecraft:oak_stairs",
      "worldMeta": 6,
      "stackMeta": 0,
      "needsSupportBlock": false,
      "rotationMetaTransform": [
        6,
        5,
        7,
        4
      ]
    },
    {
      "x": 4,
      "y": 3,
      "z": 5,
      "fuzzy": false,
      "block": "minecraft:oak_stairs",
      "worldMeta": 6,
      "stackMeta": 0,
      "needsSupportBlock": false,
      "rotationMetaTransform": [
        6,
        5,
        7,
        4
      ]
    },
    {
      "x": 4,
      "y": 3,
      "z": 6,
      "fuzzy": false,
      "block": "minecraft:oak_stairs",
      "worldMeta": 3,
      "stackMeta": 0,
      "needsSupportBlock": false,
      "rotationMetaTransform": [
        2,
        1,
        3,
        0
      ]
    },
    {
      "x": 4,
      "y": 3,
      "z": 12,
      "fuzzy": false,
      "block": "minecraft:oak_stairs",
      "worldMeta": 7,
      "stackMeta": 0,
      "needsSupportBlock": false,
      "rotationMetaTransform": [
        6,
        5,
        7,
        4
      ]
    },
    {
      "x": 4,
      "y": 4,
      "z": 2,
      "fuzzy": false,
      "block": "minecraft:log",
      "worldMeta": 4,
      "stackMeta": 0,
      "needsSupportBlock": false,
      "rotationMetaTransform": [
        4,
        8,
        4,
        8
      ]
    },
    {
      "x": 4,
      "y": 4,
      "z": 3,
      "fuzzy": false,
      "block": "minecraft:wooden_slab",
      "worldMeta": 8,
      "stackMeta": 0,
      "needsSupportBlock": false
    },
    {
      "x": 4,
      "y": 4,
      "z": 4,
      "fuzzy": false,
      "block": "minecraft:wooden_slab",
      "worldMeta": 8,
      "stackMeta": 0,
      "needsSupportBlock": false
    },
    {
      "x": 4,
      "y": 4,
      "z": 5,
      "fuzzy": false,
      "block": "minecraft:oak_stairs",
      "worldMeta": 3,
      "stackMeta": 0,
      "needsSupportBlock": false,
      "rotationMetaTransform": [
        2,
        1,
        3,
        0
      ]
    },
    {
      "x": 4,
      "y": 4,
      "z": 9,
      "fuzzy": false,
      "block": "minecraft:wooden_slab",
      "worldMeta": 8,
      "stackMeta": 0,
      "needsSupportBlock": false
    },
    {
      "x": 4,
      "y": 4,
      "z": 10,
      "fuzzy": false,
      "block": "minecraft:wooden_slab",
      "worldMeta": 8,
      "stackMeta": 0,
      "needsSupportBlock": false
    },
    {
      "x": 4,
      "y": 4,
      "z": 11,
      "fuzzy": false,
      "block": "minecraft:wooden_slab",
      "worldMeta": 8,
      "stackMeta": 0,
      "needsSupportBlock": false
    },
    {
      "x": 4,
      "y": 4,
      "z": 12,
      "fuzzy": false,
      "block": "minecraft:log",
      "worldMeta": 4,
      "stackMeta": 0,
      "needsSupportBlock": false,
      "rotationMetaTransform": [
        4,
        8,
        4,
        8
      ]
    },
    {
      "x": 4,
      "y": 5,
      "z": 2,
      "fuzzy": false,
      "block": "minecraft:oak_stairs",
      "worldMeta": 2,
      "stackMeta": 0,
      "needsSupportBlock": false,
      "rotationMetaTransform": [
        2,
        1,
        3,
        0
      ]
    },
    {
      "x": 4,
      "y": 5,
      "z": 3,
      "fuzzy": false,
      "block": "minecraft:carpet",
      "worldMeta": 14,
      "stackMeta": 14,
      "needsSupportBlock": false
    },
    {
      "x": 4,
      "y": 5,
      "z": 4,
      "fuzzy": false,
      "block": "minecraft:carpet",
      "worldMeta": 14,
      "stackMeta": 14,
      "needsSupportBlock": false
    },
    {
      "x": 4,
      "y": 5,
      "z": 9,
      "fuzzy": false,
      "block": "minecraft:carpet",
      "worldMeta": 14,
      "stackMeta": 14,
      "needsSupportBlock": false
    },
    {
      "x": 4,
      "y": 5,
      "z": 10,
      "fuzzy": false,
      "block": "minecraft:carpet",
      "worldMeta": 14,
      "stackMeta": 14,
      "needsSupportBlock": false
    },
    {
      "x": 4,
      "y": 5,
      "z": 11,
      "fuzzy": false,
      "block": "minecraft:carpet",
      "worldMeta": 14,
      "stackMeta": 14,
      "needsSupportBlock": false
    },
    {
      "x": 4,
      "y": 5,
      "z": 12,
      "fuzzy": false,
      "block": "minecraft:oak_stairs",
      "worldMeta": 3,
      "stackMeta": 0,
      "needsSupportBlock": false,
      "rotationMetaTransform": [
        2,
        1,
        3,
        0
      ]
    },
    {
      "x": 4,
      "y": 6,
      "z": 2,
      "fuzzy": false,
      "block": "minecraft:glass_pane",
      "worldMeta": 0,
      "stackMeta": 0,
      "needsSupportBlock": false
    },
    {
      "x": 4,
      "y": 6,
      "z": 12,
      "fuzzy": false,
      "block": "minecraft:glass_pane",
      "worldMeta": 0,
      "stackMeta": 0,
      "needsSupportBlock": false
    },
    {
      "x": 4,
      "y": 7,
      "z": 2,
      "fuzzy": false,
      "block": "minecraft:oak_stairs",
      "worldMeta": 6,
      "stackMeta": 0,
      "needsSupportBlock": false,
      "rotationMetaTransform": [
        6,
        5,
        7,
        4
      ]
    },
    {
      "x": 4,
      "y": 7,
      "z": 12,
      "fuzzy": false,
      "block": "minecraft:oak_stairs",
      "worldMeta": 7,
      "stackMeta": 0,
      "needsSupportBlock": false,
      "rotationMetaTransform": [
        6,
        5,
        7,
        4
      ]
    },
    {
      "x": 4,
      "y": 8,
      "z": 1,
      "fuzzy": false,
      "block": "minecraft:brick_stairs",
      "worldMeta": 5,
      "stackMeta": 0,
      "needsSupportBlock": false,
      "rotationMetaTransform": [
        6,
        5,
        7,
        4
      ]
    },
    {
      "x": 4,
      "y": 8,
      "z": 2,
      "fuzzy": false,
      "block": "minecraft:planks",
      "worldMeta": 0,
      "stackMeta": 0,
      "needsSupportBlock": false
    },
    {
      "x": 4,
      "y": 8,
      "z": 3,
      "fuzzy": false,
      "block": "minecraft:brick_stairs",
      "worldMeta": 5,
      "stackMeta": 0,
      "needsSupportBlock": false,
      "rotationMetaTransform": [
        6,
        5,
        7,
        4
      ]
    },
    {
      "x": 4,
      "y": 8,
      "z": 4,
      "fuzzy": false,
      "block": "minecraft:brick_stairs",
      "worldMeta": 5,
      "stackMeta": 0,
      "needsSupportBlock": false,
      "rotationMetaTransform": [
        6,
        5,
        7,
        4
      ]
    },
    {
      "x": 4,
      "y": 8,
      "z": 5,
      "fuzzy": false,
      "block": "minecraft:log",
      "worldMeta": 4,
      "stackMeta": 0,
      "needsSupportBlock": false,
      "rotationMetaTransform": [
        4,
        8,
        4,
        8
      ]
    },
    {
      "x": 4,
      "y": 8,
      "z": 6,
      "fuzzy": false,
      "block": "minecraft:wooden_slab",
      "worldMeta": 8,
      "stackMeta": 0,
      "needsSupportBlock": false
    },
    {
      "x": 4,
      "y": 8,
      "z": 7,
      "fuzzy": false,
      "block": "minecraft:wooden_slab",
      "worldMeta": 8,
      "stackMeta": 0,
      "needsSupportBlock": false
    },
    {
      "x": 4,
      "y": 8,
      "z": 8,
      "fuzzy": false,
      "block": "minecraft:wooden_slab",
      "worldMeta": 8,
      "stackMeta": 0,
      "needsSupportBlock": false
    },
    {
      "x": 4,
      "y": 8,
      "z": 9,
      "fuzzy": false,
      "block": "minecraft:log",
      "worldMeta": 4,
      "stackMeta": 0,
      "needsSupportBlock": false,
      "rotationMetaTransform": [
        4,
        8,
        4,
        8
      ]
    },
    {
      "x": 4,
      "y": 8,
      "z": 10,
      "fuzzy": false,
      "block": "minecraft:brick_stairs",
      "worldMeta": 5,
      "stackMeta": 0,
      "needsSupportBlock": false,
      "rotationMetaTransform": [
        6,
        5,
        7,
        4
      ]
    },
    {
      "x": 4,
      "y": 8,
      "z": 11,
      "fuzzy": false,
      "block": "minecraft:brick_stairs",
      "worldMeta": 5,
      "stackMeta": 0,
      "needsSupportBlock": false,
      "rotationMetaTransform": [
        6,
        5,
        7,
        4
      ]
    },
    {
      "x": 4,
      "y": 8,
      "z": 12,
      "fuzzy": false,
      "block": "minecraft:planks",
      "worldMeta": 0,
      "stackMeta": 0,
      "needsSupportBlock": false
    },
    {
      "x": 4,
      "y": 8,
      "z": 13,
      "fuzzy": false,
      "block": "minecraft:brick_stairs",
      "worldMeta": 5,
      "stackMeta": 0,
      "needsSupportBlock": false,
      "rotationMetaTransform": [
        6,
        5,
        7,
        4
      ]
    },
    {
      "x": 4,
      "y": 9,
      "z": 1,
      "fuzzy": false,
      "block": "minecraft:brick_stairs",
      "worldMeta": 0,
      "stackMeta": 0,
      "needsSupportBlock": false,
      "rotationMetaTransform": [
        2,
        1,
        3,
        0
      ]
    },
    {
      "x": 4,
      "y": 9,
      "z": 2,
      "fuzzy": false,
      "block": "minecraft:brick_stairs",
      "worldMeta": 0,
      "stackMeta": 0,
      "needsSupportBlock": false,
      "rotationMetaTransform": [
        2,
        1,
        3,
        0
      ]
    },
    {
      "x": 4,
      "y": 9,
      "z": 3,
      "fuzzy": false,
      "block": "minecraft:brick_stairs",
      "worldMeta": 0,
      "stackMeta": 0,
      "needsSupportBlock": false,
      "rotationMetaTransform": [
        2,
        1,
        3,
        0
      ]
    },
    {
      "x": 4,
      "y": 9,
      "z": 4,
      "fuzzy": false,
      "block": "minecraft:brick_stairs",
      "worldMeta": 0,
      "stackMeta": 0,
      "needsSupportBlock": false,
      "rotationMetaTransform": [
        2,
        1,
        3,
        0
      ]
    },
    {
      "x": 4,
      "y": 9,
      "z": 5,
      "fuzzy": false,
      "block": "minecraft:brick_stairs",
      "worldMeta": 0,
      "stackMeta": 0,
      "needsSupportBlock": false,
      "rotationMetaTransform": [
        2,
        1,
        3,
        0
      ]
    },
    {
      "x": 4,
      "y": 9,
      "z": 6,
      "fuzzy": false,
      "block": "minecraft:brick_stairs",
      "worldMeta": 0,
      "stackMeta": 0,
      "needsSupportBlock": false,
      "rotationMetaTransform": [
        2,
        1,
        3,
        0
      ]
    },
    {
      "x": 4,
      "y": 9,
      "z": 7,
      "fuzzy": false,
      "block": "minecraft:brick_stairs",
      "worldMeta": 0,
      "stackMeta": 0,
      "needsSupportBlock": false,
      "rotationMetaTransform": [
        2,
        1,
        3,
        0
      ]
    },
    {
      "x": 4,
      "y": 9,
      "z": 8,
      "fuzzy": false,
      "block": "minecraft:brick_stairs",
      "worldMeta": 0,
      "stackMeta": 0,
      "needsSupportBlock": false,
      "rotationMetaTransform": [
        2,
        1,
        3,
        0
      ]
    },
    {
      "x": 4,
      "y": 9,
      "z": 9,
      "fuzzy": false,
      "block": "minecraft:brick_stairs",
      "worldMeta": 0,
      "stackMeta": 0,
      "needsSupportBlock": false,
      "rotationMetaTransform": [
        2,
        1,
        3,
        0
      ]
    },
    {
      "x": 4,
      "y": 9,
      "z": 10,
      "fuzzy": false,
      "block": "minecraft:brick_stairs",
      "worldMeta": 0,
      "stackMeta": 0,
      "needsSupportBlock": false,
      "rotationMetaTransform": [
        2,
        1,
        3,
        0
      ]
    },
    {
      "x": 4,
      "y": 9,
      "z": 11,
      "fuzzy": false,
      "block": "minecraft:brick_stairs",
      "worldMeta": 0,
      "stackMeta": 0,
      "needsSupportBlock": false,
      "rotationMetaTransform": [
        2,
        1,
        3,
        0
      ]
    },
    {
      "x": 4,
      "y": 9,
      "z": 12,
      "fuzzy": false,
      "block": "minecraft:brick_stairs",
      "worldMeta": 0,
      "stackMeta": 0,
      "needsSupportBlock": false,
      "rotationMetaTransform": [
        2,
        1,
        3,
        0
      ]
    },
    {
      "x": 4,
      "y": 9,
      "z": 13,
      "fuzzy": false,
      "block": "minecraft:brick_stairs",
      "worldMeta": 0,
      "stackMeta": 0,
      "needsSupportBlock": false,
      "rotationMetaTransform": [
        2,
        1,
        3,
        0
      ]
    },
    {
      "x": 5,
      "y": 0,
      "z": 0,
      "fuzzy": false,
      "block": "minecraft:trapdoor",
      "worldMeta": 12,
      "stackMeta": 0,
      "needsSupportBlock": true,
      "rotationMetaTransform": [
        15,
        13,
        14,
        12
      ]
    },
    {
      "x": 5,
      "y": 0,
      "z": 1,
      "fuzzy": false,
      "block": "minecraft:grass",
      "worldMeta": 0,
      "stackMeta": 0,
      "needsSupportBlock": false
    },
    {
      "x": 5,
      "y": 0,
      "z": 2,
      "fuzzy": false,
      "block": "minecraft:cobblestone",
      "worldMeta": 0,
      "stackMeta": 0,
      "needsSupportBlock": false
    },
    {
      "x": 5,
      "y": 0,
      "z": 3,
      "fuzzy": false,
      "block": "minecraft:cobblestone",
      "worldMeta": 0,
      "stackMeta": 0,
      "needsSupportBlock": false
    },
    {
      "x": 5,
      "y": 0,
      "z": 4,
      "fuzzy": false,
      "block": "minecraft:cobblestone",
      "worldMeta": 0,
      "stackMeta": 0,
      "needsSupportBlock": false
    },
    {
      "x": 5,
      "y": 0,
      "z": 5,
      "fuzzy": false,
      "block": "minecraft:cobblestone",
      "worldMeta": 0,
      "stackMeta": 0,
      "needsSupportBlock": false
    },
    {
      "x": 5,
      "y": 0,
      "z": 6,
      "fuzzy": false,
      "block": "minecraft:cobblestone",
      "worldMeta": 0,
      "stackMeta": 0,
      "needsSupportBlock": false
    },
    {
      "x": 5,
      "y": 0,
      "z": 7,
      "fuzzy": false,
      "block": "minecraft:cobblestone",
      "worldMeta": 0,
      "stackMeta": 0,
      "needsSupportBlock": false
    },
    {
      "x": 5,
      "y": 0,
      "z": 8,
      "fuzzy": false,
      "block": "minecraft:cobblestone",
      "worldMeta": 0,
      "stackMeta": 0,
      "needsSupportBlock": false
    },
    {
      "x": 5,
      "y": 0,
      "z": 9,
      "fuzzy": false,
      "block": "minecraft:cobblestone",
      "worldMeta": 0,
      "stackMeta": 0,
      "needsSupportBlock": false
    },
    {
      "x": 5,
      "y": 0,
      "z": 10,
      "fuzzy": false,
      "block": "minecraft:cobblestone",
      "worldMeta": 0,
      "stackMeta": 0,
      "needsSupportBlock": false
    },
    {
      "x": 5,
      "y": 0,
      "z": 11,
      "fuzzy": false,
      "block": "minecraft:cobblestone",
      "worldMeta": 0,
      "stackMeta": 0,
      "needsSupportBlock": false
    },
    {
      "x": 5,
      "y": 0,
      "z": 12,
      "fuzzy": false,
      "block": "minecraft:cobblestone",
      "worldMeta": 0,
      "stackMeta": 0,
      "needsSupportBlock": false
    },
    {
      "x": 5,
      "y": 0,
      "z": 13,
      "fuzzy": false,
      "block": "minecraft:grass",
      "worldMeta": 0,
      "stackMeta": 0,
      "needsSupportBlock": false
    },
    {
      "x": 5,
      "y": 0,
      "z": 14,
      "fuzzy": false,
      "block": "minecraft:trapdoor",
      "worldMeta": 13,
      "stackMeta": 0,
      "needsSupportBlock": true,
      "rotationMetaTransform": [
        15,
        13,
        14,
        12
      ]
    },
    {
      "x": 5,
      "y": 1,
      "z": 2,
      "fuzzy": false,
      "block": "minecraft:planks",
      "worldMeta": 0,
      "stackMeta": 0,
      "needsSupportBlock": false
    },
    {
      "x": 5,
      "y": 1,
      "z": 3,
      "fuzzy": false,
      "block": "minecraft:crafting_table",
      "worldMeta": 0,
      "stackMeta": 0,
      "needsSupportBlock": false
    },
    {
      "x": 5,
      "y": 1,
      "z": 4,
      "fuzzy": false,
      "block": "minecraft:carpet",
      "worldMeta": 14,
      "stackMeta": 14,
      "needsSupportBlock": false
    },
    {
      "x": 5,
      "y": 1,
      "z": 5,
      "fuzzy": false,
      "block": "minecraft:carpet",
      "worldMeta": 14,
      "stackMeta": 14,
      "needsSupportBlock": false
    },
    {
      "x": 5,
      "y": 1,
      "z": 7,
      "fuzzy": false,
      "block": "minecraft:oak_stairs",
      "worldMeta": 6,
      "stackMeta": 0,
      "needsSupportBlock": false,
      "rotationMetaTransform": [
        6,
        5,
        7,
        4
      ]
    },
    {
      "x": 5,
      "y": 1,
      "z": 8,
      "fuzzy": false,
      "block": "minecraft:oak_stairs",
      "worldMeta": 3,
      "stackMeta": 0,
      "needsSupportBlock": false,
      "rotationMetaTransform": [
        2,
        1,
        3,
        0
      ]
    },
    {
      "x": 5,
      "y": 1,
      "z": 9,
      "fuzzy": false,
      "block": "minecraft:carpet",
      "worldMeta": 14,
      "stackMeta": 14,
      "needsSupportBlock": false
    },
    {
      "x": 5,
      "y": 1,
      "z": 10,
      "fuzzy": false,
      "block": "minecraft:carpet",
      "worldMeta": 14,
      "stackMeta": 14,
      "needsSupportBlock": false
    },
    {
      "x": 5,
      "y": 1,
      "z": 12,
      "fuzzy": false,
      "block": "minecraft:planks",
      "worldMeta": 0,
      "stackMeta": 0,
      "needsSupportBlock": false
    },
    {
      "x": 5,
      "y": 2,
      "z": 2,
      "fuzzy": false,
      "block": "minecraft:planks",
      "worldMeta": 0,
      "stackMeta": 0,
      "needsSupportBlock": false
    },
    {
      "x": 5,
      "y": 2,
      "z": 3,
      "fuzzy": false,
      "block": "minecraft:trapdoor",
      "worldMeta": 13,
      "stackMeta": 0,
      "needsSupportBlock": true,
      "rotationMetaTransform": [
        15,
        13,
        14,
        12
      ]
    },
    {
      "x": 5,
      "y": 2,
      "z": 6,
      "fuzzy": false,
      "block": "minecraft:oak_stairs",
      "worldMeta": 6,
      "stackMeta": 0,
      "needsSupportBlock": false,
      "rotationMetaTransform": [
        6,
        5,
        7,
        4
      ]
    },
    {
      "x": 5,
      "y": 2,
      "z": 7,
      "fuzzy": false,
      "block": "minecraft:oak_stairs",
      "worldMeta": 3,
      "stackMeta": 0,
      "needsSupportBlock": false,
      "rotationMetaTransform": [
        2,
        1,
        3,
        0
      ]
    },
    {
      "x": 5,
      "y": 2,
      "z": 11,
      "fuzzy": false,
      "block": "minecraft:trapdoor",
      "worldMeta": 12,
      "stackMeta": 0,
      "needsSupportBlock": true,
      "rotationMetaTransform": [
        15,
        13,
        14,
        12
      ]
    },
    {
      "x": 5,
      "y": 2,
      "z": 12,
      "fuzzy": false,
      "block": "minecraft:planks",
      "worldMeta": 0,
      "stackMeta": 0,
      "needsSupportBlock": false
    },
    {
      "x": 5,
      "y": 3,
      "z": 2,
      "fuzzy": false,
      "block": "minecraft:planks",
      "worldMeta": 0,
      "stackMeta": 0,
      "needsSupportBlock": false
    },
    {
      "x": 5,
      "y": 3,
      "z": 5,
      "fuzzy": false,
      "block": "minecraft:oak_stairs",
      "worldMeta": 6,
      "stackMeta": 0,
      "needsSupportBlock": false,
      "rotationMetaTransform": [
        6,
        5,
        7,
        4
      ]
    },
    {
      "x": 5,
      "y": 3,
      "z": 6,
      "fuzzy": false,
      "block": "minecraft:oak_stairs",
      "worldMeta": 3,
      "stackMeta": 0,
      "needsSupportBlock": false,
      "rotationMetaTransform": [
        2,
        1,
        3,
        0
      ]
    },
    {
      "x": 5,
      "y": 3,
      "z": 12,
      "fuzzy": false,
      "block": "minecraft:planks",
      "worldMeta": 0,
      "stackMeta": 0,
      "needsSupportBlock": false
    },
    {
      "x": 5,
      "y": 4,
      "z": 2,
      "fuzzy": false,
      "block": "minecraft:log",
      "worldMeta": 4,
      "stackMeta": 0,
      "needsSupportBlock": false,
      "rotationMetaTransform": [
        4,
        8,
        4,
        8
      ]
    },
    {
      "x": 5,
      "y": 4,
      "z": 3,
      "fuzzy": false,
      "block": "minecraft:wooden_slab",
      "worldMeta": 8,
      "stackMeta": 0,
      "needsSupportBlock": false
    },
    {
      "x": 5,
      "y": 4,
      "z": 4,
      "fuzzy": false,
      "block": "minecraft:wooden_slab",
      "worldMeta": 8,
      "stackMeta": 0,
      "needsSupportBlock": false
    },
    {
      "x": 5,
      "y": 4,
      "z": 5,
      "fuzzy": false,
      "block": "minecraft:oak_stairs",
      "worldMeta": 3,
      "stackMeta": 0,
      "needsSupportBlock": false,
      "rotationMetaTransform": [
        2,
        1,
        3,
        0
      ]
    },
    {
      "x": 5,
      "y": 4,
      "z": 9,
      "fuzzy": false,
      "block": "minecraft:wooden_slab",
      "worldMeta": 8,
      "stackMeta": 0,
      "needsSupportBlock": false
    },
    {
      "x": 5,
      "y": 4,
      "z": 10,
      "fuzzy": false,
      "block": "minecraft:wooden_slab",
      "worldMeta": 8,
      "stackMeta": 0,
      "needsSupportBlock": false
    },
    {
      "x": 5,
      "y": 4,
      "z": 11,
      "fuzzy": false,
      "block": "minecraft:wooden_slab",
      "worldMeta": 8,
      "stackMeta": 0,
      "needsSupportBlock": false
    },
    {
      "x": 5,
      "y": 4,
      "z": 12,
      "fuzzy": false,
      "block": "minecraft:log",
      "worldMeta": 4,
      "stackMeta": 0,
      "needsSupportBlock": false,
      "rotationMetaTransform": [
        4,
        8,
        4,
        8
      ]
    },
    {
      "x": 5,
      "y": 5,
      "z": 2,
      "fuzzy": false,
      "block": "minecraft:planks",
      "worldMeta": 0,
      "stackMeta": 0,
      "needsSupportBlock": false
    },
    {
      "x": 5,
      "y": 5,
      "z": 3,
      "fuzzy": false,
      "block": "minecraft:carpet",
      "worldMeta": 14,
      "stackMeta": 14,
      "needsSupportBlock": false
    },
    {
      "x": 5,
      "y": 5,
      "z": 4,
      "fuzzy": false,
      "block": "minecraft:carpet",
      "worldMeta": 14,
      "stackMeta": 14,
      "needsSupportBlock": false
    },
    {
      "x": 5,
      "y": 5,
      "z": 9,
      "fuzzy": false,
      "block": "minecraft:carpet",
      "worldMeta": 14,
      "stackMeta": 14,
      "needsSupportBlock": false
    },
    {
      "x": 5,
      "y": 5,
      "z": 10,
      "fuzzy": false,
      "block": "minecraft:carpet",
      "worldMeta": 14,
      "stackMeta": 14,
      "needsSupportBlock": false
    },
    {
      "x": 5,
      "y": 5,
      "z": 11,
      "fuzzy": false,
      "block": "minecraft:carpet",
      "worldMeta": 14,
      "stackMeta": 14,
      "needsSupportBlock": false
    },
    {
      "x": 5,
      "y": 5,
      "z": 12,
      "fuzzy": false,
      "block": "minecraft:planks",
      "worldMeta": 0,
      "stackMeta": 0,
      "needsSupportBlock": false
    },
    {
      "x": 5,
      "y": 6,
      "z": 2,
      "fuzzy": false,
      "block": "minecraft:planks",
      "worldMeta": 0,
      "stackMeta": 0,
      "needsSupportBlock": false
    },
    {
      "x": 5,
      "y": 6,
      "z": 3,
      "fuzzy": false,
      "block": "minecraft:trapdoor",
      "worldMeta": 13,
      "stackMeta": 0,
      "needsSupportBlock": true,
      "rotationMetaTransform": [
        15,
        13,
        14,
        12
      ]
    },
    {
      "x": 5,
      "y": 6,
      "z": 11,
      "fuzzy": false,
      "block": "minecraft:trapdoor",
      "worldMeta": 12,
      "stackMeta": 0,
      "needsSupportBlock": true,
      "rotationMetaTransform": [
        15,
        13,
        14,
        12
      ]
    },
    {
      "x": 5,
      "y": 6,
      "z": 12,
      "fuzzy": false,
      "block": "minecraft:planks",
      "worldMeta": 0,
      "stackMeta": 0,
      "needsSupportBlock": false
    },
    {
      "x": 5,
      "y": 7,
      "z": 2,
      "fuzzy": false,
      "block": "minecraft:planks",
      "worldMeta": 0,
      "stackMeta": 0,
      "needsSupportBlock": false
    },
    {
      "x": 5,
      "y": 7,
      "z": 12,
      "fuzzy": false,
      "block": "minecraft:planks",
      "worldMeta": 0,
      "stackMeta": 0,
      "needsSupportBlock": false
    },
    {
      "x": 5,
      "y": 8,
      "z": 2,
      "fuzzy": false,
      "block": "minecraft:planks",
      "worldMeta": 0,
      "stackMeta": 0,
      "needsSupportBlock": false
    },
    {
      "x": 5,
      "y": 8,
      "z": 5,
      "fuzzy": false,
      "block": "minecraft:log",
      "worldMeta": 4,
      "stackMeta": 0,
      "needsSupportBlock": false,
      "rotationMetaTransform": [
        4,
        8,
        4,
        8
      ]
    },
    {
      "x": 5,
      "y": 8,
      "z": 6,
      "fuzzy": false,
      "block": "minecraft:wooden_slab",
      "worldMeta": 8,
      "stackMeta": 0,
      "needsSupportBlock": false
    },
    {
      "x": 5,
      "y": 8,
      "z": 7,
      "fuzzy": false,
      "block": "minecraft:wooden_slab",
      "worldMeta": 8,
      "stackMeta": 0,
      "needsSupportBlock": false
    },
    {
      "x": 5,
      "y": 8,
      "z": 8,
      "fuzzy": false,
      "block": "minecraft:wooden_slab",
      "worldMeta": 8,
      "stackMeta": 0,
      "needsSupportBlock": false
    },
    {
      "x": 5,
      "y": 8,
      "z": 9,
      "fuzzy": false,
      "block": "minecraft:log",
      "worldMeta": 4,
      "stackMeta": 0,
      "needsSupportBlock": false,
      "rotationMetaTransform": [
        4,
        8,
        4,
        8
      ]
    },
    {
      "x": 5,
      "y": 8,
      "z": 12,
      "fuzzy": false,
      "block": "minecraft:planks",
      "worldMeta": 0,
      "stackMeta": 0,
      "needsSupportBlock": false
    },
    {
      "x": 5,
      "y": 9,
      "z": 1,
      "fuzzy": false,
      "block": "minecraft:brick_block",
      "worldMeta": 0,
      "stackMeta": 0,
      "needsSupportBlock": false
    },
    {
      "x": 5,
      "y": 9,
      "z": 2,
      "fuzzy": false,
      "block": "minecraft:brick_block",
      "worldMeta": 0,
      "stackMeta": 0,
      "needsSupportBlock": false
    },
    {
      "x": 5,
      "y": 9,
      "z": 3,
      "fuzzy": false,
      "block": "minecraft:brick_block",
      "worldMeta": 0,
      "stackMeta": 0,
      "needsSupportBlock": false
    },
    {
      "x": 5,
      "y": 9,
      "z": 4,
      "fuzzy": false,
      "block": "minecraft:brick_block",
      "worldMeta": 0,
      "stackMeta": 0,
      "needsSupportBlock": false
    },
    {
      "x": 5,
      "y": 9,
      "z": 5,
      "fuzzy": false,
      "block": "minecraft:brick_block",
      "worldMeta": 0,
      "stackMeta": 0,
      "needsSupportBlock": false
    },
    {
      "x": 5,
      "y": 9,
      "z": 6,
      "fuzzy": false,
      "block": "minecraft:planks",
      "worldMeta": 0,
      "stackMeta": 0,
      "needsSupportBlock": false
    },
    {
      "x": 5,
      "y": 9,
      "z": 7,
      "fuzzy": false,
      "block": "minecraft:planks",
      "worldMeta": 0,
      "stackMeta": 0,
      "needsSupportBlock": false
    },
    {
      "x": 5,
      "y": 9,
      "z": 8,
      "fuzzy": false,
      "block": "minecraft:planks",
      "worldMeta": 0,
      "stackMeta": 0,
      "needsSupportBlock": false
    },
    {
      "x": 5,
      "y": 9,
      "z": 9,
      "fuzzy": false,
      "block": "minecraft:brick_block",
      "worldMeta": 0,
      "stackMeta": 0,
      "needsSupportBlock": false
    },
    {
      "x": 5,
      "y": 9,
      "z": 10,
      "fuzzy": false,
      "block": "minecraft:brick_block",
      "worldMeta": 0,
      "stackMeta": 0,
      "needsSupportBlock": false
    },
    {
      "x": 5,
      "y": 9,
      "z": 11,
      "fuzzy": false,
      "block": "minecraft:brick_block",
      "worldMeta": 0,
      "stackMeta": 0,
      "needsSupportBlock": false
    },
    {
      "x": 5,
      "y": 9,
      "z": 12,
      "fuzzy": false,
      "block": "minecraft:brick_block",
      "worldMeta": 0,
      "stackMeta": 0,
      "needsSupportBlock": false
    },
    {
      "x": 5,
      "y": 9,
      "z": 13,
      "fuzzy": false,
      "block": "minecraft:brick_block",
      "worldMeta": 0,
      "stackMeta": 0,
      "needsSupportBlock": false
    },
    {
      "x": 5,
      "y": 10,
      "z": 1,
      "fuzzy": false,
      "block": "minecraft:stone_slab",
      "worldMeta": 4,
      "stackMeta": 4,
      "needsSupportBlock": false
    },
    {
      "x": 5,
      "y": 10,
      "z": 2,
      "fuzzy": false,
      "block": "minecraft:stone_slab",
      "worldMeta": 4,
      "stackMeta": 4,
      "needsSupportBlock": false
    },
    {
      "x": 5,
      "y": 10,
      "z": 3,
      "fuzzy": false,
      "block": "minecraft:stone_slab",
      "worldMeta": 4,
      "stackMeta": 4,
      "needsSupportBlock": false
    },
    {
      "x": 5,
      "y": 10,
      "z": 4,
      "fuzzy": false,
      "block": "minecraft:stone_slab",
      "worldMeta": 4,
      "stackMeta": 4,
      "needsSupportBlock": false
    },
    {
      "x": 5,
      "y": 10,
      "z": 5,
      "fuzzy": false,
      "block": "minecraft:stone_slab",
      "worldMeta": 4,
      "stackMeta": 4,
      "needsSupportBlock": false
    },
    {
      "x": 5,
      "y": 10,
      "z": 6,
      "fuzzy": false,
      "block": "minecraft:brick_stairs",
      "worldMeta": 0,
      "stackMeta": 0,
      "needsSupportBlock": false,
      "rotationMetaTransform": [
        2,
        1,
        3,
        0
      ]
    },
    {
      "x": 5,
      "y": 10,
      "z": 7,
      "fuzzy": false,
      "block": "minecraft:brick_stairs",
      "worldMeta": 0,
      "stackMeta": 0,
      "needsSupportBlock": false,
      "rotationMetaTransform": [
        2,
        1,
        3,
        0
      ]
    },
    {
      "x": 5,
      "y": 10,
      "z": 8,
      "fuzzy": false,
      "block": "minecraft:brick_stairs",
      "worldMeta": 0,
      "stackMeta": 0,
      "needsSupportBlock": false,
      "rotationMetaTransform": [
        2,
        1,
        3,
        0
      ]
    },
    {
      "x": 5,
      "y": 10,
      "z": 9,
      "fuzzy": false,
      "block": "minecraft:stone_slab",
      "worldMeta": 4,
      "stackMeta": 4,
      "needsSupportBlock": false
    },
    {
      "x": 5,
      "y": 10,
      "z": 10,
      "fuzzy": false,
      "block": "minecraft:stone_slab",
      "worldMeta": 4,
      "stackMeta": 4,
      "needsSupportBlock": false
    },
    {
      "x": 5,
      "y": 10,
      "z": 11,
      "fuzzy": false,
      "block": "minecraft:stone_slab",
      "worldMeta": 4,
      "stackMeta": 4,
      "needsSupportBlock": false
    },
    {
      "x": 5,
      "y": 10,
      "z": 12,
      "fuzzy": false,
      "block": "minecraft:stone_slab",
      "worldMeta": 4,
      "stackMeta": 4,
      "needsSupportBlock": false
    },
    {
      "x": 5,
      "y": 10,
      "z": 13,
      "fuzzy": false,
      "block": "minecraft:stone_slab",
      "worldMeta": 4,
      "stackMeta": 4,
      "needsSupportBlock": false
    },
    {
      "x": 6,
      "y": 0,
      "z": 0,
      "fuzzy": false,
      "block": "minecraft:trapdoor",
      "worldMeta": 12,
      "stackMeta": 0,
      "needsSupportBlock": true,
      "rotationMetaTransform": [
        15,
        13,
        14,
        12
      ]
    },
    {
      "x": 6,
      "y": 0,
      "z": 1,
      "fuzzy": false,
      "block": "minecraft:grass",
      "worldMeta": 0,
      "stackMeta": 0,
      "needsSupportBlock": false
    },
    {
      "x": 6,
      "y": 0,
      "z": 2,
      "fuzzy": false,
      "block": "minecraft:cobblestone",
      "worldMeta": 0,
      "stackMeta": 0,
      "needsSupportBlock": false
    },
    {
      "x": 6,
      "y": 0,
      "z": 3,
      "fuzzy": false,
      "block": "minecraft:cobblestone",
      "worldMeta": 0,
      "stackMeta": 0,
      "needsSupportBlock": false
    },
    {
      "x": 6,
      "y": 0,
      "z": 4,
      "fuzzy": false,
      "block": "minecraft:cobblestone",
      "worldMeta": 0,
      "stackMeta": 0,
      "needsSupportBlock": false
    },
    {
      "x": 6,
      "y": 0,
      "z": 5,
      "fuzzy": false,
      "block": "minecraft:cobblestone",
      "worldMeta": 0,
      "stackMeta": 0,
      "needsSupportBlock": false
    },
    {
      "x": 6,
      "y": 0,
      "z": 6,
      "fuzzy": false,
      "block": "minecraft:cobblestone",
      "worldMeta": 0,
      "stackMeta": 0,
      "needsSupportBlock": false
    },
    {
      "x": 6,
      "y": 0,
      "z": 7,
      "fuzzy": false,
      "block": "minecraft:cobblestone",
      "worldMeta": 0,
      "stackMeta": 0,
      "needsSupportBlock": false
    },
    {
      "x": 6,
      "y": 0,
      "z": 8,
      "fuzzy": false,
      "block": "minecraft:cobblestone",
      "worldMeta": 0,
      "stackMeta": 0,
      "needsSupportBlock": false
    },
    {
      "x": 6,
      "y": 0,
      "z": 9,
      "fuzzy": false,
      "block": "minecraft:cobblestone",
      "worldMeta": 0,
      "stackMeta": 0,
      "needsSupportBlock": false
    },
    {
      "x": 6,
      "y": 0,
      "z": 10,
      "fuzzy": false,
      "block": "minecraft:cobblestone",
      "worldMeta": 0,
      "stackMeta": 0,
      "needsSupportBlock": false
    },
    {
      "x": 6,
      "y": 0,
      "z": 11,
      "fuzzy": false,
      "block": "minecraft:cobblestone",
      "worldMeta": 0,
      "stackMeta": 0,
      "needsSupportBlock": false
    },
    {
      "x": 6,
      "y": 0,
      "z": 12,
      "fuzzy": false,
      "block": "minecraft:cobblestone",
      "worldMeta": 0,
      "stackMeta": 0,
      "needsSupportBlock": false
    },
    {
      "x": 6,
      "y": 0,
      "z": 13,
      "fuzzy": false,
      "block": "minecraft:grass",
      "worldMeta": 0,
      "stackMeta": 0,
      "needsSupportBlock": false
    },
    {
      "x": 6,
      "y": 0,
      "z": 14,
      "fuzzy": false,
      "block": "minecraft:trapdoor",
      "worldMeta": 13,
      "stackMeta": 0,
      "needsSupportBlock": true,
      "rotationMetaTransform": [
        15,
        13,
        14,
        12
      ]
    },
    {
      "x": 6,
      "y": 1,
      "z": 2,
      "fuzzy": false,
      "block": "minecraft:oak_stairs",
      "worldMeta": 2,
      "stackMeta": 0,
      "needsSupportBlock": false,
      "rotationMetaTransform": [
        2,
        1,
        3,
        0
      ]
    },
    {
      "x": 6,
      "y": 1,
      "z": 3,
      "fuzzy": false,
      "block": "minecraft:chest",
      "worldMeta": 3,
      "stackMeta": 0,
      "needsSupportBlock": false,
      "rotationMetaTransform": [
        5,
        3,
        4,
        2
      ],
      "nbtString": "{x:-1664,y:5,z:-31,Items:[],id:\"Chest\",Lock:\"\"}"
    },
    {
      "x": 6,
      "y": 1,
      "z": 4,
      "fuzzy": false,
      "block": "minecraft:carpet",
      "worldMeta": 14,
      "stackMeta": 14,
      "needsSupportBlock": false
    },
    {
      "x": 6,
      "y": 1,
      "z": 5,
      "fuzzy": false,
      "block": "minecraft:carpet",
      "worldMeta": 14,
      "stackMeta": 14,
      "needsSupportBlock": false
    },
    {
      "x": 6,
      "y": 1,
      "z": 6,
      "fuzzy": false,
      "block": "minecraft:carpet",
      "worldMeta": 14,
      "stackMeta": 14,
      "needsSupportBlock": false
    },
    {
      "x": 6,
      "y": 1,
      "z": 7,
      "fuzzy": false,
      "block": "minecraft:carpet",
      "worldMeta": 14,
      "stackMeta": 14,
      "needsSupportBlock": false
    },
    {
      "x": 6,
      "y": 1,
      "z": 8,
      "fuzzy": false,
      "block": "minecraft:carpet",
      "worldMeta": 14,
      "stackMeta": 14,
      "needsSupportBlock": false
    },
    {
      "x": 6,
      "y": 1,
      "z": 9,
      "fuzzy": false,
      "block": "minecraft:carpet",
      "worldMeta": 14,
      "stackMeta": 14,
      "needsSupportBlock": false
    },
    {
      "x": 6,
      "y": 1,
      "z": 10,
      "fuzzy": false,
      "block": "minecraft:carpet",
      "worldMeta": 14,
      "stackMeta": 14,
      "needsSupportBlock": false
    },
    {
      "x": 6,
      "y": 1,
      "z": 11,
      "fuzzy": false,
      "block": "minecraft:stone_stairs",
      "worldMeta": 4,
      "stackMeta": 0,
      "needsSupportBlock": false,
      "rotationMetaTransform": [
        6,
        5,
        7,
        4
      ]
    },
    {
      "x": 6,
      "y": 1,
      "z": 12,
      "fuzzy": false,
      "block": "minecraft:oak_stairs",
      "worldMeta": 3,
      "stackMeta": 0,
      "needsSupportBlock": false,
      "rotationMetaTransform": [
        2,
        1,
        3,
        0
      ]
    },
    {
      "x": 6,
      "y": 2,
      "z": 2,
      "fuzzy": false,
      "block": "minecraft:glass_pane",
      "worldMeta": 0,
      "stackMeta": 0,
      "needsSupportBlock": false
    },
    {
      "x": 6,
      "y": 2,
      "z": 12,
      "fuzzy": false,
      "block": "minecraft:glass_pane",
      "worldMeta": 0,
      "stackMeta": 0,
      "needsSupportBlock": false
    },
    {
      "x": 6,
      "y": 3,
      "z": 2,
      "fuzzy": false,
      "block": "minecraft:oak_stairs",
      "worldMeta": 6,
      "stackMeta": 0,
      "needsSupportBlock": false,
      "rotationMetaTransform": [
        6,
        5,
        7,
        4
      ]
    },
    {
      "x": 6,
      "y": 3,
      "z": 12,
      "fuzzy": false,
      "block": "minecraft:oak_stairs",
      "worldMeta": 7,
      "stackMeta": 0,
      "needsSupportBlock": false,
      "rotationMetaTransform": [
        6,
        5,
        7,
        4
      ]
    },
    {
      "x": 6,
      "y": 4,
      "z": 2,
      "fuzzy": false,
      "block": "minecraft:log",
      "worldMeta": 4,
      "stackMeta": 0,
      "needsSupportBlock": false,
      "rotationMetaTransform": [
        4,
        8,
        4,
        8
      ]
    },
    {
      "x": 6,
      "y": 4,
      "z": 3,
      "fuzzy": false,
      "block": "minecraft:wooden_slab",
      "worldMeta": 8,
      "stackMeta": 0,
      "needsSupportBlock": false
    },
    {
      "x": 6,
      "y": 4,
      "z": 4,
      "fuzzy": false,
      "block": "minecraft:wooden_slab",
      "worldMeta": 8,
      "stackMeta": 0,
      "needsSupportBlock": false
    },
    {
      "x": 6,
      "y": 4,
      "z": 5,
      "fuzzy": false,
      "block": "minecraft:wooden_slab",
      "worldMeta": 8,
      "stackMeta": 0,
      "needsSupportBlock": false
    },
    {
      "x": 6,
      "y": 4,
      "z": 6,
      "fuzzy": false,
      "block": "minecraft:wooden_slab",
      "worldMeta": 8,
      "stackMeta": 0,
      "needsSupportBlock": false
    },
    {
      "x": 6,
      "y": 4,
      "z": 7,
      "fuzzy": false,
      "block": "minecraft:wooden_slab",
      "worldMeta": 8,
      "stackMeta": 0,
      "needsSupportBlock": false
    },
    {
      "x": 6,
      "y": 4,
      "z": 8,
      "fuzzy": false,
      "block": "minecraft:wooden_slab",
      "worldMeta": 8,
      "stackMeta": 0,
      "needsSupportBlock": false
    },
    {
      "x": 6,
      "y": 4,
      "z": 9,
      "fuzzy": false,
      "block": "minecraft:wooden_slab",
      "worldMeta": 8,
      "stackMeta": 0,
      "needsSupportBlock": false
    },
    {
      "x": 6,
      "y": 4,
      "z": 10,
      "fuzzy": false,
      "block": "minecraft:wooden_slab",
      "worldMeta": 8,
      "stackMeta": 0,
      "needsSupportBlock": false
    },
    {
      "x": 6,
      "y": 4,
      "z": 11,
      "fuzzy": false,
      "block": "minecraft:wooden_slab",
      "worldMeta": 8,
      "stackMeta": 0,
      "needsSupportBlock": false
    },
    {
      "x": 6,
      "y": 4,
      "z": 12,
      "fuzzy": false,
      "block": "minecraft:log",
      "worldMeta": 4,
      "stackMeta": 0,
      "needsSupportBlock": false,
      "rotationMetaTransform": [
        4,
        8,
        4,
        8
      ]
    },
    {
      "x": 6,
      "y": 5,
      "z": 2,
      "fuzzy": false,
      "block": "minecraft:oak_stairs",
      "worldMeta": 2,
      "stackMeta": 0,
      "needsSupportBlock": false,
      "rotationMetaTransform": [
        2,
        1,
        3,
        0
      ]
    },
    {
      "x": 6,
      "y": 5,
      "z": 3,
      "fuzzy": false,
      "block": "minecraft:carpet",
      "worldMeta": 14,
      "stackMeta": 14,
      "needsSupportBlock": false
    },
    {
      "x": 6,
      "y": 5,
      "z": 4,
      "fuzzy": false,
      "block": "minecraft:carpet",
      "worldMeta": 14,
      "stackMeta": 14,
      "needsSupportBlock": false
    },
    {
      "x": 6,
      "y": 5,
      "z": 5,
      "fuzzy": false,
      "block": "minecraft:carpet",
      "worldMeta": 14,
      "stackMeta": 14,
      "needsSupportBlock": false
    },
    {
      "x": 6,
      "y": 5,
      "z": 6,
      "fuzzy": false,
      "block": "minecraft:carpet",
      "worldMeta": 14,
      "stackMeta": 14,
      "needsSupportBlock": false
    },
    {
      "x": 6,
      "y": 5,
      "z": 7,
      "fuzzy": false,
      "block": "minecraft:carpet",
      "worldMeta": 14,
      "stackMeta": 14,
      "needsSupportBlock": false
    },
    {
      "x": 6,
      "y": 5,
      "z": 8,
      "fuzzy": false,
      "block": "minecraft:carpet",
      "worldMeta": 14,
      "stackMeta": 14,
      "needsSupportBlock": false
    },
    {
      "x": 6,
      "y": 5,
      "z": 9,
      "fuzzy": false,
      "block": "minecraft:carpet",
      "worldMeta": 14,
      "stackMeta": 14,
      "needsSupportBlock": false
    },
    {
      "x": 6,
      "y": 5,
      "z": 10,
      "fuzzy": false,
      "block": "minecraft:carpet",
      "worldMeta": 14,
      "stackMeta": 14,
      "needsSupportBlock": false
    },
    {
      "x": 6,
      "y": 5,
      "z": 11,
      "fuzzy": false,
      "block": "minecraft:carpet",
      "worldMeta": 14,
      "stackMeta": 14,
      "needsSupportBlock": false
    },
    {
      "x": 6,
      "y": 5,
      "z": 12,
      "fuzzy": false,
      "block": "minecraft:oak_stairs",
      "worldMeta": 3,
      "stackMeta": 0,
      "needsSupportBlock": false,
      "rotationMetaTransform": [
        2,
        1,
        3,
        0
      ]
    },
    {
      "x": 6,
      "y": 6,
      "z": 2,
      "fuzzy": false,
      "block": "minecraft:glass_pane",
      "worldMeta": 0,
      "stackMeta": 0,
      "needsSupportBlock": false
    },
    {
      "x": 6,
      "y": 6,
      "z": 12,
      "fuzzy": false,
      "block": "minecraft:glass_pane",
      "worldMeta": 0,
      "stackMeta": 0,
      "needsSupportBlock": false
    },
    {
      "x": 6,
      "y": 7,
      "z": 2,
      "fuzzy": false,
      "block": "minecraft:oak_stairs",
      "worldMeta": 6,
      "stackMeta": 0,
      "needsSupportBlock": false,
      "rotationMetaTransform": [
        6,
        5,
        7,
        4
      ]
    },
    {
      "x": 6,
      "y": 7,
      "z": 12,
      "fuzzy": false,
      "block": "minecraft:oak_stairs",
      "worldMeta": 7,
      "stackMeta": 0,
      "needsSupportBlock": false,
      "rotationMetaTransform": [
        6,
        5,
        7,
        4
      ]
    },
    {
      "x": 6,
      "y": 8,
      "z": 1,
      "fuzzy": false,
      "block": "minecraft:brick_stairs",
      "worldMeta": 4,
      "stackMeta": 0,
      "needsSupportBlock": false,
      "rotationMetaTransform": [
        6,
        5,
        7,
        4
      ]
    },
    {
      "x": 6,
      "y": 8,
      "z": 2,
      "fuzzy": false,
      "block": "minecraft:planks",
      "worldMeta": 0,
      "stackMeta": 0,
      "needsSupportBlock": false
    },
    {
      "x": 6,
      "y": 8,
      "z": 3,
      "fuzzy": false,
      "block": "minecraft:brick_stairs",
      "worldMeta": 4,
      "stackMeta": 0,
      "needsSupportBlock": false,
      "rotationMetaTransform": [
        6,
        5,
        7,
        4
      ]
    },
    {
      "x": 6,
      "y": 8,
      "z": 4,
      "fuzzy": false,
      "block": "minecraft:brick_stairs",
      "worldMeta": 4,
      "stackMeta": 0,
      "needsSupportBlock": false,
      "rotationMetaTransform": [
        6,
        5,
        7,
        4
      ]
    },
    {
      "x": 6,
      "y": 8,
      "z": 5,
      "fuzzy": false,
      "block": "minecraft:log",
      "worldMeta": 4,
      "stackMeta": 0,
      "needsSupportBlock": false,
      "rotationMetaTransform": [
        4,
        8,
        4,
        8
      ]
    },
    {
      "x": 6,
      "y": 8,
      "z": 6,
      "fuzzy": false,
      "block": "minecraft:wooden_slab",
      "worldMeta": 8,
      "stackMeta": 0,
      "needsSupportBlock": false
    },
    {
      "x": 6,
      "y": 8,
      "z": 7,
      "fuzzy": false,
      "block": "minecraft:wooden_slab",
      "worldMeta": 8,
      "stackMeta": 0,
      "needsSupportBlock": false
    },
    {
      "x": 6,
      "y": 8,
      "z": 8,
      "fuzzy": false,
      "block": "minecraft:wooden_slab",
      "worldMeta": 8,
      "stackMeta": 0,
      "needsSupportBlock": false
    },
    {
      "x": 6,
      "y": 8,
      "z": 9,
      "fuzzy": false,
      "block": "minecraft:log",
      "worldMeta": 4,
      "stackMeta": 0,
      "needsSupportBlock": false,
      "rotationMetaTransform": [
        4,
        8,
        4,
        8
      ]
    },
    {
      "x": 6,
      "y": 8,
      "z": 10,
      "fuzzy": false,
      "block": "minecraft:brick_stairs",
      "worldMeta": 4,
      "stackMeta": 0,
      "needsSupportBlock": false,
      "rotationMetaTransform": [
        6,
        5,
        7,
        4
      ]
    },
    {
      "x": 6,
      "y": 8,
      "z": 11,
      "fuzzy": false,
      "block": "minecraft:brick_stairs",
      "worldMeta": 4,
      "stackMeta": 0,
