{
  "groundLevel": 0,
  "home": [
    13,
    0,
    7
  ],
  "blocks": [
    {
      "x": 0,
      "y": 2,
      "z": 1,
      "fuzzy": false,
      "block": "minecraft:trapdoor",
      "worldMeta": 14,
      "stackMeta": 0,
      "needsSupportBlock": true,
      "rotationMetaTransform": [
        15,
        13,
        14,
        12
      ]
    },
    {
      "x": 0,
      "y": 2,
      "z": 9,
      "fuzzy": false,
      "block": "minecraft:trapdoor",
      "worldMeta": 14,
      "stackMeta": 0,
      "needsSupportBlock": true,
      "rotationMetaTransform": [
        15,
        13,
        14,
        12
      ]
    },
    {
      "x": 0,
      "y": 2,
      "z": 17,
      "fuzzy": false,
      "block": "minecraft:trapdoor",
      "worldMeta": 14,
      "stackMeta": 0,
      "needsSupportBlock": true,
      "rotationMetaTransform": [
        15,
        13,
        14,
        12
      ]
    },
    {
      "x": 1,
      "y": 0,
      "z": 1,
      "fuzzy": false,
      "block": "minecraft:log",
      "worldMeta": 0,
      "stackMeta": 0,
      "needsSupportBlock": false
    },
    {
      "x": 1,
      "y": 0,
      "z": 2,
      "fuzzy": false,
      "block": "minecraft:cobblestone",
      "worldMeta": 0,
      "stackMeta": 0,
      "needsSupportBlock": false
    },
    {
      "x": 1,
      "y": 0,
      "z": 3,
      "fuzzy": false,
      "block": "minecraft:cobblestone",
      "worldMeta": 0,
      "stackMeta": 0,
      "needsSupportBlock": false
    },
    {
      "x": 1,
      "y": 0,
      "z": 4,
      "fuzzy": false,
      "block": "minecraft:cobblestone",
      "worldMeta": 0,
      "stackMeta": 0,
      "needsSupportBlock": false
    },
    {
      "x": 1,
      "y": 0,
      "z": 5,
      "fuzzy": false,
      "block": "minecraft:cobblestone",
      "worldMeta": 0,
      "stackMeta": 0,
      "needsSupportBlock": false
    },
    {
      "x": 1,
      "y": 0,
      "z": 6,
      "fuzzy": false,
      "block": "minecraft:cobblestone",
      "worldMeta": 0,
      "stackMeta": 0,
      "needsSupportBlock": false
    },
    {
      "x": 1,
      "y": 0,
      "z": 7,
      "fuzzy": false,
      "block": "minecraft:cobblestone",
      "worldMeta": 0,
      "stackMeta": 0,
      "needsSupportBlock": false
    },
    {
      "x": 1,
      "y": 0,
      "z": 8,
      "fuzzy": false,
      "block": "minecraft:cobblestone",
      "worldMeta": 0,
      "stackMeta": 0,
      "needsSupportBlock": false
    },
    {
      "x": 1,
      "y": 0,
      "z": 9,
      "fuzzy": false,
      "block": "minecraft:log",
      "worldMeta": 0,
      "stackMeta": 0,
      "needsSupportBlock": false
    },
    {
      "x": 1,
      "y": 0,
      "z": 10,
      "fuzzy": false,
      "block": "minecraft:cobblestone",
      "worldMeta": 0,
      "stackMeta": 0,
      "needsSupportBlock": false
    },
    {
      "x": 1,
      "y": 0,
      "z": 11,
      "fuzzy": false,
      "block": "minecraft:cobblestone",
      "worldMeta": 0,
      "stackMeta": 0,
      "needsSupportBlock": false
    },
    {
      "x": 1,
      "y": 0,
      "z": 12,
      "fuzzy": false,
      "block": "minecraft:cobblestone",
      "worldMeta": 0,
      "stackMeta": 0,
      "needsSupportBlock": false
    },
    {
      "x": 1,
      "y": 0,
      "z": 13,
      "fuzzy": false,
      "block": "minecraft:cobblestone",
      "worldMeta": 0,
      "stackMeta": 0,
      "needsSupportBlock": false
    },
    {
      "x": 1,
      "y": 0,
      "z": 14,
      "fuzzy": false,
      "block": "minecraft:cobblestone",
      "worldMeta": 0,
      "stackMeta": 0,
      "needsSupportBlock": false
    },
    {
      "x": 1,
      "y": 0,
      "z": 15,
      "fuzzy": false,
      "block": "minecraft:cobblestone",
      "worldMeta": 0,
      "stackMeta": 0,
      "needsSupportBlock": false
    },
    {
      "x": 1,
      "y": 0,
      "z": 16,
      "fuzzy": false,
      "block": "minecraft:cobblestone",
      "worldMeta": 0,
      "stackMeta": 0,
      "needsSupportBlock": false
    },
    {
      "x": 1,
      "y": 0,
      "z": 17,
      "fuzzy": false,
      "block": "minecraft:log",
      "worldMeta": 0,
      "stackMeta": 0,
      "needsSupportBlock": false
    },
    {
      "x": 1,
      "y": 0,
      "z": 18,
      "fuzzy": false,
      "block": "minecraft:cobblestone",
      "worldMeta": 0,
      "stackMeta": 0,
      "needsSupportBlock": false
    },
    {
      "x": 1,
      "y": 0,
      "z": 19,
      "fuzzy": false,
      "block": "minecraft:cobblestone",
      "worldMeta": 0,
      "stackMeta": 0,
      "needsSupportBlock": false
    },
    {
      "x": 1,
      "y": 0,
      "z": 20,
      "fuzzy": false,
      "block": "minecraft:cobblestone",
      "worldMeta": 0,
      "stackMeta": 0,
      "needsSupportBlock": false
    },
    {
      "x": 1,
      "y": 0,
      "z": 21,
      "fuzzy": false,
      "block": "minecraft:cobblestone",
      "worldMeta": 0,
      "stackMeta": 0,
      "needsSupportBlock": false
    },
    {
      "x": 1,
      "y": 0,
      "z": 22,
      "fuzzy": false,
      "block": "minecraft:cobblestone",
      "worldMeta": 0,
      "stackMeta": 0,
      "needsSupportBlock": false
    },
    {
      "x": 1,
      "y": 0,
      "z": 23,
      "fuzzy": false,
      "block": "minecraft:cobblestone",
      "worldMeta": 0,
      "stackMeta": 0,
      "needsSupportBlock": false
    },
    {
      "x": 1,
      "y": 0,
      "z": 24,
      "fuzzy": false,
      "block": "minecraft:cobblestone",
      "worldMeta": 0,
      "stackMeta": 0,
      "needsSupportBlock": false
    },
    {
      "x": 1,
      "y": 0,
      "z": 25,
      "fuzzy": false,
      "block": "minecraft:log",
      "worldMeta": 0,
      "stackMeta": 0,
      "needsSupportBlock": false
    },
    {
      "x": 1,
      "y": 1,
      "z": 1,
      "fuzzy": false,
      "block": "minecraft:log",
      "worldMeta": 0,
      "stackMeta": 0,
      "needsSupportBlock": false
    },
    {
      "x": 1,
      "y": 1,
      "z": 3,
      "fuzzy": false,
      "block": "minecraft:stone_stairs",
      "worldMeta": 0,
      "stackMeta": 0,
      "needsSupportBlock": false,
      "rotationMetaTransform": [
        2,
        1,
        3,
        0
      ]
    },
    {
      "x": 1,
      "y": 1,
      "z": 5,
      "fuzzy": false,
      "block": "minecraft:stone_stairs",
      "worldMeta": 0,
      "stackMeta": 0,
      "needsSupportBlock": false,
      "rotationMetaTransform": [
        2,
        1,
        3,
        0
      ]
    },
    {
      "x": 1,
      "y": 1,
      "z": 7,
      "fuzzy": false,
      "block": "minecraft:stone_stairs",
      "worldMeta": 0,
      "stackMeta": 0,
      "needsSupportBlock": false,
      "rotationMetaTransform": [
        2,
        1,
        3,
        0
      ]
    },
    {
      "x": 1,
      "y": 1,
      "z": 9,
      "fuzzy": false,
      "block": "minecraft:log",
      "worldMeta": 0,
      "stackMeta": 0,
      "needsSupportBlock": false
    },
    {
      "x": 1,
      "y": 1,
      "z": 11,
      "fuzzy": false,
      "block": "minecraft:stone_stairs",
      "worldMeta": 0,
      "stackMeta": 0,
      "needsSupportBlock": false,
      "rotationMetaTransform": [
        2,
        1,
        3,
        0
      ]
    },
    {
      "x": 1,
      "y": 1,
      "z": 13,
      "fuzzy": false,
      "block": "minecraft:stone_stairs",
      "worldMeta": 0,
      "stackMeta": 0,
      "needsSupportBlock": false,
      "rotationMetaTransform": [
        2,
        1,
        3,
        0
      ]
    },
    {
      "x": 1,
      "y": 1,
      "z": 15,
      "fuzzy": false,
      "block": "minecraft:stone_stairs",
      "worldMeta": 0,
      "stackMeta": 0,
      "needsSupportBlock": false,
      "rotationMetaTransform": [
        2,
        1,
        3,
        0
      ]
    },
    {
      "x": 1,
      "y": 1,
      "z": 17,
      "fuzzy": false,
      "block": "minecraft:log",
      "worldMeta": 0,
      "stackMeta": 0,
      "needsSupportBlock": false
    },
    {
      "x": 1,
      "y": 1,
      "z": 19,
      "fuzzy": false,
      "block": "minecraft:stone_stairs",
      "worldMeta": 0,
      "stackMeta": 0,
      "needsSupportBlock": false,
      "rotationMetaTransform": [
        2,
        1,
        3,
        0
      ]
    },
    {
      "x": 1,
      "y": 1,
      "z": 21,
      "fuzzy": false,
      "block": "minecraft:stone_stairs",
      "worldMeta": 0,
      "stackMeta": 0,
      "needsSupportBlock": false,
      "rotationMetaTransform": [
        2,
        1,
        3,
        0
      ]
    },
    {
      "x": 1,
      "y": 1,
      "z": 23,
      "fuzzy": false,
      "block": "minecraft:stone_stairs",
      "worldMeta": 0,
      "stackMeta": 0,
      "needsSupportBlock": false,
      "rotationMetaTransform": [
        2,
        1,
        3,
        0
      ]
    },
    {
      "x": 1,
      "y": 1,
      "z": 25,
      "fuzzy": false,
      "block": "minecraft:log",
      "worldMeta": 0,
      "stackMeta": 0,
      "needsSupportBlock": false
    },
    {
      "x": 1,
      "y": 2,
      "z": 0,
      "fuzzy": false,
      "block": "minecraft:trapdoor",
      "worldMeta": 12,
      "stackMeta": 0,
      "needsSupportBlock": true,
      "rotationMetaTransform": [
        15,
        13,
        14,
        12
      ]
    },
    {
      "x": 1,
      "y": 2,
      "z": 1,
      "fuzzy": false,
      "block": "minecraft:log",
      "worldMeta": 0,
      "stackMeta": 0,
      "needsSupportBlock": false
    },
    {
      "x": 1,
      "y": 2,
      "z": 2,
      "fuzzy": false,
      "block": "minecraft:iron_bars",
      "worldMeta": 0,
      "stackMeta": 0,
      "needsSupportBlock": false
    },
    {
      "x": 1,
      "y": 2,
      "z": 3,
      "fuzzy": false,
      "block": "minecraft:iron_bars",
      "worldMeta": 0,
      "stackMeta": 0,
      "needsSupportBlock": false
    },
    {
      "x": 1,
      "y": 2,
      "z": 4,
      "fuzzy": false,
      "block": "minecraft:iron_bars",
      "worldMeta": 0,
      "stackMeta": 0,
      "needsSupportBlock": false
    },
    {
      "x": 1,
      "y": 2,
      "z": 5,
      "fuzzy": false,
      "block": "minecraft:iron_bars",
      "worldMeta": 0,
      "stackMeta": 0,
      "needsSupportBlock": false
    },
    {
      "x": 1,
      "y": 2,
      "z": 6,
      "fuzzy": false,
      "block": "minecraft:iron_bars",
      "worldMeta": 0,
      "stackMeta": 0,
      "needsSupportBlock": false
    },
    {
      "x": 1,
      "y": 2,
      "z": 7,
      "fuzzy": false,
      "block": "minecraft:iron_bars",
      "worldMeta": 0,
      "stackMeta": 0,
      "needsSupportBlock": false
    },
    {
      "x": 1,
      "y": 2,
      "z": 8,
      "fuzzy": false,
      "block": "minecraft:iron_bars",
      "worldMeta": 0,
      "stackMeta": 0,
      "needsSupportBlock": false
    },
    {
      "x": 1,
      "y": 2,
      "z": 9,
      "fuzzy": false,
      "block": "minecraft:log",
      "worldMeta": 0,
      "stackMeta": 0,
      "needsSupportBlock": false
    },
    {
      "x": 1,
      "y": 2,
      "z": 10,
      "fuzzy": false,
      "block": "minecraft:iron_bars",
      "worldMeta": 0,
      "stackMeta": 0,
      "needsSupportBlock": false
    },
    {
      "x": 1,
      "y": 2,
      "z": 11,
      "fuzzy": false,
      "block": "minecraft:iron_bars",
      "worldMeta": 0,
      "stackMeta": 0,
      "needsSupportBlock": false
    },
    {
      "x": 1,
      "y": 2,
      "z": 12,
      "fuzzy": false,
      "block": "minecraft:iron_bars",
      "worldMeta": 0,
      "stackMeta": 0,
      "needsSupportBlock": false
    },
    {
      "x": 1,
      "y": 2,
      "z": 13,
      "fuzzy": false,
      "block": "minecraft:iron_bars",
      "worldMeta": 0,
      "stackMeta": 0,
      "needsSupportBlock": false
    },
    {
      "x": 1,
      "y": 2,
      "z": 14,
      "fuzzy": false,
      "block": "minecraft:iron_bars",
      "worldMeta": 0,
      "stackMeta": 0,
      "needsSupportBlock": false
    },
    {
      "x": 1,
      "y": 2,
      "z": 15,
      "fuzzy": false,
      "block": "minecraft:iron_bars",
      "worldMeta": 0,
      "stackMeta": 0,
      "needsSupportBlock": false
    },
    {
      "x": 1,
      "y": 2,
      "z": 16,
      "fuzzy": false,
      "block": "minecraft:iron_bars",
      "worldMeta": 0,
      "stackMeta": 0,
      "needsSupportBlock": false
    },
    {
      "x": 1,
      "y": 2,
      "z": 17,
      "fuzzy": false,
      "block": "minecraft:log",
      "worldMeta": 0,
      "stackMeta": 0,
      "needsSupportBlock": false
    },
    {
      "x": 1,
      "y": 2,
      "z": 18,
      "fuzzy": false,
      "block": "minecraft:iron_bars",
      "worldMeta": 0,
      "stackMeta": 0,
      "needsSupportBlock": false
    },
    {
      "x": 1,
      "y": 2,
      "z": 19,
      "fuzzy": false,
      "block": "minecraft:iron_bars",
      "worldMeta": 0,
      "stackMeta": 0,
      "needsSupportBlock": false
    },
    {
      "x": 1,
      "y": 2,
      "z": 20,
      "fuzzy": false,
      "block": "minecraft:iron_bars",
      "worldMeta": 0,
      "stackMeta": 0,
      "needsSupportBlock": false
    },
    {
      "x": 1,
      "y": 2,
      "z": 21,
      "fuzzy": false,
      "block": "minecraft:iron_bars",
      "worldMeta": 0,
      "stackMeta": 0,
      "needsSupportBlock": false
    },
    {
      "x": 1,
      "y": 2,
      "z": 22,
      "fuzzy": false,
      "block": "minecraft:iron_bars",
      "worldMeta": 0,
      "stackMeta": 0,
      "needsSupportBlock": false
    },
    {
      "x": 1,
      "y": 2,
      "z": 23,
      "fuzzy": false,
      "block": "minecraft:iron_bars",
      "worldMeta": 0,
      "stackMeta": 0,
      "needsSupportBlock": false
    },
    {
      "x": 1,
      "y": 2,
      "z": 24,
      "fuzzy": false,
      "block": "minecraft:iron_bars",
      "worldMeta": 0,
      "stackMeta": 0,
      "needsSupportBlock": false
    },
    {
      "x": 1,
      "y": 2,
      "z": 25,
      "fuzzy": false,
      "block": "minecraft:log",
      "worldMeta": 0,
      "stackMeta": 0,
      "needsSupportBlock": false
    },
    {
      "x": 1,
      "y": 2,
      "z": 26,
      "fuzzy": false,
      "block": "minecraft:trapdoor",
      "worldMeta": 13,
      "stackMeta": 0,
      "needsSupportBlock": true,
      "rotationMetaTransform": [
        15,
        13,
        14,
        12
      ]
    },
    {
      "x": 1,
      "y": 3,
      "z": 1,
      "fuzzy": false,
      "block": "minecraft:torch",
      "worldMeta": 5,
      "stackMeta": 0,
      "needsSupportBlock": true
    },
    {
      "x": 1,
      "y": 3,
      "z": 9,
      "fuzzy": false,
      "block": "minecraft:torch",
      "worldMeta": 5,
      "stackMeta": 0,
      "needsSupportBlock": true
    },
    {
      "x": 1,
      "y": 3,
      "z": 17,
      "fuzzy": false,
      "block": "minecraft:torch",
      "worldMeta": 5,
      "stackMeta": 0,
      "needsSupportBlock": true
    },
    {
      "x": 1,
      "y": 3,
      "z": 25,
      "fuzzy": false,
      "block": "minecraft:torch",
      "worldMeta": 5,
      "stackMeta": 0,
      "needsSupportBlock": true
    },
    {
      "x": 2,
      "y": 0,
      "z": 1,
      "fuzzy": false,
      "block": "minecraft:cobblestone",
      "worldMeta": 0,
      "stackMeta": 0,
      "needsSupportBlock": false
    },
    {
      "x": 2,
      "y": 0,
      "z": 25,
      "fuzzy": false,
      "block": "minecraft:cobblestone",
      "worldMeta": 0,
      "stackMeta": 0,
      "needsSupportBlock": false
    },
    {
      "x": 2,
      "y": 2,
      "z": 1,
      "fuzzy": false,
      "block": "minecraft:iron_bars",
      "worldMeta": 0,
      "stackMeta": 0,
      "needsSupportBlock": false
    },
    {
      "x": 2,
      "y": 2,
      "z": 15,
      "fuzzy": false,
      "block": "minecraft:torch",
      "worldMeta": 2,
      "stackMeta": 0,
      "needsSupportBlock": true,
      "rotationMetaTransform": [
        3,
        2,
        4,
        1
      ]
    },
    {
      "x": 2,
      "y": 2,
      "z": 23,
      "fuzzy": false,
      "block": "minecraft:torch",
      "worldMeta": 2,
      "stackMeta": 0,
      "needsSupportBlock": true,
      "rotationMetaTransform": [
        3,
        2,
        4,
        1
      ]
    },
    {
      "x": 2,
      "y": 2,
      "z": 25,
      "fuzzy": false,
      "block": "minecraft:iron_bars",
      "worldMeta": 0,
      "stackMeta": 0,
      "needsSupportBlock": false
    },
    {
      "x": 2,
      "y": 3,
      "z": 3,
      "fuzzy": false,
      "block": "minecraft:torch",
      "worldMeta": 2,
      "stackMeta": 0,
      "needsSupportBlock": true,
      "rotationMetaTransform": [
        3,
        2,
        4,
        1
      ]
    },
    {
      "x": 2,
      "y": 3,
      "z": 9,
      "fuzzy": false,
      "block": "minecraft:torch",
      "worldMeta": 2,
      "stackMeta": 0,
      "needsSupportBlock": true,
      "rotationMetaTransform": [
        3,
        2,
        4,
        1
      ]
    },
    {
      "x": 2,
      "y": 3,
      "z": 15,
      "fuzzy": false,
      "block": "minecraft:stone_slab",
      "worldMeta": 12,
      "stackMeta": 4,
      "needsSupportBlock": false
    },
    {
      "x": 2,
      "y": 3,
      "z": 16,
      "fuzzy": false,
      "block": "minecraft:stone_slab",
      "worldMeta": 12,
      "stackMeta": 4,
      "needsSupportBlock": false
    },
    {
      "x": 2,
      "y": 3,
      "z": 17,
      "fuzzy": false,
      "block": "minecraft:stone_slab",
      "worldMeta": 12,
      "stackMeta": 4,
      "needsSupportBlock": false
    },
    {
      "x": 2,
      "y": 3,
      "z": 18,
      "fuzzy": false,
      "block": "minecraft:stone_slab",
      "worldMeta": 12,
      "stackMeta": 4,
      "needsSupportBlock": false
    },
    {
      "x": 2,
      "y": 3,
      "z": 19,
      "fuzzy": false,
      "block": "minecraft:stone_slab",
      "worldMeta": 12,
      "stackMeta": 4,
      "needsSupportBlock": false
    },
    {
      "x": 2,
      "y": 3,
      "z": 20,
      "fuzzy": false,
      "block": "minecraft:stone_slab",
      "worldMeta": 12,
      "stackMeta": 4,
      "needsSupportBlock": false
    },
    {
      "x": 2,
      "y": 3,
      "z": 21,
      "fuzzy": false,
      "block": "minecraft:stone_slab",
      "worldMeta": 12,
      "stackMeta": 4,
      "needsSupportBlock": false
    },
    {
      "x": 2,
      "y": 3,
      "z": 22,
      "fuzzy": false,
      "block": "minecraft:stone_slab",
      "worldMeta": 12,
      "stackMeta": 4,
      "needsSupportBlock": false
    },
    {
      "x": 2,
      "y": 3,
      "z": 23,
      "fuzzy": false,
      "block": "minecraft:stone_slab",
      "worldMeta": 12,
      "stackMeta": 4,
      "needsSupportBlock": false
    },
    {
      "x": 3,
      "y": 0,
      "z": 1,
      "fuzzy": false,
      "block": "minecraft:cobblestone",
      "worldMeta": 0,
      "stackMeta": 0,
      "needsSupportBlock": false
    },
    {
      "x": 3,
      "y": 0,
      "z": 3,
      "fuzzy": false,
      "block": "minecraft:log",
      "worldMeta": 0,
      "stackMeta": 0,
      "needsSupportBlock": false
    },
    {
      "x": 3,
      "y": 0,
      "z": 4,
      "fuzzy": false,
      "block": "minecraft:cobblestone",
      "worldMeta": 0,
      "stackMeta": 0,
      "needsSupportBlock": false
    },
    {
      "x": 3,
      "y": 0,
      "z": 5,
      "fuzzy": false,
      "block": "minecraft:cobblestone",
      "worldMeta": 0,
      "stackMeta": 0,
      "needsSupportBlock": false
    },
    {
      "x": 3,
      "y": 0,
      "z": 6,
      "fuzzy": false,
      "block": "minecraft:cobblestone",
      "worldMeta": 0,
      "stackMeta": 0,
      "needsSupportBlock": false
    },
    {
      "x": 3,
      "y": 0,
      "z": 7,
      "fuzzy": false,
      "block": "minecraft:cobblestone",
      "worldMeta": 0,
      "stackMeta": 0,
      "needsSupportBlock": false
    },
    {
      "x": 3,
      "y": 0,
      "z": 8,
      "fuzzy": false,
      "block": "minecraft:cobblestone",
      "worldMeta": 0,
      "stackMeta": 0,
      "needsSupportBlock": false
    },
    {
      "x": 3,
      "y": 0,
      "z": 9,
      "fuzzy": false,
      "block": "minecraft:log",
      "worldMeta": 0,
      "stackMeta": 0,
      "needsSupportBlock": false
    },
    {
      "x": 3,
      "y": 0,
      "z": 15,
      "fuzzy": false,
      "block": "minecraft:log",
      "worldMeta": 0,
      "stackMeta": 0,
      "needsSupportBlock": false
    },
    {
      "x": 3,
      "y": 0,
      "z": 16,
      "fuzzy": false,
      "block": "minecraft:cobblestone",
      "worldMeta": 0,
      "stackMeta": 0,
      "needsSupportBlock": false
    },
    {
      "x": 3,
      "y": 0,
      "z": 17,
      "fuzzy": false,
      "block": "minecraft:cobblestone",
      "worldMeta": 0,
      "stackMeta": 0,
      "needsSupportBlock": false
    },
    {
      "x": 3,
      "y": 0,
      "z": 18,
      "fuzzy": false,
      "block": "minecraft:cobblestone",
      "worldMeta": 0,
      "stackMeta": 0,
      "needsSupportBlock": false
    },
    {
      "x": 3,
      "y": 0,
      "z": 19,
      "fuzzy": false,
      "block": "minecraft:cobblestone",
      "worldMeta": 0,
      "stackMeta": 0,
      "needsSupportBlock": false
    },
    {
      "x": 3,
      "y": 0,
      "z": 20,
      "fuzzy": false,
      "block": "minecraft:cobblestone",
      "worldMeta": 0,
      "stackMeta": 0,
      "needsSupportBlock": false
    },
    {
      "x": 3,
      "y": 0,
      "z": 21,
      "fuzzy": false,
      "block": "minecraft:cobblestone",
      "worldMeta": 0,
      "stackMeta": 0,
      "needsSupportBlock": false
    },
    {
      "x": 3,
      "y": 0,
      "z": 22,
      "fuzzy": false,
      "block": "minecraft:cobblestone",
      "worldMeta": 0,
      "stackMeta": 0,
      "needsSupportBlock": false
    },
    {
      "x": 3,
      "y": 0,
      "z": 23,
      "fuzzy": false,
      "block": "minecraft:log",
      "worldMeta": 0,
      "stackMeta": 0,
      "needsSupportBlock": false
    },
    {
      "x": 3,
      "y": 0,
      "z": 25,
      "fuzzy": false,
      "block": "minecraft:cobblestone",
      "worldMeta": 0,
      "stackMeta": 0,
      "needsSupportBlock": false
    },
    {
      "x": 3,
      "y": 1,
      "z": 1,
      "fuzzy": false,
      "block": "minecraft:stone_stairs",
      "worldMeta": 2,
      "stackMeta": 0,
      "needsSupportBlock": false,
      "rotationMetaTransform": [
        2,
        1,
        3,
        0
      ]
    },
    {
      "x": 3,
      "y": 1,
      "z": 3,
      "fuzzy": false,
      "block": "minecraft:log",
      "worldMeta": 0,
      "stackMeta": 0,
      "needsSupportBlock": false
    },
    {
      "x": 3,
      "y": 1,
      "z": 4,
      "fuzzy": false,
      "block": "minecraft:planks",
      "worldMeta": 0,
      "stackMeta": 0,
      "needsSupportBlock": false
    },
    {
      "x": 3,
      "y": 1,
      "z": 5,
      "fuzzy": false,
      "block": "minecraft:oak_stairs",
      "worldMeta": 0,
      "stackMeta": 0,
      "needsSupportBlock": false,
      "rotationMetaTransform": [
        2,
        1,
        3,
        0
      ]
    },
    {
      "x": 3,
      "y": 1,
      "z": 6,
      "fuzzy": false,
      "block": "minecraft:planks",
      "worldMeta": 0,
      "stackMeta": 0,
      "needsSupportBlock": false
    },
    {
      "x": 3,
      "y": 1,
      "z": 7,
      "fuzzy": false,
      "block": "minecraft:oak_stairs",
      "worldMeta": 0,
      "stackMeta": 0,
      "needsSupportBlock": false,
      "rotationMetaTransform": [
        2,
        1,
        3,
        0
      ]
    },
    {
      "x": 3,
      "y": 1,
      "z": 8,
      "fuzzy": false,
      "block": "minecraft:planks",
      "worldMeta": 0,
      "stackMeta": 0,
      "needsSupportBlock": false
    },
    {
      "x": 3,
      "y": 1,
      "z": 9,
      "fuzzy": false,
      "block": "minecraft:log",
      "worldMeta": 0,
      "stackMeta": 0,
      "needsSupportBlock": false
    },
    {
      "x": 3,
      "y": 1,
      "z": 15,
      "fuzzy": false,
      "block": "minecraft:log",
      "worldMeta": 0,
      "stackMeta": 0,
      "needsSupportBlock": false
    },
    {
      "x": 3,
      "y": 1,
      "z": 16,
      "fuzzy": false,
      "block": "minecraft:planks",
      "worldMeta": 0,
      "stackMeta": 0,
      "needsSupportBlock": false
    },
    {
      "x": 3,
      "y": 1,
      "z": 17,
      "fuzzy": false,
      "block": "minecraft:planks",
      "worldMeta": 0,
      "stackMeta": 0,
      "needsSupportBlock": false
    },
    {
      "x": 3,
      "y": 1,
      "z": 18,
      "fuzzy": false,
      "block": "minecraft:planks",
      "worldMeta": 0,
      "stackMeta": 0,
      "needsSupportBlock": false
    },
    {
      "x": 3,
      "y": 1,
      "z": 19,
      "fuzzy": false,
      "block": "minecraft:planks",
      "worldMeta": 0,
      "stackMeta": 0,
      "needsSupportBlock": false
    },
    {
      "x": 3,
      "y": 1,
      "z": 20,
      "fuzzy": false,
      "block": "minecraft:planks",
      "worldMeta": 0,
      "stackMeta": 0,
      "needsSupportBlock": false
    },
    {
      "x": 3,
      "y": 1,
      "z": 21,
      "fuzzy": false,
      "block": "minecraft:planks",
      "worldMeta": 0,
      "stackMeta": 0,
      "needsSupportBlock": false
    },
    {
      "x": 3,
      "y": 1,
      "z": 22,
      "fuzzy": false,
      "block": "minecraft:planks",
      "worldMeta": 0,
      "stackMeta": 0,
      "needsSupportBlock": false
    },
    {
      "x": 3,
      "y": 1,
      "z": 23,
      "fuzzy": false,
      "block": "minecraft:log",
      "worldMeta": 0,
      "stackMeta": 0,
      "needsSupportBlock": false
    },
    {
      "x": 3,
      "y": 1,
      "z": 25,
      "fuzzy": false,
      "block": "minecraft:stone_stairs",
      "worldMeta": 3,
      "stackMeta": 0,
      "needsSupportBlock": false,
      "rotationMetaTransform": [
        2,
        1,
        3,
        0
      ]
    },
    {
      "x": 3,
      "y": 2,
      "z": 1,
      "fuzzy": false,
      "block": "minecraft:iron_bars",
      "worldMeta": 0,
      "stackMeta": 0,
      "needsSupportBlock": false
    },
    {
      "x": 3,
      "y": 2,
      "z": 3,
      "fuzzy": false,
      "block": "minecraft:log",
      "worldMeta": 0,
      "stackMeta": 0,
      "needsSupportBlock": false
    },
    {
      "x": 3,
      "y": 2,
      "z": 4,
      "fuzzy": false,
      "block": "minecraft:planks",
      "worldMeta": 0,
      "stackMeta": 0,
      "needsSupportBlock": false
    },
    {
      "x": 3,
      "y": 2,
      "z": 5,
      "fuzzy": false,
      "block": "minecraft:trapdoor",
      "worldMeta": 14,
      "stackMeta": 0,
      "needsSupportBlock": true,
      "rotationMetaTransform": [
        15,
        13,
        14,
        12
      ]
    },
    {
      "x": 3,
      "y": 2,
      "z": 6,
      "fuzzy": false,
      "block": "minecraft:planks",
      "worldMeta": 0,
      "stackMeta": 0,
      "needsSupportBlock": false
    },
    {
      "x": 3,
      "y": 2,
      "z": 7,
      "fuzzy": false,
      "block": "minecraft:trapdoor",
      "worldMeta": 14,
      "stackMeta": 0,
      "needsSupportBlock": true,
      "rotationMetaTransform": [
        15,
        13,
        14,
        12
      ]
    },
    {
      "x": 3,
      "y": 2,
      "z": 8,
      "fuzzy": false,
      "block": "minecraft:planks",
      "worldMeta": 0,
      "stackMeta": 0,
      "needsSupportBlock": false
    },
    {
      "x": 3,
      "y": 2,
      "z": 9,
      "fuzzy": false,
      "block": "minecraft:log",
      "worldMeta": 0,
      "stackMeta": 0,
      "needsSupportBlock": false
    },
    {
      "x": 3,
      "y": 2,
      "z": 14,
      "fuzzy": false,
      "block": "minecraft:torch",
      "worldMeta": 4,
      "stackMeta": 0,
      "needsSupportBlock": true,
      "rotationMetaTransform": [
        3,
        2,
        4,
        1
      ]
    },
    {
      "x": 3,
      "y": 2,
      "z": 15,
      "fuzzy": false,
      "block": "minecraft:log",
      "worldMeta": 0,
      "stackMeta": 0,
      "needsSupportBlock": false
    },
    {
      "x": 3,
      "y": 2,
      "z": 16,
      "fuzzy": false,
      "block": "minecraft:planks",
      "worldMeta": 0,
      "stackMeta": 0,
      "needsSupportBlock": false
    },
    {
      "x": 3,
      "y": 2,
      "z": 17,
      "fuzzy": false,
      "block": "minecraft:planks",
      "worldMeta": 0,
      "stackMeta": 0,
      "needsSupportBlock": false
    },
    {
      "x": 3,
      "y": 2,
      "z": 18,
      "fuzzy": false,
      "block": "minecraft:planks",
      "worldMeta": 0,
      "stackMeta": 0,
      "needsSupportBlock": false
    },
    {
      "x": 3,
      "y": 2,
      "z": 19,
      "fuzzy": false,
      "block": "minecraft:planks",
      "worldMeta": 0,
      "stackMeta": 0,
      "needsSupportBlock": false
    },
    {
      "x": 3,
      "y": 2,
      "z": 20,
      "fuzzy": false,
      "block": "minecraft:planks",
      "worldMeta": 0,
      "stackMeta": 0,
      "needsSupportBlock": false
    },
    {
      "x": 3,
      "y": 2,
      "z": 21,
      "fuzzy": false,
      "block": "minecraft:planks",
      "worldMeta": 0,
      "stackMeta": 0,
      "needsSupportBlock": false
    },
    {
      "x": 3,
      "y": 2,
      "z": 22,
      "fuzzy": false,
      "block": "minecraft:planks",
      "worldMeta": 0,
      "stackMeta": 0,
      "needsSupportBlock": false
    },
    {
      "x": 3,
      "y": 2,
      "z": 23,
      "fuzzy": false,
      "block": "minecraft:log",
      "worldMeta": 0,
      "stackMeta": 0,
      "needsSupportBlock": false
    },
    {
      "x": 3,
      "y": 2,
      "z": 24,
      "fuzzy": false,
      "block": "minecraft:torch",
      "worldMeta": 3,
      "stackMeta": 0,
      "needsSupportBlock": true,
      "rotationMetaTransform": [
        3,
        2,
        4,
        1
      ]
    },
    {
      "x": 3,
      "y": 2,
      "z": 25,
      "fuzzy": false,
      "block": "minecraft:iron_bars",
      "worldMeta": 0,
      "stackMeta": 0,
      "needsSupportBlock": false
    },
    {
      "x": 3,
      "y": 3,
      "z": 2,
      "fuzzy": false,
      "block": "minecraft:torch",
      "worldMeta": 4,
      "stackMeta": 0,
      "needsSupportBlock": true,
      "rotationMetaTransform": [
        3,
        2,
        4,
        1
      ]
    },
    {
      "x": 3,
      "y": 3,
      "z": 3,
      "fuzzy": false,
      "block": "minecraft:log",
      "worldMeta": 0,
      "stackMeta": 0,
      "needsSupportBlock": false
    },
    {
      "x": 3,
      "y": 3,
      "z": 4,
      "fuzzy": false,
      "block": "minecraft:log",
      "worldMeta": 8,
      "stackMeta": 0,
      "needsSupportBlock": false,
      "rotationMetaTransform": [
        4,
        8,
        4,
        8
      ]
    },
    {
      "x": 3,
      "y": 3,
      "z": 5,
      "fuzzy": false,
      "block": "minecraft:log",
      "worldMeta": 8,
      "stackMeta": 0,
      "needsSupportBlock": false,
      "rotationMetaTransform": [
        4,
        8,
        4,
        8
      ]
    },
    {
      "x": 3,
      "y": 3,
      "z": 6,
      "fuzzy": false,
      "block": "minecraft:log",
      "worldMeta": 8,
      "stackMeta": 0,
      "needsSupportBlock": false,
      "rotationMetaTransform": [
        4,
        8,
        4,
        8
      ]
    },
    {
      "x": 3,
      "y": 3,
      "z": 7,
      "fuzzy": false,
      "block": "minecraft:log",
      "worldMeta": 8,
      "stackMeta": 0,
      "needsSupportBlock": false,
      "rotationMetaTransform": [
        4,
        8,
        4,
        8
      ]
    },
    {
      "x": 3,
      "y": 3,
      "z": 8,
      "fuzzy": false,
      "block": "minecraft:log",
      "worldMeta": 8,
      "stackMeta": 0,
      "needsSupportBlock": false,
      "rotationMetaTransform": [
        4,
        8,
        4,
        8
      ]
    },
    {
      "x": 3,
      "y": 3,
      "z": 9,
      "fuzzy": false,
      "block": "minecraft:log",
      "worldMeta": 0,
      "stackMeta": 0,
      "needsSupportBlock": false
    },
    {
      "x": 3,
      "y": 3,
      "z": 10,
      "fuzzy": false,
      "block": "minecraft:torch",
      "worldMeta": 3,
      "stackMeta": 0,
      "needsSupportBlock": true,
      "rotationMetaTransform": [
        3,
        2,
        4,
        1
      ]
    },
    {
      "x": 3,
      "y": 3,
      "z": 15,
      "fuzzy": false,
      "block": "minecraft:log",
      "worldMeta": 0,
      "stackMeta": 0,
      "needsSupportBlock": false
    },
    {
      "x": 3,
      "y": 3,
      "z": 16,
      "fuzzy": false,
      "block": "minecraft:log",
      "worldMeta": 8,
      "stackMeta": 0,
      "needsSupportBlock": false,
      "rotationMetaTransform": [
        4,
        8,
        4,
        8
      ]
    },
    {
      "x": 3,
      "y": 3,
      "z": 17,
      "fuzzy": false,
      "block": "minecraft:log",
      "worldMeta": 8,
      "stackMeta": 0,
      "needsSupportBlock": false,
      "rotationMetaTransform": [
        4,
        8,
        4,
        8
      ]
    },
    {
      "x": 3,
      "y": 3,
      "z": 18,
      "fuzzy": false,
      "block": "minecraft:log",
      "worldMeta": 8,
      "stackMeta": 0,
      "needsSupportBlock": false,
      "rotationMetaTransform": [
        4,
        8,
        4,
        8
      ]
    },
    {
      "x": 3,
      "y": 3,
      "z": 19,
      "fuzzy": false,
      "block": "minecraft:log",
      "worldMeta": 8,
      "stackMeta": 0,
      "needsSupportBlock": false,
      "rotationMetaTransform": [
        4,
        8,
        4,
        8
      ]
    },
    {
      "x": 3,
      "y": 3,
      "z": 20,
      "fuzzy": false,
      "block": "minecraft:log",
      "worldMeta": 8,
      "stackMeta": 0,
      "needsSupportBlock": false,
      "rotationMetaTransform": [
        4,
        8,
        4,
        8
      ]
    },
    {
      "x": 3,
      "y": 3,
      "z": 21,
      "fuzzy": false,
      "block": "minecraft:log",
      "worldMeta": 8,
      "stackMeta": 0,
      "needsSupportBlock": false,
      "rotationMetaTransform": [
        4,
        8,
        4,
        8
      ]
    },
    {
      "x": 3,
      "y": 3,
      "z": 22,
      "fuzzy": false,
      "block": "minecraft:log",
      "worldMeta": 8,
      "stackMeta": 0,
      "needsSupportBlock": false,
      "rotationMetaTransform": [
        4,
        8,
        4,
        8
      ]
    },
    {
      "x": 3,
      "y": 3,
      "z": 23,
      "fuzzy": false,
      "block": "minecraft:log",
      "worldMeta": 0,
      "stackMeta": 0,
      "needsSupportBlock": false
    },
    {
      "x": 3,
      "y": 4,
      "z": 3,
      "fuzzy": false,
      "block": "minecraft:stone_slab",
      "worldMeta": 4,
      "stackMeta": 4,
      "needsSupportBlock": false
    },
    {
      "x": 3,
      "y": 4,
      "z": 4,
      "fuzzy": false,
      "block": "minecraft:stone_slab",
      "worldMeta": 4,
      "stackMeta": 4,
      "needsSupportBlock": false
    },
    {
      "x": 3,
      "y": 4,
      "z": 5,
      "fuzzy": false,
      "block": "minecraft:stone_slab",
      "worldMeta": 4,
      "stackMeta": 4,
      "needsSupportBlock": false
    },
    {
      "x": 3,
      "y": 4,
      "z": 6,
      "fuzzy": false,
      "block": "minecraft:stone_slab",
      "worldMeta": 4,
      "stackMeta": 4,
      "needsSupportBlock": false
    },
    {
      "x": 3,
      "y": 4,
      "z": 7,
      "fuzzy": false,
      "block": "minecraft:stone_slab",
      "worldMeta": 4,
      "stackMeta": 4,
      "needsSupportBlock": false
    },
    {
      "x": 3,
      "y": 4,
      "z": 8,
      "fuzzy": false,
      "block": "minecraft:stone_slab",
      "worldMeta": 4,
      "stackMeta": 4,
      "needsSupportBlock": false
    },
    {
      "x": 3,
      "y": 4,
      "z": 9,
      "fuzzy": false,
      "block": "minecraft:stone_slab",
      "worldMeta": 4,
      "stackMeta": 4,
      "needsSupportBlock": false
    },
    {
      "x": 3,
      "y": 4,
      "z": 15,
      "fuzzy": false,
      "block": "minecraft:stone_slab",
      "worldMeta": 4,
      "stackMeta": 4,
      "needsSupportBlock": false
    },
    {
      "x": 3,
      "y": 4,
      "z": 16,
      "fuzzy": false,
      "block": "minecraft:stone_slab",
      "worldMeta": 4,
      "stackMeta": 4,
      "needsSupportBlock": false
    },
    {
      "x": 3,
      "y": 4,
      "z": 17,
      "fuzzy": false,
      "block": "minecraft:stone_slab",
      "worldMeta": 4,
      "stackMeta": 4,
      "needsSupportBlock": false
    },
    {
      "x": 3,
      "y": 4,
      "z": 18,
      "fuzzy": false,
      "block": "minecraft:stone_slab",
      "worldMeta": 4,
      "stackMeta": 4,
      "needsSupportBlock": false
    },
    {
      "x": 3,
      "y": 4,
      "z": 19,
      "fuzzy": false,
      "block": "minecraft:stone_slab",
      "worldMeta": 4,
      "stackMeta": 4,
      "needsSupportBlock": false
    },
    {
      "x": 3,
      "y": 4,
      "z": 20,
      "fuzzy": false,
      "block": "minecraft:stone_slab",
      "worldMeta": 4,
      "stackMeta": 4,
      "needsSupportBlock": false
    },
    {
      "x": 3,
      "y": 4,
      "z": 21,
      "fuzzy": false,
      "block": "minecraft:stone_slab",
      "worldMeta": 4,
      "stackMeta": 4,
      "needsSupportBlock": false
    },
    {
      "x": 3,
      "y": 4,
      "z": 22,
      "fuzzy": false,
      "block": "minecraft:stone_slab",
      "worldMeta": 4,
      "stackMeta": 4,
      "needsSupportBlock": false
    },
    {
      "x": 3,
      "y": 4,
      "z": 23,
      "fuzzy": false,
      "block": "minecraft:stone_slab",
      "worldMeta": 4,
      "stackMeta": 4,
      "needsSupportBlock": false
    },
    {
      "x": 4,
      "y": 0,
      "z": 1,
      "fuzzy": false,
      "block": "minecraft:cobblestone",
      "worldMeta": 0,
      "stackMeta": 0,
      "needsSupportBlock": false
    },
    {
      "x": 4,
      "y": 0,
      "z": 3,
      "fuzzy": false,
      "block": "minecraft:cobblestone",
      "worldMeta": 0,
      "stackMeta": 0,
      "needsSupportBlock": false
    },
    {
      "x": 4,
      "y": 0,
      "z": 4,
      "fuzzy": false,
      "block": "minecraft:cobblestone",
      "worldMeta": 0,
      "stackMeta": 0,
      "needsSupportBlock": false
    },
    {
      "x": 4,
      "y": 0,
      "z": 5,
      "fuzzy": false,
      "block": "minecraft:cobblestone",
      "worldMeta": 0,
      "stackMeta": 0,
      "needsSupportBlock": false
    },
    {
      "x": 4,
      "y": 0,
      "z": 6,
      "fuzzy": false,
      "block": "minecraft:cobblestone",
      "worldMeta": 0,
      "stackMeta": 0,
      "needsSupportBlock": false
    },
    {
      "x": 4,
      "y": 0,
      "z": 7,
      "fuzzy": false,
      "block": "minecraft:cobblestone",
      "worldMeta": 0,
      "stackMeta": 0,
      "needsSupportBlock": false
    },
    {
      "x": 4,
      "y": 0,
      "z": 8,
      "fuzzy": false,
      "block": "minecraft:cobblestone",
      "worldMeta": 0,
      "stackMeta": 0,
      "needsSupportBlock": false
    },
    {
      "x": 4,
      "y": 0,
      "z": 9,
      "fuzzy": false,
      "block": "minecraft:cobblestone",
      "worldMeta": 0,
      "stackMeta": 0,
      "needsSupportBlock": false
    },
    {
      "x": 4,
      "y": 0,
      "z": 11,
      "fuzzy": false,
      "block": "minecraft:log",
      "worldMeta": 0,
      "stackMeta": 0,
      "needsSupportBlock": false
    },
    {
      "x": 4,
      "y": 0,
      "z": 12,
      "fuzzy": false,
      "block": "minecraft:cobblestone",
      "worldMeta": 0,
      "stackMeta": 0,
      "needsSupportBlock": false
    },
    {
      "x": 4,
      "y": 0,
      "z": 13,
      "fuzzy": false,
      "block": "minecraft:log",
      "worldMeta": 0,
      "stackMeta": 0,
      "needsSupportBlock": false
    },
    {
      "x": 4,
      "y": 0,
      "z": 15,
      "fuzzy": false,
      "block": "minecraft:fence",
      "worldMeta": 0,
      "stackMeta": 0,
      "needsSupportBlock": false
    },
    {
      "x": 4,
      "y": 0,
      "z": 16,
      "fuzzy": false,
      "block": "minecraft:hay_block",
      "worldMeta": 4,
      "stackMeta": 0,
      "needsSupportBlock": false
    },
    {
      "x": 4,
      "y": 0,
      "z": 17,
      "fuzzy": false,
      "block": "minecraft:hay_block",
      "worldMeta": 8,
      "stackMeta": 0,
      "needsSupportBlock": false
    },
    {
      "x": 4,
      "y": 0,
      "z": 18,
      "fuzzy": false,
      "block": "minecraft:hay_block",
      "worldMeta": 8,
      "stackMeta": 0,
      "needsSupportBlock": false
    },
    {
      "x": 4,
      "y": 0,
      "z": 19,
      "fuzzy": false,
      "block": "minecraft:hay_block",
      "worldMeta": 8,
      "stackMeta": 0,
      "needsSupportBlock": false
    },
    {
      "x": 4,
      "y": 0,
      "z": 20,
      "fuzzy": false,
      "block": "minecraft:hay_block",
      "worldMeta": 4,
      "stackMeta": 0,
      "needsSupportBlock": false
    },
    {
      "x": 4,
      "y": 0,
      "z": 21,
      "fuzzy": false,
      "block": "minecraft:hay_block",
      "worldMeta": 4,
      "stackMeta": 0,
      "needsSupportBlock": false
    },
    {
      "x": 4,
      "y": 0,
      "z": 22,
      "fuzzy": false,
      "block": "minecraft:hay_block",
      "worldMeta": 0,
      "stackMeta": 0,
      "needsSupportBlock": false
    },
    {
      "x": 4,
      "y": 0,
      "z": 23,
      "fuzzy": false,
      "block": "minecraft:fence",
      "worldMeta": 0,
      "stackMeta": 0,
      "needsSupportBlock": false
    },
    {
      "x": 4,
      "y": 0,
      "z": 25,
      "fuzzy": false,
      "block": "minecraft:cobblestone",
      "worldMeta": 0,
      "stackMeta": 0,
      "needsSupportBlock": false
    },
    {
      "x": 4,
      "y": 1,
      "z": 3,
      "fuzzy": false,
      "block": "minecraft:planks",
      "worldMeta": 0,
      "stackMeta": 0,
      "needsSupportBlock": false
    },
    {
      "x": 4,
      "y": 1,
      "z": 4,
      "fuzzy": true,
      "block": "minecraft:bed",
      "worldMeta": 9,
      "stackMeta": 0,
      "needsSupportBlock": false,
      "rotationMetaTransform": [
        8,
        9,
        10,
        11
      ]
    },
    {
      "x": 4,
      "y": 1,
      "z": 5,
      "fuzzy": false,
      "block": "minecraft:chest",
      "worldMeta": 5,
      "stackMeta": 0,
      "needsSupportBlock": false,
      "rotationMetaTransform": [
        5,
        3,
        4,
        2
      ],
      "nbtString": "{x:-1688,y:5,z:-3,Items:[],id:\"Chest\",Lock:\"\"}"
    },
    {
      "x": 4,
      "y": 1,
      "z": 6,
      "fuzzy": true,
      "block": "minecraft:bed",
      "worldMeta": 9,
      "stackMeta": 0,
      "needsSupportBlock": false,
      "rotationMetaTransform": [
        8,
        9,
        10,
        11
      ]
    },
    {
      "x": 4,
      "y": 1,
      "z": 7,
      "fuzzy": false,
      "block": "minecraft:chest",
      "worldMeta": 5,
      "stackMeta": 0,
      "needsSupportBlock": false,
      "rotationMetaTransform": [
        5,
        3,
        4,
        2
      ],
      "nbtString": "{x:-1688,y:5,z:-1,Items:[],id:\"Chest\",Lock:\"\"}"
    },
    {
      "x": 4,
      "y": 1,
      "z": 8,
      "fuzzy": true,
      "block": "minecraft:bed",
      "worldMeta": 9,
      "stackMeta": 0,
      "needsSupportBlock": false,
      "rotationMetaTransform": [
        8,
        9,
        10,
        11
      ]
    },
    {
      "x": 4,
      "y": 1,
      "z": 9,
      "fuzzy": false,
      "block": "minecraft:planks",
      "worldMeta": 0,
      "stackMeta": 0,
      "needsSupportBlock": false
    },
    {
      "x": 4,
      "y": 1,
      "z": 11,
      "fuzzy": false,
      "block": "minecraft:log",
      "worldMeta": 0,
      "stackMeta": 0,
      "needsSupportBlock": false
    },
    {
      "x": 4,
      "y": 1,
      "z": 12,
      "fuzzy": false,
      "block": "minecraft:oak_stairs",
      "worldMeta": 0,
      "stackMeta": 0,
      "needsSupportBlock": false,
      "rotationMetaTransform": [
        2,
        1,
        3,
        0
      ]
    },
    {
      "x": 4,
      "y": 1,
      "z": 13,
      "fuzzy": false,
      "block": "minecraft:log",
      "worldMeta": 0,
      "stackMeta": 0,
      "needsSupportBlock": false
    },
    {
      "x": 4,
      "y": 1,
      "z": 15,
      "fuzzy": false,
      "block": "minecraft:fence",
      "worldMeta": 0,
      "stackMeta": 0,
      "needsSupportBlock": false
    },
    {
      "x": 4,
      "y": 1,
      "z": 18,
      "fuzzy": false,
      "block": "minecraft:hay_block",
      "worldMeta": 8,
      "stackMeta": 0,
      "needsSupportBlock": false
    },
    {
      "x": 4,
      "y": 1,
      "z": 19,
      "fuzzy": false,
      "block": "minecraft:hay_block",
      "worldMeta": 0,
      "stackMeta": 0,
      "needsSupportBlock": false
    },
    {
      "x": 4,
      "y": 1,
      "z": 20,
      "fuzzy": false,
      "block": "minecraft:hay_block",
      "worldMeta": 4,
      "stackMeta": 0,
      "needsSupportBlock": false
    },
    {
      "x": 4,
      "y": 1,
      "z": 21,
      "fuzzy": false,
      "block": "minecraft:hay_block",
      "worldMeta": 0,
      "stackMeta": 0,
      "needsSupportBlock": false
    },
    {
      "x": 4,
      "y": 1,
      "z": 23,
      "fuzzy": false,
      "block": "minecraft:fence",
      "worldMeta": 0,
      "stackMeta": 0,
      "needsSupportBlock": false
    },
    {
      "x": 4,
      "y": 2,
      "z": 1,
      "fuzzy": false,
      "block": "minecraft:iron_bars",
      "worldMeta": 0,
      "stackMeta": 0,
      "needsSupportBlock": false
    },
    {
      "x": 4,
      "y": 2,
      "z": 3,
      "fuzzy": false,
      "block": "minecraft:planks",
      "worldMeta": 0,
      "stackMeta": 0,
      "needsSupportBlock": false
    },
    {
      "x": 4,
      "y": 2,
      "z": 9,
      "fuzzy": false,
      "block": "minecraft:planks",
      "worldMeta": 0,
      "stackMeta": 0,
      "needsSupportBlock": false
    },
    {
      "x": 4,
      "y": 2,
      "z": 11,
      "fuzzy": false,
      "block": "minecraft:log",
      "worldMeta": 0,
      "stackMeta": 0,
      "needsSupportBlock": false
    },
    {
      "x": 4,
      "y": 2,
      "z": 12,
      "fuzzy": false,
      "block": "minecraft:oak_stairs",
      "worldMeta": 4,
      "stackMeta": 0,
      "needsSupportBlock": false,
      "rotationMetaTransform": [
        6,
        5,
        7,
        4
      ]
    },
    {
      "x": 4,
      "y": 2,
      "z": 13,
      "fuzzy": false,
      "block": "minecraft:log",
      "worldMeta": 0,
      "stackMeta": 0,
      "needsSupportBlock": false
    },
    {
      "x": 4,
      "y": 2,
      "z": 15,
      "fuzzy": false,
      "block": "minecraft:torch",
      "worldMeta": 5,
      "stackMeta": 0,
      "needsSupportBlock": true
    },
    {
      "x": 4,
      "y": 2,
      "z": 19,
      "fuzzy": false,
      "block": "minecraft:hay_block",
      "worldMeta": 0,
      "stackMeta": 0,
      "needsSupportBlock": false
    },
    {
      "x": 4,
      "y": 2,
      "z": 23,
      "fuzzy": false,
      "block": "minecraft:torch",
      "worldMeta": 5,
      "stackMeta": 0,
      "needsSupportBlock": true
    },
    {
      "x": 4,
      "y": 2,
      "z": 25,
      "fuzzy": false,
      "block": "minecraft:iron_bars",
      "worldMeta": 0,
      "stackMeta": 0,
      "needsSupportBlock": false
    },
    {
      "x": 4,
      "y": 3,
      "z": 3,
      "fuzzy": false,
      "block": "minecraft:log",
      "worldMeta": 4,
      "stackMeta": 0,
      "needsSupportBlock": false,
      "rotationMetaTransform": [
        4,
        8,
        4,
        8
      ]
    },
    {
      "x": 4,
      "y": 3,
      "z": 9,
      "fuzzy": false,
      "block": "minecraft:log",
      "worldMeta": 4,
      "stackMeta": 0,
      "needsSupportBlock": false,
      "rotationMetaTransform": [
        4,
        8,
        4,
        8
      ]
    },
    {
      "x": 4,
      "y": 3,
      "z": 11,
      "fuzzy": false,
      "block": "minecraft:stone_slab",
      "worldMeta": 4,
      "stackMeta": 4,
      "needsSupportBlock": false
    },
    {
      "x": 4,
      "y": 3,
      "z": 12,
      "fuzzy": false,
      "block": "minecraft:stone_slab",
      "worldMeta": 4,
      "stackMeta": 4,
      "needsSupportBlock": false
    },
    {
      "x": 4,
      "y": 3,
      "z": 13,
      "fuzzy": false,
      "block": "minecraft:stone_slab",
      "worldMeta": 4,
      "stackMeta": 4,
      "needsSupportBlock": false
    },
    {
      "x": 4,
      "y": 3,
      "z": 15,
      "fuzzy": false,
      "block": "minecraft:log",
      "worldMeta": 4,
      "stackMeta": 0,
      "needsSupportBlock": false,
      "rotationMetaTransform": [
        4,
        8,
        4,
        8
      ]
    },
    {
      "x": 4,
      "y": 3,
      "z": 23,
      "fuzzy": false,
      "block": "minecraft:log",
      "worldMeta": 4,
      "stackMeta": 0,
      "needsSupportBlock": false,
      "rotationMetaTransform": [
        4,
        8,
        4,
        8
      ]
    },
    {
      "x": 4,
      "y": 4,
      "z": 3,
      "fuzzy": false,
      "block": "minecraft:stone_slab",
      "worldMeta": 4,
      "stackMeta": 4,
      "needsSupportBlock": false
    },
    {
      "x": 4,
      "y": 4,
      "z": 4,
      "fuzzy": false,
      "block": "minecraft:stone_slab",
      "worldMeta": 4,
      "stackMeta": 4,
      "needsSupportBlock": false
    },
    {
      "x": 4,
      "y": 4,
      "z": 5,
      "fuzzy": false,
      "block": "minecraft:stone_slab",
      "worldMeta": 4,
      "stackMeta": 4,
      "needsSupportBlock": false
    },
    {
      "x": 4,
      "y": 4,
      "z": 6,
      "fuzzy": false,
      "block": "minecraft:stone_slab",
      "worldMeta": 4,
      "stackMeta": 4,
      "needsSupportBlock": false
    },
    {
      "x": 4,
      "y": 4,
      "z": 7,
      "fuzzy": false,
      "block": "minecraft:stone_slab",
      "worldMeta": 4,
      "stackMeta": 4,
      "needsSupportBlock": false
    },
    {
      "x": 4,
      "y": 4,
      "z": 8,
      "fuzzy": false,
      "block": "minecraft:stone_slab",
      "worldMeta": 4,
      "stackMeta": 4,
      "needsSupportBlock": false
    },
    {
      "x": 4,
      "y": 4,
      "z": 9,
      "fuzzy": false,
      "block": "minecraft:stone_slab",
      "worldMeta": 4,
      "stackMeta": 4,
      "needsSupportBlock": false
    },
    {
      "x": 4,
      "y": 4,
      "z": 15,
      "fuzzy": false,
      "block": "minecraft:brick_block",
      "worldMeta": 0,
      "stackMeta": 0,
      "needsSupportBlock": false
    },
    {
      "x": 4,
      "y": 4,
      "z": 16,
      "fuzzy": false,
      "block": "minecraft:brick_block",
      "worldMeta": 0,
      "stackMeta": 0,
      "needsSupportBlock": false
    },
    {
      "x": 4,
      "y": 4,
      "z": 17,
      "fuzzy": false,
      "block": "minecraft:brick_block",
      "worldMeta": 0,
      "stackMeta": 0,
      "needsSupportBlock": false
    },
    {
      "x": 4,
      "y": 4,
      "z": 18,
      "fuzzy": false,
      "block": "minecraft:brick_block",
      "worldMeta": 0,
      "stackMeta": 0,
      "needsSupportBlock": false
    },
    {
      "x": 4,
      "y": 4,
      "z": 19,
      "fuzzy": false,
      "block": "minecraft:brick_block",
      "worldMeta": 0,
      "stackMeta": 0,
      "needsSupportBlock": false
    },
    {
      "x": 4,
      "y": 4,
      "z": 20,
      "fuzzy": false,
      "block": "minecraft:brick_block",
      "worldMeta": 0,
      "stackMeta": 0,
      "needsSupportBlock": false
    },
    {
      "x": 4,
      "y": 4,
      "z": 21,
      "fuzzy": false,
      "block": "minecraft:brick_block",
      "worldMeta": 0,
      "stackMeta": 0,
      "needsSupportBlock": false
    },
    {
      "x": 4,
      "y": 4,
      "z": 22,
      "fuzzy": false,
      "block": "minecraft:brick_block",
      "worldMeta": 0,
      "stackMeta": 0,
      "needsSupportBlock": false
    },
    {
      "x": 4,
      "y": 4,
      "z": 23,
      "fuzzy": false,
      "block": "minecraft:brick_block",
      "worldMeta": 0,
      "stackMeta": 0,
      "needsSupportBlock": false
    },
    {
      "x": 5,
      "y": 0,
      "z": 1,
      "fuzzy": false,
      "block": "minecraft:cobblestone",
      "worldMeta": 0,
      "stackMeta": 0,
      "needsSupportBlock": false
    },
    {
      "x": 5,
      "y": 0,
      "z": 3,
      "fuzzy": false,
      "block": "minecraft:cobblestone",
      "worldMeta": 0,
      "stackMeta": 0,
      "needsSupportBlock": false
    },
    {
      "x": 5,
      "y": 0,
      "z": 4,
      "fuzzy": false,
      "block": "minecraft:cobblestone",
      "worldMeta": 0,
      "stackMeta": 0,
      "needsSupportBlock": false
    },
    {
      "x": 5,
      "y": 0,
      "z": 5,
      "fuzzy": false,
      "block": "minecraft:cobblestone",
      "worldMeta": 0,
      "stackMeta": 0,
      "needsSupportBlock": false
    },
    {
      "x": 5,
      "y": 0,
      "z": 6,
      "fuzzy": false,
      "block": "minecraft:cobblestone",
      "worldMeta": 0,
      "stackMeta": 0,
      "needsSupportBlock": false
    },
    {
      "x": 5,
      "y": 0,
      "z": 7,
      "fuzzy": false,
      "block": "minecraft:cobblestone",
      "worldMeta": 0,
      "stackMeta": 0,
      "needsSupportBlock": false
    },
    {
      "x": 5,
      "y": 0,
      "z": 8,
      "fuzzy": false,
      "block": "minecraft:cobblestone",
      "worldMeta": 0,
      "stackMeta": 0,
      "needsSupportBlock": false
    },
    {
      "x": 5,
      "y": 0,
      "z": 9,
      "fuzzy": false,
      "block": "minecraft:cobblestone",
      "worldMeta": 0,
      "stackMeta": 0,
      "needsSupportBlock": false
    },
    {
      "x": 5,
      "y": 0,
      "z": 11,
      "fuzzy": false,
      "block": "minecraft:cobblestone",
      "worldMeta": 0,
      "stackMeta": 0,
      "needsSupportBlock": false
    },
    {
      "x": 5,
      "y": 0,
      "z": 12,
      "fuzzy": false,
      "block": "minecraft:water",
      "worldMeta": 0,
      "stackMeta": 0,
      "needsSupportBlock": false
    },
    {
      "x": 5,
      "y": 0,
      "z": 13,
      "fuzzy": false,
      "block": "minecraft:cobblestone",
      "worldMeta": 0,
      "stackMeta": 0,
      "needsSupportBlock": false
    },
    {
      "x": 5,
      "y": 0,
      "z": 15,
      "fuzzy": false,
      "block": "minecraft:fence",
      "worldMeta": 0,
      "stackMeta": 0,
      "needsSupportBlock": false
    },
    {
      "x": 5,
      "y": 0,
      "z": 18,
      "fuzzy": false,
      "block": "minecraft:hay_block",
      "worldMeta": 8,
      "stackMeta": 0,
      "needsSupportBlock": false
    },
    {
      "x": 5,
      "y": 0,
      "z": 19,
      "fuzzy": false,
      "block": "minecraft:hay_block",
      "worldMeta": 4,
      "stackMeta": 0,
      "needsSupportBlock": false
    },
    {
      "x": 5,
      "y": 0,
      "z": 20,
      "fuzzy": false,
      "block": "minecraft:hay_block",
      "worldMeta": 0,
      "stackMeta": 0,
      "needsSupportBlock": false
    },
    {
      "x": 5,
      "y": 0,
      "z": 23,
      "fuzzy": false,
      "block": "minecraft:fence",
      "worldMeta": 0,
      "stackMeta": 0,
      "needsSupportBlock": false
    },
    {
      "x": 5,
      "y": 0,
      "z": 25,
      "fuzzy": false,
      "block": "minecraft:cobblestone",
      "worldMeta": 0,
      "stackMeta": 0,
      "needsSupportBlock": false
    },
    {
      "x": 5,
      "y": 1,
      "z": 1,
      "fuzzy": false,
      "block": "minecraft:stone_stairs",
      "worldMeta": 2,
      "stackMeta": 0,
      "needsSupportBlock": false,
      "rotationMetaTransform": [
        2,
        1,
        3,
        0
      ]
    },
    {
      "x": 5,
      "y": 1,
      "z": 3,
      "fuzzy": false,
      "block": "minecraft:oak_stairs",
      "worldMeta": 2,
      "stackMeta": 0,
      "needsSupportBlock": false,
      "rotationMetaTransform": [
        2,
        1,
        3,
        0
      ]
    },
    {
      "x": 5,
      "y": 1,
      "z": 4,
      "fuzzy": true,
      "block": "minecraft:bed",
      "worldMeta": 1,
      "stackMeta": 0,
      "needsSupportBlock": false,
      "rotationMetaTransform": [
        0,
        1,
        2,
        3
      ]
    },
    {
      "x": 5,
      "y": 1,
      "z": 6,
      "fuzzy": true,
      "block": "minecraft:bed",
      "worldMeta": 1,
      "stackMeta": 0,
      "needsSupportBlock": false,
      "rotationMetaTransform": [
        0,
        1,
        2,
        3
      ]
    },
    {
      "x": 5,
      "y": 1,
      "z": 8,
      "fuzzy": true,
      "block": "minecraft:bed",
      "worldMeta": 1,
      "stackMeta": 0,
      "needsSupportBlock": false,
      "rotationMetaTransform": [
        0,
        1,
        2,
        3
      ]
    },
    {
      "x": 5,
      "y": 1,
      "z": 9,
      "fuzzy": false,
      "block": "minecraft:oak_stairs",
      "worldMeta": 3,
      "stackMeta": 0,
      "needsSupportBlock": false,
      "rotationMetaTransform": [
        2,
        1,
        3,
        0
      ]
    },
    {
      "x": 5,
      "y": 1,
      "z": 11,
      "fuzzy": false,
      "block": "minecraft:oak_stairs",
      "worldMeta": 2,
      "stackMeta": 0,
      "needsSupportBlock": false,
      "rotationMetaTransform": [
        2,
        1,
        3,
        0
      ]
    },
    {
      "x": 5,
      "y": 1,
      "z": 12,
      "fuzzy": false,
      "block": "minecraft:trapdoor",
      "worldMeta": 3,
      "stackMeta": 0,
      "needsSupportBlock": true
    },
    {
      "x": 5,
      "y": 1,
      "z": 13,
      "fuzzy": false,
      "block": "minecraft:oak_stairs",
      "worldMeta": 3,
      "stackMeta": 0,
      "needsSupportBlock": false,
      "rotationMetaTransform": [
        2,
        1,
        3,
        0
      ]
    },
    {
      "x": 5,
      "y": 1,
      "z": 15,
      "fuzzy": false,
      "block": "minecraft:fence",
      "worldMeta": 0,
      "stackMeta": 0,
      "needsSupportBlock": false
    },
    {
      "x": 5,
      "y": 1,
      "z": 23,
      "fuzzy": false,
      "block": "minecraft:fence",
      "worldMeta": 0,
      "stackMeta": 0,
      "needsSupportBlock": false
    },
    {
      "x": 5,
      "y": 1,
      "z": 25,
      "fuzzy": false,
      "block": "minecraft:stone_stairs",
      "worldMeta": 3,
      "stackMeta": 0,
      "needsSupportBlock": false,
      "rotationMetaTransform": [
        2,
        1,
        3,
        0
      ]
    },
    {
      "x": 5,
      "y": 2,
      "z": 1,
      "fuzzy": false,
      "block": "minecraft:iron_bars",
      "worldMeta": 0,
      "stackMeta": 0,
      "needsSupportBlock": false
    },
    {
      "x": 5,
      "y": 2,
      "z": 3,
      "fuzzy": false,
      "block": "minecraft:trapdoor",
      "worldMeta": 12,
      "stackMeta": 0,
      "needsSupportBlock": true,
      "rotationMetaTransform": [
        15,
        13,
        14,
        12
      ]
    },
    {
      "x": 5,
      "y": 2,
      "z": 9,
      "fuzzy": false,
      "block": "minecraft:trapdoor",
      "worldMeta": 13,
      "stackMeta": 0,
      "needsSupportBlock": true,
      "rotationMetaTransform": [
        15,
        13,
        14,
        12
      ]
    },
    {
      "x": 5,
      "y": 2,
      "z": 11,
      "fuzzy": false,
      "block": "minecraft:oak_stairs",
      "worldMeta": 6,
      "stackMeta": 0,
      "needsSupportBlock": false,
      "rotationMetaTransform": [
        6,
        5,
        7,
        4
      ]
    },
    {
      "x": 5,
      "y": 2,
      "z": 13,
      "fuzzy": false,
      "block": "minecraft:oak_stairs",
      "worldMeta": 7,
      "stackMeta": 0,
      "needsSupportBlock": false,
      "rotationMetaTransform": [
        6,
        5,
        7,
        4
      ]
    },
    {
      "x": 5,
      "y": 2,
      "z": 25,
      "fuzzy": false,
      "block": "minecraft:iron_bars",
      "worldMeta": 0,
      "stackMeta": 0,
      "needsSupportBlock": false
    },
    {
      "x": 5,
      "y": 3,
      "z": 3,
      "fuzzy": false,
      "block": "minecraft:log",
      "worldMeta": 4,
      "stackMeta": 0,
      "needsSupportBlock": false,
      "rotationMetaTransform": [
        4,
        8,
        4,
        8
      ]
    },
    {
      "x": 5,
      "y": 3,
      "z": 9,
      "fuzzy": false,
      "block": "minecraft:log",
      "worldMeta": 4,
      "stackMeta": 0,
      "needsSupportBlock": false,
      "rotationMetaTransform": [
        4,
        8,
        4,
        8
      ]
    },
    {
      "x": 5,
      "y": 3,
      "z": 11,
      "fuzzy": false,
      "block": "minecraft:stone_slab",
      "worldMeta": 4,
      "stackMeta": 4,
      "needsSupportBlock": false
    },
    {
      "x": 5,
      "y": 3,
      "z": 12,
      "fuzzy": false,
      "block": "minecraft:stone_slab",
      "worldMeta": 4,
      "stackMeta": 4,
      "needsSupportBlock": false
    },
    {
      "x": 5,
      "y": 3,
      "z": 13,
      "fuzzy": false,
      "block": "minecraft:stone_slab",
      "worldMeta": 4,
      "stackMeta": 4,
      "needsSupportBlock": false
    },
    {
      "x": 5,
      "y": 4,
      "z": 3,
      "fuzzy": false,
      "block": "minecraft:stone_slab",
      "worldMeta": 4,
      "stackMeta": 4,
      "needsSupportBlock": false
    },
    {
      "x": 5,
      "y": 4,
      "z": 4,
      "fuzzy": false,
      "block": "minecraft:stone_slab",
      "worldMeta": 4,
      "stackMeta": 4,
      "needsSupportBlock": false
    },
    {
      "x": 5,
      "y": 4,
      "z": 5,
      "fuzzy": false,
      "block": "minecraft:stone_slab",
      "worldMeta": 4,
      "stackMeta": 4,
      "needsSupportBlock": false
    },
    {
      "x": 5,
      "y": 4,
      "z": 6,
      "fuzzy": false,
      "block": "minecraft:stone_slab",
      "worldMeta": 4,
      "stackMeta": 4,
      "needsSupportBlock": false
    },
    {
      "x": 5,
      "y": 4,
      "z": 7,
      "fuzzy": false,
      "block": "minecraft:stone_slab",
      "worldMeta": 4,
      "stackMeta": 4,
      "needsSupportBlock": false
    },
    {
      "x": 5,
      "y": 4,
      "z": 8,
      "fuzzy": false,
      "block": "minecraft:stone_slab",
      "worldMeta": 4,
      "stackMeta": 4,
      "needsSupportBlock": false
    },
    {
      "x": 5,
      "y": 4,
      "z": 9,
      "fuzzy": false,
      "block": "minecraft:stone_slab",
      "worldMeta": 4,
      "stackMeta": 4,
      "needsSupportBlock": false
    },
    {
      "x": 6,
      "y": 0,
      "z": 1,
      "fuzzy": false,
      "block": "minecraft:cobblestone",
      "worldMeta": 0,
      "stackMeta": 0,
      "needsSupportBlock": false
    },
    {
      "x": 6,
      "y": 0,
      "z": 3,
      "fuzzy": false,
      "block": "minecraft:cobblestone",
      "worldMeta": 0,
      "stackMeta": 0,
      "needsSupportBlock": false
    },
    {
      "x": 6,
      "y": 0,
      "z": 4,
      "fuzzy": false,
      "block": "minecraft:cobblestone",
      "worldMeta": 0,
      "stackMeta": 0,
      "needsSupportBlock": false
    },
    {
      "x": 6,
      "y": 0,
      "z": 5,
      "fuzzy": false,
      "block": "minecraft:cobblestone",
      "worldMeta": 0,
      "stackMeta": 0,
      "needsSupportBlock": false
    },
    {
      "x": 6,
      "y": 0,
      "z": 6,
      "fuzzy": false,
      "block": "minecraft:cobblestone",
      "worldMeta": 0,
      "stackMeta": 0,
      "needsSupportBlock": false
    },
    {
      "x": 6,
      "y": 0,
      "z": 7,
      "fuzzy": false,
      "block": "minecraft:cobblestone",
      "worldMeta": 0,
      "stackMeta": 0,
      "needsSupportBlock": false
    },
    {
      "x": 6,
      "y": 0,
      "z": 8,
      "fuzzy": false,
      "block": "minecraft:cobblestone",
      "worldMeta": 0,
      "stackMeta": 0,
      "needsSupportBlock": false
    },
    {
      "x": 6,
      "y": 0,
      "z": 9,
      "fuzzy": false,
      "block": "minecraft:cobblestone",
      "worldMeta": 0,
      "stackMeta": 0,
      "needsSupportBlock": false
    },
    {
      "x": 6,
      "y": 0,
      "z": 11,
      "fuzzy": false,
      "block": "minecraft:log",
      "worldMeta": 0,
      "stackMeta": 0,
      "needsSupportBlock": false
    },
    {
      "x": 6,
      "y": 0,
      "z": 12,
      "fuzzy": false,
      "block": "minecraft:cobblestone",
      "worldMeta": 0,
      "stackMeta": 0,
      "needsSupportBlock": false
    },
    {
      "x": 6,
      "y": 0,
      "z": 13,
      "fuzzy": false,
      "block": "minecraft:log",
      "worldMeta": 0,
      "stackMeta": 0,
      "needsSupportBlock": false
    },
    {
      "x": 6,
      "y": 0,
      "z": 15,
      "fuzzy": false,
      "block": "minecraft:fence",
      "worldMeta": 0,
      "stackMeta": 0,
      "needsSupportBlock": false
    },
    {
      "x": 6,
      "y": 0,
      "z": 17,
      "fuzzy": false,
      "block": "minecraft:fence",
      "worldMeta": 0,
      "stackMeta": 0,
      "needsSupportBlock": false
    },
    {
      "x": 6,
      "y": 0,
      "z": 23,
      "fuzzy": false,
      "block": "minecraft:fence",
      "worldMeta": 0,
      "stackMeta": 0,
      "needsSupportBlock": false
    },
    {
      "x": 6,
      "y": 0,
      "z": 25,
      "fuzzy": false,
      "block": "minecraft:cobblestone",
      "worldMeta": 0,
      "stackMeta": 0,
      "needsSupportBlock": false
    },
    {
      "x": 6,
      "y": 1,
      "z": 3,
      "fuzzy": false,
      "block": "minecraft:planks",
      "worldMeta": 0,
      "stackMeta": 0,
      "needsSupportBlock": false
    },
    {
      "x": 6,
      "y": 1,
      "z": 9,
      "fuzzy": false,
      "block": "minecraft:planks",
      "worldMeta": 0,
      "stackMeta": 0,
      "needsSupportBlock": false
    },
    {
      "x": 6,
      "y": 1,
      "z": 11,
      "fuzzy": false,
      "block": "minecraft:log",
      "worldMeta": 0,
      "stackMeta": 0,
      "needsSupportBlock": false
    },
    {
      "x": 6,
      "y": 1,
      "z": 12,
      "fuzzy": true,
      "block": "minecraft:wooden_door",
      "worldMeta": 2,
      "stackMeta": 0,
      "needsSupportBlock": true,
      "rotationMetaTransform": [
        0,
        1,
        2,
        3
      ]
    },
    {
      "x": 6,
      "y": 1,
      "z": 13,
      "fuzzy": false,
      "block": "minecraft:log",
      "worldMeta": 0,
      "stackMeta": 0,
      "needsSupportBlock": false
    },
    {
      "x": 6,
      "y": 1,
      "z": 15,
      "fuzzy": false,
      "block": "minecraft:fence",
      "worldMeta": 0,
      "stackMeta": 0,
      "needsSupportBlock": false
    },
    {
      "x": 6,
      "y": 1,
      "z": 17,
      "fuzzy": false,
      "block": "minecraft:fence",
      "worldMeta": 0,
      "stackMeta": 0,
      "needsSupportBlock": false
    },
    {
      "x": 6,
      "y": 1,
      "z": 23,
      "fuzzy": false,
      "block": "minecraft:fence",
      "worldMeta": 0,
      "stackMeta": 0,
      "needsSupportBlock": false
    },
    {
      "x": 6,
      "y": 2,
      "z": 1,
      "fuzzy": false,
      "block": "minecraft:iron_bars",
      "worldMeta": 0,
      "stackMeta": 0,
      "needsSupportBlock": false
    },
    {
      "x": 6,
      "y": 2,
      "z": 3,
      "fuzzy": false,
      "block": "minecraft:planks",
      "worldMeta": 0,
      "stackMeta": 0,
      "needsSupportBlock": false
    },
    {
      "x": 6,
      "y": 2,
      "z": 9,
      "fuzzy": false,
      "block": "minecraft:planks",
      "worldMeta": 0,
      "stackMeta": 0,
      "needsSupportBlock": false
    },
    {
      "x": 6,
      "y": 2,
      "z": 11,
      "fuzzy": false,
      "block": "minecraft:log",
      "worldMeta": 0,
      "stackMeta": 0,
      "needsSupportBlock": false
    },
    {
      "x": 6,
      "y": 2,
      "z": 12,
      "fuzzy": true,
      "block": "minecraft:wooden_door",
      "worldMeta": 8,
      "stackMeta": 0,
      "needsSupportBlock": true
    },
    {
      "x": 6,
      "y": 2,
      "z": 13,
      "fuzzy": false,
      "block": "minecraft:log",
      "worldMeta": 0,
      "stackMeta": 0,
      "needsSupportBlock": false
    },
    {
      "x": 6,
      "y": 2,
      "z": 17,
      "fuzzy": false,
      "block": "minecraft:skull",
      "worldMeta": 1,
      "stackMeta": 0,
      "needsSupportBlock": false,
      "nbtString": "{Rot:4b,x:-1686,y:6,z:9,id:\"Skull\",SkullType:0b}"
    },
    {
      "x": 6,
      "y": 2,
      "z": 25,
      "fuzzy": false,
      "block": "minecraft:iron_bars",
      "worldMeta": 0,
      "stackMeta": 0,
      "needsSupportBlock": false
    },
    {
      "x": 6,
      "y": 3,
      "z": 3,
      "fuzzy": false,
      "block": "minecraft:log",
      "worldMeta": 4,
      "stackMeta": 0,
      "needsSupportBlock": false,
      "rotationMetaTransform": [
        4,
        8,
        4,
        8
      ]
    },
    {
      "x": 6,
      "y": 3,
      "z": 9,
      "fuzzy": false,
      "block": "minecraft:log",
      "worldMeta": 4,
      "stackMeta": 0,
      "needsSupportBlock": false,
      "rotationMetaTransform": [
        4,
        8,
        4,
        8
      ]
    },
    {
      "x": 6,
      "y": 3,
      "z": 11,
      "fuzzy": false,
      "block": "minecraft:stone_slab",
      "worldMeta": 4,
      "stackMeta": 4,
      "needsSupportBlock": false
    },
    {
      "x": 6,
      "y": 3,
      "z": 12,
      "fuzzy": false,
      "block": "minecraft:stone_slab",
      "worldMeta": 4,
      "stackMeta": 4,
      "needsSupportBlock": false
    },
    {
      "x": 6,
      "y": 3,
      "z": 13,
      "fuzzy": false,
      "block": "minecraft:stone_slab",
      "worldMeta": 4,
      "stackMeta": 4,
      "needsSupportBlock": false
    },
    {
      "x": 6,
      "y": 4,
      "z": 3,
      "fuzzy": false,
      "block": "minecraft:stone_slab",
      "worldMeta": 4,
      "stackMeta": 4,
      "needsSupportBlock": false
    },
    {
      "x": 6,
      "y": 4,
      "z": 4,
      "fuzzy": false,
      "block": "minecraft:stone_slab",
      "worldMeta": 4,
      "stackMeta": 4,
      "needsSupportBlock": false
    },
    {
      "x": 6,
      "y": 4,
      "z": 5,
      "fuzzy": false,
      "block": "minecraft:stone_slab",
      "worldMeta": 4,
      "stackMeta": 4,
      "needsSupportBlock": false
    },
    {
      "x": 6,
      "y": 4,
      "z": 6,
      "fuzzy": false,
      "block": "minecraft:stone_slab",
      "worldMeta": 4,
      "stackMeta": 4,
      "needsSupportBlock": false
    },
    {
      "x": 6,
      "y": 4,
      "z": 7,
      "fuzzy": false,
      "block": "minecraft:stone_slab",
      "worldMeta": 4,
      "stackMeta": 4,
      "needsSupportBlock": false
    },
    {
      "x": 6,
      "y": 4,
      "z": 8,
      "fuzzy": false,
      "block": "minecraft:stone_slab",
      "worldMeta": 4,
      "stackMeta": 4,
      "needsSupportBlock": false
    },
    {
      "x": 6,
      "y": 4,
      "z": 9,
      "fuzzy": false,
      "block": "minecraft:stone_slab",
      "worldMeta": 4,
      "stackMeta": 4,
      "needsSupportBlock": false
    },
    {
      "x": 7,
      "y": 0,
      "z": 1,
      "fuzzy": false,
      "block": "minecraft:cobblestone",
      "worldMeta": 0,
      "stackMeta": 0,
      "needsSupportBlock": false
    },
    {
      "x": 7,
      "y": 0,
      "z": 3,
      "fuzzy": false,
      "block": "minecraft:log",
      "worldMeta": 0,
      "stackMeta": 0,
      "needsSupportBlock": false
    },
    {
      "x": 7,
      "y": 0,
      "z": 4,
      "fuzzy": false,
      "block": "minecraft:cobblestone",
      "worldMeta": 0,
      "stackMeta": 0,
      "needsSupportBlock": false
    },
    {
      "x": 7,
      "y": 0,
      "z": 5,
      "fuzzy": false,
      "block": "minecraft:cobblestone",
      "worldMeta": 0,
      "stackMeta": 0,
      "needsSupportBlock": false
    },
    {
      "x": 7,
      "y": 0,
      "z": 6,
      "fuzzy": false,
      "block": "minecraft:cobblestone",
      "worldMeta": 0,
      "stackMeta": 0,
      "needsSupportBlock": false
    },
    {
      "x": 7,
      "y": 0,
      "z": 7,
      "fuzzy": false,
      "block": "minecraft:cobblestone",
      "worldMeta": 0,
      "stackMeta": 0,
      "needsSupportBlock": false
    },
    {
      "x": 7,
      "y": 0,
      "z": 8,
      "fuzzy": false,
      "block": "minecraft:cobblestone",
      "worldMeta": 0,
      "stackMeta": 0,
      "needsSupportBlock": false
    },
    {
      "x": 7,
      "y": 0,
      "z": 9,
      "fuzzy": false,
      "block": "minecraft:log",
      "worldMeta": 0,
      "stackMeta": 0,
      "needsSupportBlock": false
    },
    {
      "x": 7,
      "y": 0,
      "z": 12,
      "fuzzy": false,
      "block": "minecraft:stone_stairs",
      "worldMeta": 1,
      "stackMeta": 0,
      "needsSupportBlock": false,
      "rotationMetaTransform": [
        2,
        1,
        3,
        0
      ]
    },
    {
      "x": 7,
      "y": 0,
      "z": 15,
      "fuzzy": false,
      "block": "minecraft:fence",
      "worldMeta": 0,
      "stackMeta": 0,
      "needsSupportBlock": false
    },
    {
      "x": 7,
      "y": 0,
      "z": 21,
      "fuzzy": false,
      "block": "minecraft:fence",
      "worldMeta": 0,
      "stackMeta": 0,
      "needsSupportBlock": false
    },
    {
      "x": 7,
      "y": 0,
      "z": 23,
      "fuzzy": false,
      "block": "minecraft:fence",
      "worldMeta": 0,
      "stackMeta": 0,
      "needsSupportBlock": false
    },
    {
      "x": 7,
      "y": 0,
      "z": 25,
      "fuzzy": false,
      "block": "minecraft:cobblestone",
      "worldMeta": 0,
      "stackMeta": 0,
      "needsSupportBlock": false
    },
    {
      "x": 7,
      "y": 1,
      "z": 1,
      "fuzzy": false,
      "block": "minecraft:stone_stairs",
      "worldMeta": 2,
      "stackMeta": 0,
      "needsSupportBlock": false,
      "rotationMetaTransform": [
        2,
        1,
        3,
        0
      ]
    },
    {
      "x": 7,
      "y": 1,
      "z": 3,
      "fuzzy": false,
      "block": "minecraft:log",
      "worldMeta": 0,
      "stackMeta": 0,
      "needsSupportBlock": false
    },
    {
      "x": 7,
      "y": 1,
      "z": 4,
      "fuzzy": false,
      "block": "minecraft:planks",
      "worldMeta": 0,
      "stackMeta": 0,
      "needsSupportBlock": false
    },
    {
      "x": 7,
      "y": 1,
      "z": 5,
      "fuzzy": true,
      "block": "minecraft:wooden_door",
      "worldMeta": 2,
      "stackMeta": 0,
      "needsSupportBlock": true,
      "rotationMetaTransform": [
        0,
        1,
        2,
        3
      ]
    },
    {
      "x": 7,
      "y": 1,
      "z": 6,
      "fuzzy": false,
      "block": "minecraft:planks",
      "worldMeta": 0,
      "stackMeta": 0,
      "needsSupportBlock": false
    },
    {
      "x": 7,
      "y": 1,
      "z": 7,
      "fuzzy": false,
      "block": "minecraft:oak_stairs",
      "worldMeta": 1,
      "stackMeta": 0,
      "needsSupportBlock": false,
      "rotationMetaTransform": [
        2,
        1,
        3,
        0
      ]
    },
    {
      "x": 7,
      "y": 1,
      "z": 8,
      "fuzzy": false,
      "block": "minecraft:planks",
      "worldMeta": 0,
      "stackMeta": 0,
      "needsSupportBlock": false
    },
    {
      "x": 7,
      "y": 1,
      "z": 9,
      "fuzzy": false,
      "block": "minecraft:log",
      "worldMeta": 0,
      "stackMeta": 0,
      "needsSupportBlock": false
    },
    {
      "x": 7,
      "y": 1,
      "z": 15,
      "fuzzy": false,
      "block": "minecraft:fence",
      "worldMeta": 0,
      "stackMeta": 0,
      "needsSupportBlock": false
    },
    {
      "x": 7,
      "y": 1,
      "z": 21,
      "fuzzy": false,
      "block": "minecraft:skull",
      "worldMeta": 1,
      "stackMeta": 0,
      "needsSupportBlock": false,
      "nbtString": "{Rot:4b,x:-1685,y:5,z:13,id:\"Skull\",SkullType:4b}"
    },
    {
      "x": 7,
      "y": 1,
      "z": 23,
      "fuzzy": false,
      "block": "minecraft:fence",
      "worldMeta": 0,
      "stackMeta": 0,
      "needsSupportBlock": false
    },
    {
      "x": 7,
      "y": 1,
      "z": 25,
      "fuzzy": false,
      "block": "minecraft:stone_stairs",
      "worldMeta": 3,
      "stackMeta": 0,
      "needsSupportBlock": false,
      "rotationMetaTransform": [
        2,
        1,
        3,
        0
      ]
    },
    {
      "x": 7,
      "y": 2,
      "z": 1,
      "fuzzy": false,
      "block": "minecraft:iron_bars",
      "worldMeta": 0,
      "stackMeta": 0,
      "needsSupportBlock": false
    },
    {
      "x": 7,
      "y": 2,
      "z": 3,
      "fuzzy": false,
      "block": "minecraft:log",
      "worldMeta": 0,
      "stackMeta": 0,
      "needsSupportBlock": false
    },
    {
      "x": 7,
      "y": 2,
      "z": 4,
      "fuzzy": false,
      "block": "minecraft:planks",
      "worldMeta": 0,
      "stackMeta": 0,
      "needsSupportBlock": false
    },
    {
      "x": 7,
      "y": 2,
      "z": 5,
      "fuzzy": true,
      "block": "minecraft:wooden_door",
      "worldMeta": 8,
      "stackMeta": 0,
      "needsSupportBlock": true
    },
    {
      "x": 7,
      "y": 2,
      "z": 6,
      "fuzzy": false,
      "block": "minecraft:planks",
      "worldMeta": 0,
      "stackMeta": 0,
      "needsSupportBlock": false
    },
    {
      "x": 7,
      "y": 2,
      "z": 7,
      "fuzzy": false,
      "block": "minecraft:trapdoor",
      "worldMeta": 15,
      "stackMeta": 0,
      "needsSupportBlock": true,
      "rotationMetaTransform": [
        15,
        13,
        14,
        12
      ]
    },
    {
      "x": 7,
      "y": 2,
      "z": 8,
      "fuzzy": false,
      "block": "minecraft:planks",
      "worldMeta": 0,
      "stackMeta": 0,
      "needsSupportBlock": false
    },
    {
      "x": 7,
      "y": 2,
      "z": 9,
      "fuzzy": false,
      "block": "minecraft:log",
      "worldMeta": 0,
      "stackMeta": 0,
      "needsSupportBlock": false
    },
    {
      "x": 7,
      "y": 2,
      "z": 25,
      "fuzzy": false,
      "block": "minecraft:iron_bars",
      "worldMeta": 0,
      "stackMeta": 0,
      "needsSupportBlock": false
    },
    {
      "x": 7,
      "y": 3,
      "z": 2,
      "fuzzy": false,
      "block": "minecraft:torch",
      "worldMeta": 4,
      "stackMeta": 0,
      "needsSupportBlock": true,
      "rotationMetaTransform": [
        3,
        2,
        4,
        1
      ]
    },
    {
      "x": 7,
      "y": 3,
      "z": 3,
      "fuzzy": false,
      "block": "minecraft:log",
      "worldMeta": 0,
      "stackMeta": 0,
      "needsSupportBlock": false
    },
    {
      "x": 7,
      "y": 3,
      "z": 4,
      "fuzzy": false,
      "block": "minecraft:log",
      "worldMeta": 8,
      "stackMeta": 0,
      "needsSupportBlock": false,
      "rotationMetaTransform": [
        4,
        8,
        4,
        8
      ]
    },
    {
      "x": 7,
      "y": 3,
      "z": 5,
      "fuzzy": false,
      "block": "minecraft:log",
      "worldMeta": 8,
      "stackMeta": 0,
      "needsSupportBlock": false,
      "rotationMetaTransform": [
        4,
        8,
        4,
        8
      ]
    },
    {
      "x": 7,
      "y": 3,
      "z": 6,
      "fuzzy": false,
      "block": "minecraft:log",
      "worldMeta": 8,
      "stackMeta": 0,
      "needsSupportBlock": false,
      "rotationMetaTransform": [
        4,
        8,
        4,
        8
      ]
    },
    {
      "x": 7,
      "y": 3,
      "z": 7,
      "fuzzy": false,
      "block": "minecraft:log",
      "worldMeta": 8,
      "stackMeta": 0,
      "needsSupportBlock": false,
      "rotationMetaTransform": [
        4,
        8,
        4,
        8
      ]
    },
    {
      "x": 7,
      "y": 3,
      "z": 8,
      "fuzzy": false,
      "block": "minecraft:log",
      "worldMeta": 8,
      "stackMeta": 0,
      "needsSupportBlock": false,
      "rotationMetaTransform": [
        4,
        8,
        4,
        8
      ]
    },
    {
      "x": 7,
      "y": 3,
      "z": 9,
      "fuzzy": false,
      "block": "minecraft:log",
      "worldMeta": 0,
      "stackMeta": 0,
      "needsSupportBlock": false
    },
    {
      "x": 7,
      "y": 3,
      "z": 10,
      "fuzzy": false,
      "block": "minecraft:torch",
      "worldMeta": 3,
      "stackMeta": 0,
      "needsSupportBlock": true,
      "rotationMetaTransform": [
        3,
        2,
        4,
        1
      ]
    },
    {
      "x": 7,
      "y": 4,
      "z": 3,
      "fuzzy": false,
      "block": "minecraft:stone_slab",
      "worldMeta": 4,
      "stackMeta": 4,
      "needsSupportBlock": false
    },
    {
      "x": 7,
      "y": 4,
      "z": 4,
      "fuzzy": false,
      "block": "minecraft:stone_slab",
      "worldMeta": 4,
      "stackMeta": 4,
      "needsSupportBlock": false
    },
    {
      "x": 7,
      "y": 4,
      "z": 5,
      "fuzzy": false,
      "block": "minecraft:stone_slab",
      "worldMeta": 4,
      "stackMeta": 4,
      "needsSupportBlock": false
    },
    {
      "x": 7,
      "y": 4,
      "z": 6,
      "fuzzy": false,
      "block": "minecraft:stone_slab",
      "worldMeta": 4,
      "stackMeta": 4,
      "needsSupportBlock": false
    },
    {
      "x": 7,
      "y": 4,
      "z": 7,
      "fuzzy": false,
      "block": "minecraft:stone_slab",
      "worldMeta": 4,
      "stackMeta": 4,
      "needsSupportBlock": false
    },
    {
      "x": 7,
      "y": 4,
      "z": 8,
      "fuzzy": false,
      "block": "minecraft:stone_slab",
      "worldMeta": 4,
      "stackMeta": 4,
      "needsSupportBlock": false
    },
    {
      "x": 7,
      "y": 4,
      "z": 9,
      "fuzzy": false,
      "block": "minecraft:stone_slab",
      "worldMeta": 4,
      "stackMeta": 4,
      "needsSupportBlock": false
    },
    {
      "x": 8,
      "y": 0,
      "z": 1,
      "fuzzy": false,
      "block": "minecraft:cobblestone",
      "worldMeta": 0,
      "stackMeta": 0,
      "needsSupportBlock": false
    },
    {
      "x": 8,
      "y": 0,
      "z": 5,
      "fuzzy": false,
      "block": "minecraft:stone_stairs",
      "worldMeta": 1,
      "stackMeta": 0,
      "needsSupportBlock": false,
      "rotationMetaTransform": [
        2,
        1,
        3,
        0
      ]
    },
    {
      "x": 8,
      "y": 0,
      "z": 15,
      "fuzzy": false,
      "block": "minecraft:fence",
      "worldMeta": 0,
      "stackMeta": 0,
      "needsSupportBlock": false
    },
    {
      "x": 8,
      "y": 0,
      "z": 19,
      "fuzzy": false,
      "block": "minecraft:fence",
      "worldMeta": 0,
      "stackMeta": 0,
      "needsSupportBlock": false
    },
    {
      "x": 8,
      "y": 0,
      "z": 23,
      "fuzzy": false,
      "block": "minecraft:fence",
      "worldMeta": 0,
      "stackMeta": 0,
      "needsSupportBlock": false
    },
    {
      "x": 8,
      "y": 0,
      "z": 25,
      "fuzzy": false,
      "block": "minecraft:cobblestone",
      "worldMeta": 0,
      "stackMeta": 0,
      "needsSupportBlock": false
    },
    {
      "x": 8,
      "y": 1,
      "z": 15,
      "fuzzy": false,
      "block": "minecraft:fence",
      "worldMeta": 0,
      "stackMeta": 0,
      "needsSupportBlock": false
    },
    {
      "x": 8,
      "y": 1,
      "z": 19,
      "fuzzy": false,
      "block": "minecraft:skull",
      "worldMeta": 1,
      "stackMeta": 0,
      "needsSupportBlock": false,
      "nbtString": "{Rot:4b,x:-1684,y:5,z:11,id:\"Skull\",SkullType:2b}"
    },
    {
      "x": 8,
      "y": 1,
      "z": 23,
      "fuzzy": false,
      "block": "minecraft:fence",
      "worldMeta": 0,
      "stackMeta": 0,
      "needsSupportBlock": false
    },
    {
      "x": 8,
      "y": 2,
      "z": 1,
      "fuzzy": false,
      "block": "minecraft:iron_bars",
      "worldMeta": 0,
      "stackMeta": 0,
      "needsSupportBlock": false
    },
    {
      "x": 8,
      "y": 2,
      "z": 25,
      "fuzzy": false,
      "block": "minecraft:iron_bars",
      "worldMeta": 0,
      "stackMeta": 0,
      "needsSupportBlock": false
    },
    {
      "x": 8,
      "y": 3,
      "z": 3,
      "fuzzy": false,
      "block": "minecraft:torch",
      "worldMeta": 1,
      "stackMeta": 0,
      "needsSupportBlock": true,
      "rotationMetaTransform": [
        3,
        2,
        4,
        1
      ]
    },
    {
      "x": 8,
      "y": 3,
      "z": 9,
      "fuzzy": false,
      "block": "minecraft:torch",
      "worldMeta": 1,
      "stackMeta": 0,
      "needsSupportBlock": true,
      "rotationMetaTransform": [
        3,
        2,
        4,
        1
      ]
    },
    {
      "x": 9,
      "y": 0,
      "z": 1,
      "fuzzy": false,
      "block": "minecraft:log",
      "worldMeta": 0,
      "stackMeta": 0,
      "needsSupportBlock": false
    },
    {
      "x": 9,
      "y": 0,
      "z": 15,
      "fuzzy": false,
      "block": "minecraft:fence",
      "worldMeta": 0,
      "stackMeta": 0,
      "needsSupportBlock": false
    },
    {
      "x": 9,
      "y": 0,
      "z": 23,
      "fuzzy": false,
      "block": "minecraft:fence",
      "worldMeta": 0,
      "stackMeta": 0,
      "needsSupportBlock": false
    },
    {
      "x": 9,
      "y": 0,
      "z": 25,
      "fuzzy": false,
      "block": "minecraft:log",
      "worldMeta": 0,
      "stackMeta": 0,
      "needsSupportBlock": false
    },
    {
      "x": 9,
      "y": 1,
      "z": 1,
      "fuzzy": false,
      "block": "minecraft:log",
      "worldMeta": 0,
      "stackMeta": 0,
      "needsSupportBlock": false
    },
    {
      "x": 9,
      "y": 1,
      "z": 15,
      "fuzzy": false,
      "block": "minecraft:fence",
      "worldMeta": 0,
      "stackMeta": 0,
      "needsSupportBlock": false
    },
    {
      "x": 9,
      "y": 1,
      "z": 23,
      "fuzzy": false,
      "block": "minecraft:fence",
      "worldMeta": 0,
      "stackMeta": 0,
      "needsSupportBlock": false
    },
    {
      "x": 9,
      "y": 1,
      "z": 25,
      "fuzzy": false,
      "block": "minecraft:log",
      "worldMeta": 0,
      "stackMeta": 0,
      "needsSupportBlock": false
    },
    {
      "x": 9,
      "y": 2,
      "z": 0,
      "fuzzy": false,
      "block": "minecraft:trapdoor",
      "worldMeta": 12,
      "stackMeta": 0,
      "needsSupportBlock": true,
      "rotationMetaTransform": [
        15,
        13,
        14,
        12
      ]
    },
    {
      "x": 9,
      "y": 2,
      "z": 1,
      "fuzzy": false,
      "block": "minecraft:log",
      "worldMeta": 0,
      "stackMeta": 0,
      "needsSupportBlock": false
    },
    {
      "x": 9,
      "y": 2,
      "z": 25,
      "fuzzy": false,
      "block": "minecraft:log",
      "worldMeta": 0,
      "stackMeta": 0,
      "needsSupportBlock": false
    },
    {
      "x": 9,
      "y": 2,
      "z": 26,
      "fuzzy": false,
      "block": "minecraft:trapdoor",
      "worldMeta": 13,
      "stackMeta": 0,
      "needsSupportBlock": true,
      "rotationMetaTransform": [
        15,
        13,
        14,
        12
      ]
    },
    {
      "x": 9,
      "y": 3,
      "z": 1,
      "fuzzy": false,
      "block": "minecraft:torch",
      "worldMeta": 5,
      "stackMeta": 0,
      "needsSupportBlock": true
    },
    {
      "x": 9,
      "y": 3,
      "z": 25,
      "fuzzy": false,
      "block": "minecraft:torch",
      "worldMeta": 5,
      "stackMeta": 0,
      "needsSupportBlock": true
    },
    {
      "x": 10,
      "y": 0,
      "z": 1,
      "fuzzy": false,
      "block": "minecraft:cobblestone",
      "worldMeta": 0,
      "stackMeta": 0,
      "needsSupportBlock": false
    },
    {
      "x": 10,
      "y": 0,
      "z": 15,
      "fuzzy": false,
      "block": "minecraft:fence",
      "worldMeta": 0,
      "stackMeta": 0,
      "needsSupportBlock": false
    },
    {
      "x": 10,
      "y": 0,
      "z": 23,
      "fuzzy": false,
      "block": "minecraft:fence",
      "worldMeta": 0,
      "stackMeta": 0,
      "needsSupportBlock": false
    },
    {
      "x": 10,
      "y": 0,
      "z": 25,
      "fuzzy": false,
      "block": "minecraft:cobblestone",
      "worldMeta": 0,
      "stackMeta": 0,
      "needsSupportBlock": false
    },
    {
      "x": 10,
      "y": 1,
      "z": 15,
      "fuzzy": false,
      "block": "minecraft:fence",
      "worldMeta": 0,
      "stackMeta": 0,
      "needsSupportBlock": false
    },
    {
      "x": 10,
      "y": 1,
      "z": 23,
      "fuzzy": false,
      "block": "minecraft:fence",
      "worldMeta": 0,
      "stackMeta": 0,
      "needsSupportBlock": false
    },
    {
      "x": 10,
      "y": 2,
      "z": 1,
      "fuzzy": false,
      "block": "minecraft:iron_bars",
      "worldMeta": 0,
      "stackMeta": 0,
      "needsSupportBlock": false
    },
    {
      "x": 10,
      "y": 2,
      "z": 25,
      "fuzzy": false,
      "block": "minecraft:iron_bars",
      "worldMeta": 0,
      "stackMeta": 0,
      "needsSupportBlock": false
    },
    {
      "x": 11,
      "y": 0,
      "z": 1,
      "fuzzy": false,
      "block": "minecraft:cobblestone",
      "worldMeta": 0,
      "stackMeta": 0,
      "needsSupportBlock": false
    },
    {
      "x": 11,
      "y": 0,
      "z": 15,
      "fuzzy": false,
      "block": "minecraft:fence",
      "worldMeta": 0,
      "stackMeta": 0,
      "needsSupportBlock": false
    },
    {
      "x": 11,
      "y": 0,
      "z": 23,
      "fuzzy": false,
      "block": "minecraft:fence",
      "worldMeta": 0,
      "stackMeta": 0,
      "needsSupportBlock": false
    },
    {
      "x": 11,
      "y": 0,
      "z": 25,
      "fuzzy": false,
      "block": "minecraft:cobblestone",
      "worldMeta": 0,
      "stackMeta": 0,
      "needsSupportBlock": false
    },
    {
      "x": 11,
      "y": 1,
      "z": 1,
      "fuzzy": false,
      "block": "minecraft:stone_stairs",
      "worldMeta": 2,
      "stackMeta": 0,
      "needsSupportBlock": false,
      "rotationMetaTransform": [
        2,
        1,
        3,
        0
      ]
    },
    {
      "x": 11,
      "y": 1,
      "z": 15,
      "fuzzy": false,
      "block": "minecraft:fence",
      "worldMeta": 0,
      "stackMeta": 0,
      "needsSupportBlock": false
    },
    {
      "x": 11,
      "y": 1,
      "z": 23,
      "fuzzy": false,
      "block": "minecraft:fence",
      "worldMeta": 0,
      "stackMeta": 0,
      "needsSupportBlock": false
    },
    {
      "x": 11,
      "y": 1,
      "z": 25,
      "fuzzy": false,
      "block": "minecraft:stone_stairs",
      "worldMeta": 3,
      "stackMeta": 0,
      "needsSupportBlock": false,
      "rotationMetaTransform": [
        2,
        1,
        3,
        0
      ]
    },
    {
      "x": 11,
      "y": 2,
      "z": 1,
      "fuzzy": false,
      "block": "minecraft:iron_bars",
      "worldMeta": 0,
      "stackMeta": 0,
      "needsSupportBlock": false
    },
    {
      "x": 11,
      "y": 2,
      "z": 25,
      "fuzzy": false,
      "block": "minecraft:iron_bars",
      "worldMeta": 0,
      "stackMeta": 0,
      "needsSupportBlock": false
    },
    {
      "x": 12,
      "y": 0,
      "z": 1,
      "fuzzy": false,
      "block": "minecraft:cobblestone",
      "worldMeta": 0,
      "stackMeta": 0,
      "needsSupportBlock": false
    },
    {
      "x": 12,
      "y": 0,
      "z": 15,
      "fuzzy": false,
      "block": "minecraft:fence",
      "worldMeta": 0,
      "stackMeta": 0,
      "needsSupportBlock": false
    },
    {
      "x": 12,
      "y": 0,
      "z": 23,
      "fuzzy": false,
      "block": "minecraft:fence",
      "worldMeta": 0,
      "stackMeta": 0,
      "needsSupportBlock": false
    },
    {
      "x": 12,
      "y": 0,
      "z": 25,
      "fuzzy": false,
      "block": "minecraft:cobblestone",
      "worldMeta": 0,
      "stackMeta": 0,
      "needsSupportBlock": false
    },
    {
      "x": 12,
      "y": 1,
      "z": 15,
      "fuzzy": false,
      "block": "minecraft:fence",
      "worldMeta": 0,
      "stackMeta": 0,
      "needsSupportBlock": false
    },
    {
      "x": 12,
      "y": 1,
      "z": 23,
      "fuzzy": false,
      "block": "minecraft:fence",
      "worldMeta": 0,
      "stackMeta": 0,
      "needsSupportBlock": false
    },
    {
      "x": 12,
      "y": 2,
      "z": 1,
      "fuzzy": false,
      "block": "minecraft:iron_bars",
      "worldMeta": 0,
      "stackMeta": 0,
      "needsSupportBlock": false
    },
    {
      "x": 12,
      "y": 2,
      "z": 25,
      "fuzzy": false,
      "block": "minecraft:iron_bars",
      "worldMeta": 0,
      "stackMeta": 0,
      "needsSupportBlock": false
    },
    {
      "x": 13,
      "y": 0,
      "z": 1,
      "fuzzy": false,
      "block": "minecraft:cobblestone",
      "worldMeta": 0,
      "stackMeta": 0,
      "needsSupportBlock": false
    },
    {
      "x": 13,
      "y": 0,
      "z": 15,
      "fuzzy": false,
      "block": "minecraft:fence",
      "worldMeta": 0,
      "stackMeta": 0,
      "needsSupportBlock": false
    },
    {
      "x": 13,
      "y": 0,
      "z": 16,
      "fuzzy": false,
      "block": "minecraft:fence",
      "worldMeta": 0,
      "stackMeta": 0,
      "needsSupportBlock": false
    },
    {
      "x": 13,
      "y": 0,
      "z": 17,
      "fuzzy": false,
      "block": "minecraft:fence_gate",
      "worldMeta": 3,
      "stackMeta": 0,
      "needsSupportBlock": false,
      "rotationMetaTransform": [
        0,
        1,
        2,
        3
      ]
    },
    {
      "x": 13,
      "y": 0,
      "z": 18,
      "fuzzy": false,
      "block": "minecraft:fence",
      "worldMeta": 0,
      "stackMeta": 0,
      "needsSupportBlock": false
    },
    {
      "x": 13,
      "y": 0,
      "z": 19,
      "fuzzy": false,
      "block": "minecraft:fence_gate",
      "worldMeta": 3,
      "stackMeta": 0,
      "needsSupportBlock": false,
      "rotationMetaTransform": [
        0,
        1,
        2,
        3
      ]
    },
    {
      "x": 13,
      "y": 0,
      "z": 20,
      "fuzzy": false,
      "block": "minecraft:fence",
      "worldMeta": 0,
      "stackMeta": 0,
      "needsSupportBlock": false
    },
    {
      "x": 13,
      "y": 0,
      "z": 21,
      "fuzzy": false,
      "block": "minecraft:fence_gate",
      "worldMeta": 3,
      "stackMeta": 0,
      "needsSupportBlock": false,
      "rotationMetaTransform": [
        0,
        1,
        2,
        3
      ]
    },
    {
      "x": 13,
      "y": 0,
      "z": 22,
      "fuzzy": false,
      "block": "minecraft:fence",
      "worldMeta": 0,
      "stackMeta": 0,
      "needsSupportBlock": false
    },
    {
      "x": 13,
      "y": 0,
      "z": 23,
      "fuzzy": false,
      "block": "minecraft:fence",
      "worldMeta": 0,
      "stackMeta": 0,
      "needsSupportBlock": false
    },
    {
      "x": 13,
      "y": 0,
      "z": 25,
      "fuzzy": false,
      "block": "minecraft:cobblestone",
      "worldMeta": 0,
      "stackMeta": 0,
      "needsSupportBlock": false
    },
    {
      "x": 13,
      "y": 1,
      "z": 1,
      "fuzzy": false,
      "block": "minecraft:stone_stairs",
      "worldMeta": 2,
      "stackMeta": 0,
      "needsSupportBlock": false,
      "rotationMetaTransform": [
        2,
        1,
        3,
        0
      ]
    },
    {
      "x": 13,
      "y": 1,
      "z": 15,
      "fuzzy": false,
      "block": "minecraft:fence",
      "worldMeta": 0,
      "stackMeta": 0,
      "needsSupportBlock": false
    },
    {
      "x": 13,
      "y": 1,
      "z": 16,
      "fuzzy": false,
      "block": "minecraft:fence",
      "worldMeta": 0,
      "stackMeta": 0,
      "needsSupportBlock": false
    },
    {
      "x": 13,
      "y": 1,
      "z": 18,
      "fuzzy": false,
      "block": "minecraft:fence",
      "worldMeta": 0,
      "stackMeta": 0,
      "needsSupportBlock": false
    },
    {
      "x": 13,
      "y": 1,
      "z": 20,
      "fuzzy": false,
      "block": "minecraft:fence",
      "worldMeta": 0,
      "stackMeta": 0,
      "needsSupportBlock": false
    },
    {
      "x": 13,
      "y": 1,
      "z": 22,
      "fuzzy": false,
      "block": "minecraft:fence",
      "worldMeta": 0,
      "stackMeta": 0,
      "needsSupportBlock": false
    },
    {
      "x": 13,
      "y": 1,
      "z": 23,
      "fuzzy": false,
      "block": "minecraft:fence",
      "worldMeta": 0,
      "stackMeta": 0,
      "needsSupportBlock": false
    },
    {
      "x": 13,
      "y": 1,
      "z": 25,
      "fuzzy": false,
      "block": "minecraft:stone_stairs",
      "worldMeta": 3,
      "stackMeta": 0,
      "needsSupportBlock": false,
      "rotationMetaTransform": [
        2,
        1,
        3,
        0
      ]
    },
    {
      "x": 13,
      "y": 2,
      "z": 1,
      "fuzzy": false,
      "block": "minecraft:iron_bars",
      "worldMeta": 0,
      "stackMeta": 0,
      "needsSupportBlock": false
    },
    {
      "x": 13,
      "y": 2,
      "z": 15,
      "fuzzy": false,
      "block": "minecraft:torch",
      "worldMeta": 5,
      "stackMeta": 0,
      "needsSupportBlock": true
    },
    {
      "x": 13,
      "y": 2,
      "z": 23,
      "fuzzy": false,
      "block": "minecraft:torch",
      "worldMeta": 5,
      "stackMeta": 0,
      "needsSupportBlock": true
    },
    {
      "x": 13,
      "y": 2,
      "z": 25,
      "fuzzy": false,
      "block": "minecraft:iron_bars",
      "worldMeta": 0,
      "stackMeta": 0,
      "needsSupportBlock": false
    },
    {
      "x": 14,
      "y": 0,
      "z": 1,
      "fuzzy": false,
      "block": "minecraft:cobblestone",
      "worldMeta": 0,
      "stackMeta": 0,
      "needsSupportBlock": false
    },
    {
      "x": 14,
      "y": 0,
      "z": 25,
      "fuzzy": false,
      "block": "minecraft:cobblestone",
      "worldMeta": 0,
      "stackMeta": 0,
      "needsSupportBlock": false
    },
    {
      "x": 14,
      "y": 2,
      "z": 1,
      "fuzzy": false,
      "block": "minecraft:iron_bars",
      "worldMeta": 0,
      "stackMeta": 0,
      "needsSupportBlock": false
    },
    {
      "x": 14,
      "y": 2,
      "z": 25,
      "fuzzy": false,
      "block": "minecraft:iron_bars",
      "worldMeta": 0,
      "stackMeta": 0,
      "needsSupportBlock": false
    },
    {
      "x": 15,
      "y": 0,
      "z": 1,
      "fuzzy": false,
      "block": "minecraft:cobblestone",
      "worldMeta": 0,
      "stackMeta": 0,
      "needsSupportBlock": false
    },
    {
      "x": 15,
      "y": 0,
      "z": 25,
      "fuzzy": false,
      "block": "minecraft:cobblestone",
      "worldMeta": 0,
      "stackMeta": 0,
      "needsSupportBlock": false
    },
    {
      "x": 15,
      "y": 1,
      "z": 1,
      "fuzzy": false,
      "block": "minecraft:stone_stairs",
      "worldMeta": 2,
      "stackMeta": 0,
      "needsSupportBlock": false,
      "rotationMetaTransform": [
        2,
        1,
        3,
        0
      ]
    },
    {
      "x": 15,
      "y": 1,
      "z": 25,
      "fuzzy": false,
      "block": "minecraft:stone_stairs",
      "worldMeta": 3,
      "stackMeta": 0,
      "needsSupportBlock": false,
      "rotationMetaTransform": [
        2,
        1,
        3,
        0
      ]
    },
    {
      "x": 15,
      "y": 2,
      "z": 1,
      "fuzzy": false,
      "block": "minecraft:iron_bars",
      "worldMeta": 0,
      "stackMeta": 0,
      "needsSupportBlock": false
    },
    {
      "x": 15,
      "y": 2,
      "z": 25,
      "fuzzy": false,
      "block": "minecraft:iron_bars",
      "worldMeta": 0,
      "stackMeta": 0,
      "needsSupportBlock": false
    },
    {
      "x": 16,
      "y": 0,
      "z": 1,
      "fuzzy": false,
      "block": "minecraft:cobblestone",
      "worldMeta": 0,
      "stackMeta": 0,
      "needsSupportBlock": false
    },
    {
      "x": 16,
      "y": 0,
      "z": 25,
      "fuzzy": false,
      "block": "minecraft:cobblestone",
      "worldMeta": 0,
      "stackMeta": 0,
      "needsSupportBlock": false
    },
    {
      "x": 16,
      "y": 2,
      "z": 1,
