{
  "groundLevel": 0,
  "home": [
    3,
    2,
    5
  ],
  "blocks": [
    {
      "x": 0,
      "y": 0,
      "z": 5,
      "block": "minecraft:stone_stairs",
      "worldMeta": 0,
      "stackMeta": 0,
      "needsSupportBlock": false,
      "rotationMetaTransform": [
        2,
        1,
        3,
        0
      ]
    },
    {
      "x": 0,
      "y": 0,
      "z": 6,
      "block": "minecraft:stone_stairs",
      "worldMeta": 0,
      "stackMeta": 0,
      "needsSupportBlock": false,
      "rotationMetaTransform": [
        2,
        1,
        3,
        0
      ]
    },
    {
      "x": 0,
      "y": 2,
      "z": 4,
      "block": "minecraft:torch",
      "worldMeta": 2,
      "stackMeta": 0,
      "needsSupportBlock": true,
      "rotationMetaTransform": [
        3,
        2,
        4,
        1
      ]
    },
    {
      "x": 0,
      "y": 4,
      "z": 0,
      "block": "minecraft:brick_stairs",
      "worldMeta": 0,
      "stackMeta": 0,
      "needsSupportBlock": false,
      "rotationMetaTransform": [
        2,
        1,
        3,
        0
      ]
    },
    {
      "x": 0,
      "y": 4,
      "z": 1,
      "block": "minecraft:brick_stairs",
      "worldMeta": 0,
      "stackMeta": 0,
      "needsSupportBlock": false,
      "rotationMetaTransform": [
        2,
        1,
        3,
        0
      ]
    },
    {
      "x": 0,
      "y": 4,
      "z": 2,
      "block": "minecraft:brick_stairs",
      "worldMeta": 0,
      "stackMeta": 0,
      "needsSupportBlock": false,
      "rotationMetaTransform": [
        2,
        1,
        3,
        0
      ]
    },
    {
      "x": 0,
      "y": 4,
      "z": 3,
      "block": "minecraft:brick_stairs",
      "worldMeta": 0,
      "stackMeta": 0,
      "needsSupportBlock": false,
      "rotationMetaTransform": [
        2,
        1,
        3,
        0
      ]
    },
    {
      "x": 0,
      "y": 4,
      "z": 4,
      "block": "minecraft:brick_stairs",
      "worldMeta": 0,
      "stackMeta": 0,
      "needsSupportBlock": false,
      "rotationMetaTransform": [
        2,
        1,
        3,
        0
      ]
    },
    {
      "x": 0,
      "y": 4,
      "z": 5,
      "block": "minecraft:brick_stairs",
      "worldMeta": 0,
      "stackMeta": 0,
      "needsSupportBlock": false,
      "rotationMetaTransform": [
        2,
        1,
        3,
        0
      ]
    },
    {
      "x": 0,
      "y": 4,
      "z": 6,
      "block": "minecraft:brick_stairs",
      "worldMeta": 0,
      "stackMeta": 0,
      "needsSupportBlock": false,
      "rotationMetaTransform": [
        2,
        1,
        3,
        0
      ]
    },
    {
      "x": 0,
      "y": 4,
      "z": 7,
      "block": "minecraft:brick_stairs",
      "worldMeta": 0,
      "stackMeta": 0,
      "needsSupportBlock": false,
      "rotationMetaTransform": [
        2,
        1,
        3,
        0
      ]
    },
    {
      "x": 0,
      "y": 4,
      "z": 8,
      "block": "minecraft:brick_stairs",
      "worldMeta": 0,
      "stackMeta": 0,
      "needsSupportBlock": false,
      "rotationMetaTransform": [
        2,
        1,
        3,
        0
      ]
    },
    {
      "x": 1,
      "y": 0,
      "z": 1,
      "block": "minecraft:log",
      "worldMeta": 0,
      "stackMeta": 0,
      "needsSupportBlock": false
    },
    {
      "x": 1,
      "y": 0,
      "z": 2,
      "block": "minecraft:cobblestone",
      "worldMeta": 0,
      "stackMeta": 0,
      "needsSupportBlock": false
    },
    {
      "x": 1,
      "y": 0,
      "z": 3,
      "block": "minecraft:cobblestone",
      "worldMeta": 0,
      "stackMeta": 0,
      "needsSupportBlock": false
    },
    {
      "x": 1,
      "y": 0,
      "z": 4,
      "block": "minecraft:log",
      "worldMeta": 0,
      "stackMeta": 0,
      "needsSupportBlock": false
    },
    {
      "x": 1,
      "y": 0,
      "z": 5,
      "block": "minecraft:cobblestone",
      "worldMeta": 0,
      "stackMeta": 0,
      "needsSupportBlock": false
    },
    {
      "x": 1,
      "y": 0,
      "z": 6,
      "block": "minecraft:cobblestone",
      "worldMeta": 0,
      "stackMeta": 0,
      "needsSupportBlock": false
    },
    {
      "x": 1,
      "y": 0,
      "z": 7,
      "block": "minecraft:log",
      "worldMeta": 0,
      "stackMeta": 0,
      "needsSupportBlock": false
    },
    {
      "x": 1,
      "y": 1,
      "z": 1,
      "block": "minecraft:log",
      "worldMeta": 0,
      "stackMeta": 0,
      "needsSupportBlock": false
    },
    {
      "x": 1,
      "y": 1,
      "z": 2,
      "block": "minecraft:oak_stairs",
      "worldMeta": 0,
      "stackMeta": 0,
      "needsSupportBlock": false,
      "rotationMetaTransform": [
        2,
        1,
        3,
        0
      ]
    },
    {
      "x": 1,
      "y": 1,
      "z": 3,
      "block": "minecraft:oak_stairs",
      "worldMeta": 0,
      "stackMeta": 0,
      "needsSupportBlock": false,
      "rotationMetaTransform": [
        2,
        1,
        3,
        0
      ]
    },
    {
      "x": 1,
      "y": 1,
      "z": 4,
      "block": "minecraft:log",
      "worldMeta": 0,
      "stackMeta": 0,
      "needsSupportBlock": false
    },
    {
      "x": 1,
      "y": 1,
      "z": 5,
      "fuzzy": true,
      "block": "minecraft:wooden_door",
      "worldMeta": 0,
      "stackMeta": 0,
      "needsSupportBlock": true,
      "rotationMetaTransform": [
        0,
        1,
        2,
        3
      ]
    },
    {
      "x": 1,
      "y": 1,
      "z": 6,
      "block": "minecraft:planks",
      "worldMeta": 0,
      "stackMeta": 0,
      "needsSupportBlock": false
    },
    {
      "x": 1,
      "y": 1,
      "z": 7,
      "block": "minecraft:log",
      "worldMeta": 0,
      "stackMeta": 0,
      "needsSupportBlock": false
    },
    {
      "x": 1,
      "y": 2,
      "z": 1,
      "block": "minecraft:log",
      "worldMeta": 0,
      "stackMeta": 0,
      "needsSupportBlock": false
    },
    {
      "x": 1,
      "y": 2,
      "z": 2,
      "block": "minecraft:glass_pane",
      "worldMeta": 0,
      "stackMeta": 0,
      "needsSupportBlock": false
    },
    {
      "x": 1,
      "y": 2,
      "z": 3,
      "block": "minecraft:glass_pane",
      "worldMeta": 0,
      "stackMeta": 0,
      "needsSupportBlock": false
    },
    {
      "x": 1,
      "y": 2,
      "z": 4,
      "block": "minecraft:log",
      "worldMeta": 0,
      "stackMeta": 0,
      "needsSupportBlock": false
    },
    {
      "x": 1,
      "y": 2,
      "z": 5,
      "fuzzy": true,
      "block": "minecraft:wooden_door",
      "worldMeta": 9,
      "stackMeta": 0,
      "needsSupportBlock": true
    },
    {
      "x": 1,
      "y": 2,
      "z": 6,
      "block": "minecraft:planks",
      "worldMeta": 0,
      "stackMeta": 0,
      "needsSupportBlock": false
    },
    {
      "x": 1,
      "y": 2,
      "z": 7,
      "block": "minecraft:log",
      "worldMeta": 0,
      "stackMeta": 0,
      "needsSupportBlock": false
    },
    {
      "x": 1,
      "y": 3,
      "z": 1,
      "block": "minecraft:log",
      "worldMeta": 0,
      "stackMeta": 0,
      "needsSupportBlock": false
    },
    {
      "x": 1,
      "y": 3,
      "z": 2,
      "block": "minecraft:log",
      "worldMeta": 8,
      "stackMeta": 0,
      "needsSupportBlock": false,
      "rotationMetaTransform": [
        4,
        8,
        4,
        8
      ]
    },
    {
      "x": 1,
      "y": 3,
      "z": 3,
      "block": "minecraft:log",
      "worldMeta": 8,
      "stackMeta": 0,
      "needsSupportBlock": false,
      "rotationMetaTransform": [
        4,
        8,
        4,
        8
      ]
    },
    {
      "x": 1,
      "y": 3,
      "z": 4,
      "block": "minecraft:log",
      "worldMeta": 0,
      "stackMeta": 0,
      "needsSupportBlock": false
    },
    {
      "x": 1,
      "y": 3,
      "z": 5,
      "block": "minecraft:log",
      "worldMeta": 8,
      "stackMeta": 0,
      "needsSupportBlock": false,
      "rotationMetaTransform": [
        4,
        8,
        4,
        8
      ]
    },
    {
      "x": 1,
      "y": 3,
      "z": 6,
      "block": "minecraft:log",
      "worldMeta": 8,
      "stackMeta": 0,
      "needsSupportBlock": false,
      "rotationMetaTransform": [
        4,
        8,
        4,
        8
      ]
    },
    {
      "x": 1,
      "y": 3,
      "z": 7,
      "block": "minecraft:log",
      "worldMeta": 0,
      "stackMeta": 0,
      "needsSupportBlock": false
    },
    {
      "x": 1,
      "y": 4,
      "z": 0,
      "block": "minecraft:brick_stairs",
      "worldMeta": 5,
      "stackMeta": 0,
      "needsSupportBlock": false,
      "rotationMetaTransform": [
        6,
        5,
        7,
        4
      ]
    },
    {
      "x": 1,
      "y": 4,
      "z": 1,
      "block": "minecraft:log",
      "worldMeta": 0,
      "stackMeta": 0,
      "needsSupportBlock": false
    },
    {
      "x": 1,
      "y": 4,
      "z": 2,
      "block": "minecraft:brick_stairs",
      "worldMeta": 5,
      "stackMeta": 0,
      "needsSupportBlock": false,
      "rotationMetaTransform": [
        6,
        5,
        7,
        4
      ]
    },
    {
      "x": 1,
      "y": 4,
      "z": 3,
      "block": "minecraft:brick_stairs",
      "worldMeta": 5,
      "stackMeta": 0,
      "needsSupportBlock": false,
      "rotationMetaTransform": [
        6,
        5,
        7,
        4
      ]
    },
    {
      "x": 1,
      "y": 4,
      "z": 4,
      "block": "minecraft:log",
      "worldMeta": 0,
      "stackMeta": 0,
      "needsSupportBlock": false
    },
    {
      "x": 1,
      "y": 4,
      "z": 5,
      "block": "minecraft:brick_stairs",
      "worldMeta": 5,
      "stackMeta": 0,
      "needsSupportBlock": false,
      "rotationMetaTransform": [
        6,
        5,
        7,
        4
      ]
    },
    {
      "x": 1,
      "y": 4,
      "z": 6,
      "block": "minecraft:brick_stairs",
      "worldMeta": 5,
      "stackMeta": 0,
      "needsSupportBlock": false,
      "rotationMetaTransform": [
        6,
        5,
        7,
        4
      ]
    },
    {
      "x": 1,
      "y": 4,
      "z": 7,
      "block": "minecraft:log",
      "worldMeta": 0,
      "stackMeta": 0,
      "needsSupportBlock": false
    },
    {
      "x": 1,
      "y": 4,
      "z": 8,
      "block": "minecraft:brick_stairs",
      "worldMeta": 5,
      "stackMeta": 0,
      "needsSupportBlock": false,
      "rotationMetaTransform": [
        6,
        5,
        7,
        4
      ]
    },
    {
      "x": 1,
      "y": 5,
      "z": 0,
      "block": "minecraft:brick_stairs",
      "worldMeta": 0,
      "stackMeta": 0,
      "needsSupportBlock": false,
      "rotationMetaTransform": [
        2,
        1,
        3,
        0
      ]
    },
    {
      "x": 1,
      "y": 5,
      "z": 1,
      "block": "minecraft:brick_stairs",
      "worldMeta": 0,
      "stackMeta": 0,
      "needsSupportBlock": false,
      "rotationMetaTransform": [
        2,
        1,
        3,
        0
      ]
    },
    {
      "x": 1,
      "y": 5,
      "z": 2,
      "block": "minecraft:brick_stairs",
      "worldMeta": 0,
      "stackMeta": 0,
      "needsSupportBlock": false,
      "rotationMetaTransform": [
        2,
        1,
        3,
        0
      ]
    },
    {
      "x": 1,
      "y": 5,
      "z": 3,
      "block": "minecraft:brick_stairs",
      "worldMeta": 0,
      "stackMeta": 0,
      "needsSupportBlock": false,
      "rotationMetaTransform": [
        2,
        1,
        3,
        0
      ]
    },
    {
      "x": 1,
      "y": 5,
      "z": 4,
      "block": "minecraft:brick_stairs",
      "worldMeta": 0,
      "stackMeta": 0,
      "needsSupportBlock": false,
      "rotationMetaTransform": [
        2,
        1,
        3,
        0
      ]
    },
    {
      "x": 1,
      "y": 5,
      "z": 5,
      "block": "minecraft:brick_stairs",
      "worldMeta": 0,
      "stackMeta": 0,
      "needsSupportBlock": false,
      "rotationMetaTransform": [
        2,
        1,
        3,
        0
      ]
    },
    {
      "x": 1,
      "y": 5,
      "z": 6,
      "block": "minecraft:brick_stairs",
      "worldMeta": 0,
      "stackMeta": 0,
      "needsSupportBlock": false,
      "rotationMetaTransform": [
        2,
        1,
        3,
        0
      ]
    },
    {
      "x": 1,
      "y": 5,
      "z": 7,
      "block": "minecraft:brick_stairs",
      "worldMeta": 0,
      "stackMeta": 0,
      "needsSupportBlock": false,
      "rotationMetaTransform": [
        2,
        1,
        3,
        0
      ]
    },
    {
      "x": 1,
      "y": 5,
      "z": 8,
      "block": "minecraft:brick_stairs",
      "worldMeta": 0,
      "stackMeta": 0,
      "needsSupportBlock": false,
      "rotationMetaTransform": [
        2,
        1,
        3,
        0
      ]
    },
    {
      "x": 2,
      "y": 0,
      "z": 1,
      "block": "minecraft:cobblestone",
      "worldMeta": 0,
      "stackMeta": 0,
      "needsSupportBlock": false
    },
    {
      "x": 2,
      "y": 0,
      "z": 2,
      "block": "minecraft:cobblestone",
      "worldMeta": 0,
      "stackMeta": 0,
      "needsSupportBlock": false
    },
    {
      "x": 2,
      "y": 0,
      "z": 3,
      "block": "minecraft:cobblestone",
      "worldMeta": 0,
      "stackMeta": 0,
      "needsSupportBlock": false
    },
    {
      "x": 2,
      "y": 0,
      "z": 4,
      "block": "minecraft:cobblestone",
      "worldMeta": 0,
      "stackMeta": 0,
      "needsSupportBlock": false
    },
    {
      "x": 2,
      "y": 0,
      "z": 5,
      "block": "minecraft:cobblestone",
      "worldMeta": 0,
      "stackMeta": 0,
      "needsSupportBlock": false
    },
    {
      "x": 2,
      "y": 0,
      "z": 6,
      "block": "minecraft:cobblestone",
      "worldMeta": 0,
      "stackMeta": 0,
      "needsSupportBlock": false
    },
    {
      "x": 2,
      "y": 0,
      "z": 7,
      "block": "minecraft:cobblestone",
      "worldMeta": 0,
      "stackMeta": 0,
      "needsSupportBlock": false
    },
    {
      "x": 2,
      "y": 1,
      "z": 1,
      "block": "minecraft:planks",
      "worldMeta": 0,
      "stackMeta": 0,
      "needsSupportBlock": false
    },
    {
      "x": 2,
      "y": 1,
      "z": 2,
      "block": "minecraft:bed",
      "worldMeta": 10,
      "stackMeta": 0,
      "needsSupportBlock": false,
      "rotationMetaTransform": [
        8,
        9,
        10,
        11
      ]
    },
    {
      "x": 2,
      "y": 1,
      "z": 3,
      "block": "minecraft:bed",
      "worldMeta": 2,
      "stackMeta": 0,
      "needsSupportBlock": false,
      "rotationMetaTransform": [
        0,
        1,
        2,
        3
      ]
    },
    {
      "x": 2,
      "y": 1,
      "z": 4,
      "block": "minecraft:carpet",
      "worldMeta": 14,
      "stackMeta": 14,
      "needsSupportBlock": false
    },
    {
      "x": 2,
      "y": 1,
      "z": 5,
      "block": "minecraft:carpet",
      "worldMeta": 14,
      "stackMeta": 14,
      "needsSupportBlock": false
    },
    {
      "x": 2,
      "y": 1,
      "z": 6,
      "block": "minecraft:spruce_stairs",
      "worldMeta": 1,
      "stackMeta": 0,
      "needsSupportBlock": false,
      "rotationMetaTransform": [
        2,
        1,
        3,
        0
      ]
    },
    {
      "x": 2,
      "y": 1,
      "z": 7,
      "block": "minecraft:planks",
      "worldMeta": 0,
      "stackMeta": 0,
      "needsSupportBlock": false
    },
    {
      "x": 2,
      "y": 2,
      "z": 1,
      "block": "minecraft:planks",
      "worldMeta": 0,
      "stackMeta": 0,
      "needsSupportBlock": false
    },
    {
      "x": 2,
      "y": 2,
      "z": 7,
      "block": "minecraft:planks",
      "worldMeta": 0,
      "stackMeta": 0,
      "needsSupportBlock": false
    },
    {
      "x": 2,
      "y": 3,
      "z": 1,
      "block": "minecraft:log",
      "worldMeta": 4,
      "stackMeta": 0,
      "needsSupportBlock": false,
      "rotationMetaTransform": [
        4,
        8,
        4,
        8
      ]
    },
    {
      "x": 2,
      "y": 3,
      "z": 7,
      "block": "minecraft:log",
      "worldMeta": 4,
      "stackMeta": 0,
      "needsSupportBlock": false,
      "rotationMetaTransform": [
        4,
        8,
        4,
        8
      ]
    },
    {
      "x": 2,
      "y": 4,
      "z": 1,
      "block": "minecraft:planks",
      "worldMeta": 0,
      "stackMeta": 0,
      "needsSupportBlock": false
    },
    {
      "x": 2,
      "y": 4,
      "z": 7,
      "block": "minecraft:planks",
      "worldMeta": 0,
      "stackMeta": 0,
      "needsSupportBlock": false
    },
    {
      "x": 2,
      "y": 5,
      "z": 0,
      "block": "minecraft:brick_stairs",
      "worldMeta": 5,
      "stackMeta": 0,
      "needsSupportBlock": false,
      "rotationMetaTransform": [
        6,
        5,
        7,
        4
      ]
    },
    {
      "x": 2,
      "y": 5,
      "z": 1,
      "block": "minecraft:planks",
      "worldMeta": 0,
      "stackMeta": 0,
      "needsSupportBlock": false
    },
    {
      "x": 2,
      "y": 5,
      "z": 2,
      "block": "minecraft:brick_stairs",
      "worldMeta": 5,
      "stackMeta": 0,
      "needsSupportBlock": false,
      "rotationMetaTransform": [
        6,
        5,
        7,
        4
      ]
    },
    {
      "x": 2,
      "y": 5,
      "z": 3,
      "block": "minecraft:brick_stairs",
      "worldMeta": 5,
      "stackMeta": 0,
      "needsSupportBlock": false,
      "rotationMetaTransform": [
        6,
        5,
        7,
        4
      ]
    },
    {
      "x": 2,
      "y": 5,
      "z": 4,
      "block": "minecraft:brick_stairs",
      "worldMeta": 5,
      "stackMeta": 0,
      "needsSupportBlock": false,
      "rotationMetaTransform": [
        6,
        5,
        7,
        4
      ]
    },
    {
      "x": 2,
      "y": 5,
      "z": 5,
      "block": "minecraft:brick_stairs",
      "worldMeta": 5,
      "stackMeta": 0,
      "needsSupportBlock": false,
      "rotationMetaTransform": [
        6,
        5,
        7,
        4
      ]
    },
    {
      "x": 2,
      "y": 5,
      "z": 6,
      "block": "minecraft:brick_stairs",
      "worldMeta": 5,
      "stackMeta": 0,
      "needsSupportBlock": false,
      "rotationMetaTransform": [
        6,
        5,
        7,
        4
      ]
    },
    {
      "x": 2,
      "y": 5,
      "z": 7,
      "block": "minecraft:planks",
      "worldMeta": 0,
      "stackMeta": 0,
      "needsSupportBlock": false
    },
    {
      "x": 2,
      "y": 5,
      "z": 8,
      "block": "minecraft:brick_stairs",
      "worldMeta": 5,
      "stackMeta": 0,
      "needsSupportBlock": false,
      "rotationMetaTransform": [
        6,
        5,
        7,
        4
      ]
    },
    {
      "x": 2,
      "y": 6,
      "z": 0,
      "block": "minecraft:brick_stairs",
      "worldMeta": 0,
      "stackMeta": 0,
      "needsSupportBlock": false,
      "rotationMetaTransform": [
        2,
        1,
        3,
        0
      ]
    },
    {
      "x": 2,
      "y": 6,
      "z": 1,
      "block": "minecraft:brick_stairs",
      "worldMeta": 0,
      "stackMeta": 0,
      "needsSupportBlock": false,
      "rotationMetaTransform": [
        2,
        1,
        3,
        0
      ]
    },
    {
      "x": 2,
      "y": 6,
      "z": 2,
      "block": "minecraft:brick_stairs",
      "worldMeta": 0,
      "stackMeta": 0,
      "needsSupportBlock": false,
      "rotationMetaTransform": [
        2,
        1,
        3,
        0
      ]
    },
    {
      "x": 2,
      "y": 6,
      "z": 3,
      "block": "minecraft:brick_stairs",
      "worldMeta": 0,
      "stackMeta": 0,
      "needsSupportBlock": false,
      "rotationMetaTransform": [
        2,
        1,
        3,
        0
      ]
    },
    {
      "x": 2,
      "y": 6,
      "z": 4,
      "block": "minecraft:brick_stairs",
      "worldMeta": 0,
      "stackMeta": 0,
      "needsSupportBlock": false,
      "rotationMetaTransform": [
        2,
        1,
        3,
        0
      ]
    },
    {
      "x": 2,
      "y": 6,
      "z": 5,
      "block": "minecraft:brick_stairs",
      "worldMeta": 0,
      "stackMeta": 0,
      "needsSupportBlock": false,
      "rotationMetaTransform": [
        2,
        1,
        3,
        0
      ]
    },
    {
      "x": 2,
      "y": 6,
      "z": 6,
      "block": "minecraft:brick_stairs",
      "worldMeta": 0,
      "stackMeta": 0,
      "needsSupportBlock": false,
      "rotationMetaTransform": [
        2,
        1,
        3,
        0
      ]
    },
    {
      "x": 2,
      "y": 6,
      "z": 7,
      "block": "minecraft:brick_stairs",
      "worldMeta": 0,
      "stackMeta": 0,
      "needsSupportBlock": false,
      "rotationMetaTransform": [
        2,
        1,
        3,
        0
      ]
    },
    {
      "x": 2,
      "y": 6,
      "z": 8,
      "block": "minecraft:brick_stairs",
      "worldMeta": 0,
      "stackMeta": 0,
      "needsSupportBlock": false,
      "rotationMetaTransform": [
        2,
        1,
        3,
        0
      ]
    },
    {
      "x": 3,
      "y": 0,
      "z": 1,
      "block": "minecraft:cobblestone",
      "worldMeta": 0,
      "stackMeta": 0,
      "needsSupportBlock": false
    },
    {
      "x": 3,
      "y": 0,
      "z": 2,
      "block": "minecraft:cobblestone",
      "worldMeta": 0,
      "stackMeta": 0,
      "needsSupportBlock": false
    },
    {
      "x": 3,
      "y": 0,
      "z": 3,
      "block": "minecraft:cobblestone",
      "worldMeta": 0,
      "stackMeta": 0,
      "needsSupportBlock": false
    },
    {
      "x": 3,
      "y": 0,
      "z": 4,
      "block": "minecraft:cobblestone",
      "worldMeta": 0,
      "stackMeta": 0,
      "needsSupportBlock": false
    },
    {
      "x": 3,
      "y": 0,
      "z": 5,
      "block": "minecraft:cobblestone",
      "worldMeta": 0,
      "stackMeta": 0,
      "needsSupportBlock": false
    },
    {
      "x": 3,
      "y": 0,
      "z": 6,
      "block": "minecraft:cobblestone",
      "worldMeta": 0,
      "stackMeta": 0,
      "needsSupportBlock": false
    },
    {
      "x": 3,
      "y": 0,
      "z": 7,
      "block": "minecraft:cobblestone",
      "worldMeta": 0,
      "stackMeta": 0,
      "needsSupportBlock": false
    },
    {
      "x": 3,
      "y": 1,
      "z": 1,
      "block": "minecraft:oak_stairs",
      "worldMeta": 2,
      "stackMeta": 0,
      "needsSupportBlock": false,
      "rotationMetaTransform": [
        2,
        1,
        3,
        0
      ]
    },
    {
      "x": 3,
      "y": 1,
      "z": 2,
      "block": "minecraft:chest",
      "worldMeta": 3,
      "stackMeta": 0,
      "needsSupportBlock": false,
      "rotationMetaTransform": [
        5,
        3,
        4,
        2
      ],
      "nbtString": "{x:-1715,y:5,z:-41,Items:[],id:\"Chest\",Lock:\"\"}"
    },
    {
      "x": 3,
      "y": 1,
      "z": 3,
      "block": "minecraft:carpet",
      "worldMeta": 14,
      "stackMeta": 14,
      "needsSupportBlock": false
    },
    {
      "x": 3,
      "y": 1,
      "z": 4,
      "block": "minecraft:carpet",
      "worldMeta": 14,
      "stackMeta": 14,
      "needsSupportBlock": false
    },
    {
      "x": 3,
      "y": 1,
      "z": 5,
      "block": "minecraft:carpet",
      "worldMeta": 14,
      "stackMeta": 14,
      "needsSupportBlock": false
    },
    {
      "x": 3,
      "y": 1,
      "z": 6,
      "block": "minecraft:crafting_table",
      "worldMeta": 0,
      "stackMeta": 0,
      "needsSupportBlock": false
    },
    {
      "x": 3,
      "y": 1,
      "z": 7,
      "block": "minecraft:oak_stairs",
      "worldMeta": 3,
      "stackMeta": 0,
      "needsSupportBlock": false,
      "rotationMetaTransform": [
        2,
        1,
        3,
        0
      ]
    },
    {
      "x": 3,
      "y": 2,
      "z": 1,
      "block": "minecraft:glass_pane",
      "worldMeta": 0,
      "stackMeta": 0,
      "needsSupportBlock": false
    },
    {
      "x": 3,
      "y": 2,
      "z": 6,
      "block": "minecraft:flower_pot",
      "worldMeta": 0,
      "stackMeta": 0,
      "needsSupportBlock": false,
      "nbtString": "{Item:\"minecraft:red_flower\",x:-1715,y:6,z:-37,Data:0,id:\"FlowerPot\"}"
    },
    {
      "x": 3,
      "y": 2,
      "z": 7,
      "block": "minecraft:glass_pane",
      "worldMeta": 0,
      "stackMeta": 0,
      "needsSupportBlock": false
    },
    {
      "x": 3,
      "y": 3,
      "z": 0,
      "block": "minecraft:torch",
      "worldMeta": 4,
      "stackMeta": 0,
      "needsSupportBlock": true,
      "rotationMetaTransform": [
        3,
        2,
        4,
        1
      ]
    },
    {
      "x": 3,
      "y": 3,
      "z": 1,
      "block": "minecraft:log",
      "worldMeta": 4,
      "stackMeta": 0,
      "needsSupportBlock": false,
      "rotationMetaTransform": [
        4,
        8,
        4,
        8
      ]
    },
    {
      "x": 3,
      "y": 3,
      "z": 2,
      "block": "minecraft:torch",
      "worldMeta": 3,
      "stackMeta": 0,
      "needsSupportBlock": true,
      "rotationMetaTransform": [
        3,
        2,
        4,
        1
      ]
    },
    {
      "x": 3,
      "y": 3,
      "z": 6,
      "block": "minecraft:torch",
      "worldMeta": 4,
      "stackMeta": 0,
      "needsSupportBlock": true,
      "rotationMetaTransform": [
        3,
        2,
        4,
        1
      ]
    },
    {
      "x": 3,
      "y": 3,
      "z": 7,
      "block": "minecraft:log",
      "worldMeta": 4,
      "stackMeta": 0,
      "needsSupportBlock": false,
      "rotationMetaTransform": [
        4,
        8,
        4,
        8
      ]
    },
    {
      "x": 3,
      "y": 3,
      "z": 8,
      "block": "minecraft:torch",
      "worldMeta": 3,
      "stackMeta": 0,
      "needsSupportBlock": true,
      "rotationMetaTransform": [
        3,
        2,
        4,
        1
      ]
    },
    {
      "x": 3,
      "y": 4,
      "z": 1,
      "block": "minecraft:oak_stairs",
      "worldMeta": 2,
      "stackMeta": 0,
      "needsSupportBlock": false,
      "rotationMetaTransform": [
        2,
        1,
        3,
        0
      ]
    },
    {
      "x": 3,
      "y": 4,
      "z": 7,
      "block": "minecraft:oak_stairs",
      "worldMeta": 3,
      "stackMeta": 0,
      "needsSupportBlock": false,
      "rotationMetaTransform": [
        2,
        1,
        3,
        0
      ]
    },
    {
      "x": 3,
      "y": 5,
      "z": 1,
      "block": "minecraft:glass_pane",
      "worldMeta": 0,
      "stackMeta": 0,
      "needsSupportBlock": false
    },
    {
      "x": 3,
      "y": 5,
      "z": 7,
      "block": "minecraft:glass_pane",
      "worldMeta": 0,
      "stackMeta": 0,
      "needsSupportBlock": false
    },
    {
      "x": 3,
      "y": 6,
      "z": 0,
      "block": "minecraft:brick_block",
      "worldMeta": 0,
      "stackMeta": 0,
      "needsSupportBlock": false
    },
    {
      "x": 3,
      "y": 6,
      "z": 1,
      "block": "minecraft:brick_block",
      "worldMeta": 0,
      "stackMeta": 0,
      "needsSupportBlock": false
    },
    {
      "x": 3,
      "y": 6,
      "z": 2,
      "block": "minecraft:brick_block",
      "worldMeta": 0,
      "stackMeta": 0,
      "needsSupportBlock": false
    },
    {
      "x": 3,
      "y": 6,
      "z": 3,
      "block": "minecraft:brick_block",
      "worldMeta": 0,
      "stackMeta": 0,
      "needsSupportBlock": false
    },
    {
      "x": 3,
      "y": 6,
      "z": 4,
      "block": "minecraft:brick_block",
      "worldMeta": 0,
      "stackMeta": 0,
      "needsSupportBlock": false
    },
    {
      "x": 3,
      "y": 6,
      "z": 5,
      "block": "minecraft:brick_block",
      "worldMeta": 0,
      "stackMeta": 0,
      "needsSupportBlock": false
    },
    {
      "x": 3,
      "y": 6,
      "z": 6,
      "block": "minecraft:brick_block",
      "worldMeta": 0,
      "stackMeta": 0,
      "needsSupportBlock": false
    },
    {
      "x": 3,
      "y": 6,
      "z": 7,
      "block": "minecraft:brick_block",
      "worldMeta": 0,
      "stackMeta": 0,
      "needsSupportBlock": false
    },
    {
      "x": 3,
      "y": 6,
      "z": 8,
      "block": "minecraft:brick_block",
      "worldMeta": 0,
      "stackMeta": 0,
      "needsSupportBlock": false
    },
    {
      "x": 3,
      "y": 7,
      "z": 0,
      "block": "minecraft:stone_slab",
      "worldMeta": 4,
      "stackMeta": 4,
      "needsSupportBlock": false
    },
    {
      "x": 3,
      "y": 7,
      "z": 1,
      "block": "minecraft:stone_slab",
      "worldMeta": 4,
      "stackMeta": 4,
      "needsSupportBlock": false
    },
    {
      "x": 3,
      "y": 7,
      "z": 2,
      "block": "minecraft:stone_slab",
      "worldMeta": 4,
      "stackMeta": 4,
      "needsSupportBlock": false
    },
    {
      "x": 3,
      "y": 7,
      "z": 3,
      "block": "minecraft:stone_slab",
      "worldMeta": 4,
      "stackMeta": 4,
      "needsSupportBlock": false
    },
    {
      "x": 3,
      "y": 7,
      "z": 4,
      "block": "minecraft:stone_slab",
      "worldMeta": 4,
      "stackMeta": 4,
      "needsSupportBlock": false
    },
    {
      "x": 3,
      "y": 7,
      "z": 5,
      "block": "minecraft:stone_slab",
      "worldMeta": 4,
      "stackMeta": 4,
      "needsSupportBlock": false
    },
    {
      "x": 3,
      "y": 7,
      "z": 6,
      "block": "minecraft:stone_slab",
      "worldMeta": 4,
      "stackMeta": 4,
      "needsSupportBlock": false
    },
    {
      "x": 3,
      "y": 7,
      "z": 7,
      "block": "minecraft:stone_slab",
      "worldMeta": 4,
      "stackMeta": 4,
      "needsSupportBlock": false
    },
    {
      "x": 3,
      "y": 7,
      "z": 8,
      "block": "minecraft:stone_slab",
      "worldMeta": 4,
      "stackMeta": 4,
      "needsSupportBlock": false
    },
    {
      "x": 4,
      "y": 0,
      "z": 1,
      "block": "minecraft:cobblestone",
      "worldMeta": 0,
      "stackMeta": 0,
      "needsSupportBlock": false
    },
    {
      "x": 4,
      "y": 0,
      "z": 2,
      "block": "minecraft:cobblestone",
      "worldMeta": 0,
      "stackMeta": 0,
      "needsSupportBlock": false
    },
    {
      "x": 4,
      "y": 0,
      "z": 3,
      "block": "minecraft:cobblestone",
      "worldMeta": 0,
      "stackMeta": 0,
      "needsSupportBlock": false
    },
    {
      "x": 4,
      "y": 0,
      "z": 4,
      "block": "minecraft:cobblestone",
      "worldMeta": 0,
      "stackMeta": 0,
      "needsSupportBlock": false
    },
    {
      "x": 4,
      "y": 0,
      "z": 5,
      "block": "minecraft:cobblestone",
      "worldMeta": 0,
      "stackMeta": 0,
      "needsSupportBlock": false
    },
    {
      "x": 4,
      "y": 0,
      "z": 6,
      "block": "minecraft:cobblestone",
      "worldMeta": 0,
      "stackMeta": 0,
      "needsSupportBlock": false
    },
    {
      "x": 4,
      "y": 0,
      "z": 7,
      "block": "minecraft:cobblestone",
      "worldMeta": 0,
      "stackMeta": 0,
      "needsSupportBlock": false
    },
    {
      "x": 4,
      "y": 1,
      "z": 1,
      "block": "minecraft:planks",
      "worldMeta": 0,
      "stackMeta": 0,
      "needsSupportBlock": false
    },
    {
      "x": 4,
      "y": 1,
      "z": 2,
      "block": "minecraft:bed",
      "worldMeta": 10,
      "stackMeta": 0,
      "needsSupportBlock": false,
      "rotationMetaTransform": [
        8,
        9,
        10,
        11
      ]
    },
    {
      "x": 4,
      "y": 1,
      "z": 3,
      "block": "minecraft:bed",
      "worldMeta": 2,
      "stackMeta": 0,
      "needsSupportBlock": false,
      "rotationMetaTransform": [
        0,
        1,
        2,
        3
      ]
    },
    {
      "x": 4,
      "y": 1,
      "z": 4,
      "block": "minecraft:carpet",
      "worldMeta": 14,
      "stackMeta": 14,
      "needsSupportBlock": false
    },
    {
      "x": 4,
      "y": 1,
      "z": 5,
      "block": "minecraft:carpet",
      "worldMeta": 14,
      "stackMeta": 14,
      "needsSupportBlock": false
    },
    {
      "x": 4,
      "y": 1,
      "z": 6,
      "block": "minecraft:spruce_stairs",
      "worldMeta": 0,
      "stackMeta": 0,
      "needsSupportBlock": false,
      "rotationMetaTransform": [
        2,
        1,
        3,
        0
      ]
    },
    {
      "x": 4,
      "y": 1,
      "z": 7,
      "block": "minecraft:planks",
      "worldMeta": 0,
      "stackMeta": 0,
      "needsSupportBlock": false
    },
    {
      "x": 4,
      "y": 2,
      "z": 1,
      "block": "minecraft:planks",
      "worldMeta": 0,
      "stackMeta": 0,
      "needsSupportBlock": false
    },
    {
      "x": 4,
      "y": 2,
      "z": 7,
      "block": "minecraft:planks",
      "worldMeta": 0,
      "stackMeta": 0,
      "needsSupportBlock": false
    },
    {
      "x": 4,
      "y": 3,
      "z": 1,
      "block": "minecraft:log",
      "worldMeta": 4,
      "stackMeta": 0,
      "needsSupportBlock": false,
      "rotationMetaTransform": [
        4,
        8,
        4,
        8
      ]
    },
    {
      "x": 4,
      "y": 3,
      "z": 7,
      "block": "minecraft:log",
      "worldMeta": 4,
      "stackMeta": 0,
      "needsSupportBlock": false,
      "rotationMetaTransform": [
        4,
        8,
        4,
        8
      ]
    },
    {
      "x": 4,
      "y": 4,
      "z": 1,
      "block": "minecraft:planks",
      "worldMeta": 0,
      "stackMeta": 0,
      "needsSupportBlock": false
    },
    {
      "x": 4,
      "y": 4,
      "z": 7,
      "block": "minecraft:planks",
      "worldMeta": 0,
      "stackMeta": 0,
      "needsSupportBlock": false
    },
    {
      "x": 4,
      "y": 5,
      "z": 0,
      "block": "minecraft:brick_stairs",
      "worldMeta": 4,
      "stackMeta": 0,
      "needsSupportBlock": false,
      "rotationMetaTransform": [
        6,
        5,
        7,
        4
      ]
    },
    {
      "x": 4,
      "y": 5,
      "z": 1,
      "block": "minecraft:planks",
      "worldMeta": 0,
      "stackMeta": 0,
      "needsSupportBlock": false
    },
    {
      "x": 4,
      "y": 5,
      "z": 2,
      "block": "minecraft:brick_stairs",
      "worldMeta": 4,
      "stackMeta": 0,
      "needsSupportBlock": false,
      "rotationMetaTransform": [
        6,
        5,
        7,
        4
      ]
    },
    {
      "x": 4,
      "y": 5,
      "z": 3,
      "block": "minecraft:brick_stairs",
      "worldMeta": 4,
      "stackMeta": 0,
      "needsSupportBlock": false,
      "rotationMetaTransform": [
        6,
        5,
        7,
        4
      ]
    },
    {
      "x": 4,
      "y": 5,
      "z": 4,
      "block": "minecraft:brick_stairs",
      "worldMeta": 4,
      "stackMeta": 0,
      "needsSupportBlock": false,
      "rotationMetaTransform": [
        6,
        5,
        7,
        4
      ]
    },
    {
      "x": 4,
      "y": 5,
      "z": 5,
      "block": "minecraft:brick_stairs",
      "worldMeta": 4,
      "stackMeta": 0,
      "needsSupportBlock": false,
      "rotationMetaTransform": [
        6,
        5,
        7,
        4
      ]
    },
    {
      "x": 4,
      "y": 5,
      "z": 6,
      "block": "minecraft:brick_stairs",
      "worldMeta": 4,
      "stackMeta": 0,
      "needsSupportBlock": false,
      "rotationMetaTransform": [
        6,
        5,
        7,
        4
      ]
    },
    {
      "x": 4,
      "y": 5,
      "z": 7,
      "block": "minecraft:planks",
      "worldMeta": 0,
      "stackMeta": 0,
      "needsSupportBlock": false
    },
    {
      "x": 4,
      "y": 5,
      "z": 8,
      "block": "minecraft:brick_stairs",
      "worldMeta": 4,
      "stackMeta": 0,
      "needsSupportBlock": false,
      "rotationMetaTransform": [
        6,
        5,
        7,
        4
      ]
    },
    {
      "x": 4,
      "y": 6,
      "z": 0,
      "block": "minecraft:brick_stairs",
      "worldMeta": 1,
      "stackMeta": 0,
      "needsSupportBlock": false,
      "rotationMetaTransform": [
        2,
        1,
        3,
        0
      ]
    },
    {
      "x": 4,
      "y": 6,
      "z": 1,
      "block": "minecraft:brick_stairs",
      "worldMeta": 1,
      "stackMeta": 0,
      "needsSupportBlock": false,
      "rotationMetaTransform": [
        2,
        1,
        3,
        0
      ]
    },
    {
      "x": 4,
      "y": 6,
      "z": 2,
      "block": "minecraft:brick_stairs",
      "worldMeta": 1,
      "stackMeta": 0,
      "needsSupportBlock": false,
      "rotationMetaTransform": [
        2,
        1,
        3,
        0
      ]
    },
    {
      "x": 4,
      "y": 6,
      "z": 3,
      "block": "minecraft:brick_stairs",
      "worldMeta": 1,
      "stackMeta": 0,
      "needsSupportBlock": false,
      "rotationMetaTransform": [
        2,
        1,
        3,
        0
      ]
    },
    {
      "x": 4,
      "y": 6,
      "z": 4,
      "block": "minecraft:brick_stairs",
      "worldMeta": 1,
      "stackMeta": 0,
      "needsSupportBlock": false,
      "rotationMetaTransform": [
        2,
        1,
        3,
        0
      ]
    },
    {
      "x": 4,
      "y": 6,
      "z": 5,
      "block": "minecraft:brick_stairs",
      "worldMeta": 1,
      "stackMeta": 0,
      "needsSupportBlock": false,
      "rotationMetaTransform": [
        2,
        1,
        3,
        0
      ]
    },
    {
      "x": 4,
      "y": 6,
      "z": 6,
      "block": "minecraft:brick_stairs",
      "worldMeta": 1,
      "stackMeta": 0,
      "needsSupportBlock": false,
      "rotationMetaTransform": [
        2,
        1,
        3,
        0
      ]
    },
    {
      "x": 4,
      "y": 6,
      "z": 7,
      "block": "minecraft:brick_stairs",
      "worldMeta": 1,
      "stackMeta": 0,
      "needsSupportBlock": false,
      "rotationMetaTransform": [
        2,
        1,
        3,
        0
      ]
    },
    {
      "x": 4,
      "y": 6,
      "z": 8,
      "block": "minecraft:brick_stairs",
      "worldMeta": 1,
      "stackMeta": 0,
      "needsSupportBlock": false,
      "rotationMetaTransform": [
        2,
        1,
        3,
        0
      ]
    },
    {
      "x": 5,
      "y": 0,
      "z": 1,
      "block": "minecraft:log",
      "worldMeta": 0,
      "stackMeta": 0,
      "needsSupportBlock": false
    },
    {
      "x": 5,
      "y": 0,
      "z": 2,
      "block": "minecraft:cobblestone",
      "worldMeta": 0,
      "stackMeta": 0,
      "needsSupportBlock": false
    },
    {
      "x": 5,
      "y": 0,
      "z": 3,
      "block": "minecraft:cobblestone",
      "worldMeta": 0,
      "stackMeta": 0,
      "needsSupportBlock": false
    },
    {
      "x": 5,
      "y": 0,
      "z": 4,
      "block": "minecraft:log",
      "worldMeta": 0,
      "stackMeta": 0,
      "needsSupportBlock": false
    },
    {
      "x": 5,
      "y": 0,
      "z": 5,
      "block": "minecraft:cobblestone",
      "worldMeta": 0,
      "stackMeta": 0,
      "needsSupportBlock": false
    },
    {
      "x": 5,
      "y": 0,
      "z": 6,
      "block": "minecraft:cobblestone",
      "worldMeta": 0,
      "stackMeta": 0,
      "needsSupportBlock": false
    },
    {
      "x": 5,
      "y": 0,
      "z": 7,
      "block": "minecraft:log",
      "worldMeta": 0,
      "stackMeta": 0,
      "needsSupportBlock": false
    },
    {
      "x": 5,
      "y": 1,
      "z": 1,
      "block": "minecraft:log",
      "worldMeta": 0,
      "stackMeta": 0,
      "needsSupportBlock": false
    },
    {
      "x": 5,
      "y": 1,
      "z": 2,
      "block": "minecraft:oak_stairs",
      "worldMeta": 1,
      "stackMeta": 0,
      "needsSupportBlock": false,
      "rotationMetaTransform": [
        2,
        1,
        3,
        0
      ]
    },
    {
      "x": 5,
      "y": 1,
      "z": 3,
      "block": "minecraft:oak_stairs",
      "worldMeta": 1,
      "stackMeta": 0,
      "needsSupportBlock": false,
      "rotationMetaTransform": [
        2,
        1,
        3,
        0
      ]
    },
    {
      "x": 5,
      "y": 1,
      "z": 4,
      "block": "minecraft:log",
      "worldMeta": 0,
      "stackMeta": 0,
      "needsSupportBlock": false
    },
    {
      "x": 5,
      "y": 1,
      "z": 5,
      "block": "minecraft:planks",
      "worldMeta": 0,
      "stackMeta": 0,
      "needsSupportBlock": false
    },
    {
      "x": 5,
      "y": 1,
      "z": 6,
      "block": "minecraft:planks",
      "worldMeta": 0,
      "stackMeta": 0,
      "needsSupportBlock": false
    },
    {
      "x": 5,
      "y": 1,
      "z": 7,
      "block": "minecraft:log",
      "worldMeta": 0,
      "stackMeta": 0,
      "needsSupportBlock": false
    },
    {
      "x": 5,
      "y": 2,
      "z": 1,
      "block": "minecraft:log",
      "worldMeta": 0,
      "stackMeta": 0,
      "needsSupportBlock": false
    },
    {
      "x": 5,
      "y": 2,
      "z": 2,
      "block": "minecraft:glass_pane",
      "worldMeta": 0,
      "stackMeta": 0,
      "needsSupportBlock": false
    },
    {
      "x": 5,
      "y": 2,
      "z": 3,
      "block": "minecraft:glass_pane",
      "worldMeta": 0,
      "stackMeta": 0,
      "needsSupportBlock": false
    },
    {
      "x": 5,
      "y": 2,
      "z": 4,
      "block": "minecraft:log",
      "worldMeta": 0,
      "stackMeta": 0,
      "needsSupportBlock": false
    },
    {
      "x": 5,
      "y": 2,
      "z": 5,
      "block": "minecraft:planks",
      "worldMeta": 0,
      "stackMeta": 0,
      "needsSupportBlock": false
    },
    {
      "x": 5,
      "y": 2,
      "z": 6,
      "block": "minecraft:planks",
      "worldMeta": 0,
      "stackMeta": 0,
      "needsSupportBlock": false
    },
    {
      "x": 5,
      "y": 2,
      "z": 7,
      "block": "minecraft:log",
      "worldMeta": 0,
      "stackMeta": 0,
      "needsSupportBlock": false
    },
    {
      "x": 5,
      "y": 3,
      "z": 1,
      "block": "minecraft:log",
      "worldMeta": 0,
      "stackMeta": 0,
      "needsSupportBlock": false
    },
    {
      "x": 5,
      "y": 3,
      "z": 2,
      "block": "minecraft:log",
      "worldMeta": 8,
      "stackMeta": 0,
      "needsSupportBlock": false,
      "rotationMetaTransform": [
        4,
        8,
        4,
        8
      ]
    },
    {
      "x": 5,
      "y": 3,
      "z": 3,
      "block": "minecraft:log",
      "worldMeta": 8,
      "stackMeta": 0,
      "needsSupportBlock": false,
      "rotationMetaTransform": [
        4,
        8,
        4,
        8
      ]
    },
    {
      "x": 5,
      "y": 3,
      "z": 4,
      "block": "minecraft:log",
      "worldMeta": 0,
      "stackMeta": 0,
      "needsSupportBlock": false
    },
    {
      "x": 5,
      "y": 3,
      "z": 5,
      "block": "minecraft:log",
      "worldMeta": 8,
      "stackMeta": 0,
      "needsSupportBlock": false,
      "rotationMetaTransform": [
        4,
        8,
        4,
        8
      ]
    },
    {
      "x": 5,
      "y": 3,
      "z": 6,
      "block": "minecraft:log",
      "worldMeta": 8,
      "stackMeta": 0,
      "needsSupportBlock": false,
      "rotationMetaTransform": [
        4,
        8,
        4,
        8
      ]
    },
    {
      "x": 5,
      "y": 3,
      "z": 7,
      "block": "minecraft:log",
      "worldMeta": 0,
      "stackMeta": 0,
      "needsSupportBlock": false
    },
    {
      "x": 5,
      "y": 4,
      "z": 0,
      "block": "minecraft:brick_stairs",
      "worldMeta": 4,
      "stackMeta": 0,
      "needsSupportBlock": false,
      "rotationMetaTransform": [
        6,
        5,
        7,
        4
      ]
    },
    {
      "x": 5,
      "y": 4,
      "z": 1,
      "block": "minecraft:log",
      "worldMeta": 0,
      "stackMeta": 0,
      "needsSupportBlock": false
    },
    {
      "x": 5,
      "y": 4,
      "z": 2,
      "block": "minecraft:brick_stairs",
      "worldMeta": 4,
      "stackMeta": 0,
      "needsSupportBlock": false,
      "rotationMetaTransform": [
        6,
        5,
        7,
        4
      ]
    },
    {
      "x": 5,
      "y": 4,
      "z": 3,
      "block": "minecraft:brick_stairs",
      "worldMeta": 4,
      "stackMeta": 0,
      "needsSupportBlock": false,
      "rotationMetaTransform": [
        6,
        5,
        7,
        4
      ]
    },
    {
      "x": 5,
      "y": 4,
      "z": 4,
      "block": "minecraft:log",
      "worldMeta": 0,
      "stackMeta": 0,
      "needsSupportBlock": false
    },
    {
      "x": 5,
      "y": 4,
      "z": 5,
      "block": "minecraft:brick_stairs",
      "worldMeta": 4,
      "stackMeta": 0,
      "needsSupportBlock": false,
      "rotationMetaTransform": [
        6,
        5,
        7,
        4
      ]
    },
    {
      "x": 5,
      "y": 4,
      "z": 6,
      "block": "minecraft:brick_stairs",
      "worldMeta": 4,
      "stackMeta": 0,
      "needsSupportBlock": false,
      "rotationMetaTransform": [
        6,
        5,
        7,
        4
      ]
    },
    {
      "x": 5,
      "y": 4,
      "z": 7,
      "block": "minecraft:log",
      "worldMeta": 0,
      "stackMeta": 0,
      "needsSupportBlock": false
    },
    {
      "x": 5,
      "y": 4,
      "z": 8,
      "block": "minecraft:brick_stairs",
      "worldMeta": 4,
      "stackMeta": 0,
      "needsSupportBlock": false,
      "rotationMetaTransform": [
        6,
        5,
        7,
        4
      ]
    },
    {
      "x": 5,
      "y": 5,
      "z": 0,
      "block": "minecraft:brick_stairs",
      "worldMeta": 1,
      "stackMeta": 0,
      "needsSupportBlock": false,
      "rotationMetaTransform": [
        2,
        1,
        3,
        0
      ]
    },
    {
      "x": 5,
      "y": 5,
      "z": 1,
      "block": "minecraft:brick_stairs",
      "worldMeta": 1,
      "stackMeta": 0,
      "needsSupportBlock": false,
      "rotationMetaTransform": [
        2,
        1,
        3,
        0
      ]
    },
    {
      "x": 5,
      "y": 5,
      "z": 2,
      "block": "minecraft:brick_stairs",
      "worldMeta": 1,
      "stackMeta": 0,
      "needsSupportBlock": false,
      "rotationMetaTransform": [
        2,
        1,
        3,
        0
      ]
    },
    {
      "x": 5,
      "y": 5,
      "z": 3,
      "block": "minecraft:brick_stairs",
      "worldMeta": 1,
      "stackMeta": 0,
      "needsSupportBlock": false,
      "rotationMetaTransform": [
        2,
        1,
        3,
        0
      ]
    },
    {
      "x": 5,
      "y": 5,
      "z": 4,
      "block": "minecraft:brick_stairs",
      "worldMeta": 1,
      "stackMeta": 0,
      "needsSupportBlock": false,
      "rotationMetaTransform": [
        2,
        1,
        3,
        0
      ]
    },
    {
      "x": 5,
      "y": 5,
      "z": 5,
      "block": "minecraft:brick_stairs",
      "worldMeta": 1,
      "stackMeta": 0,
      "needsSupportBlock": false,
      "rotationMetaTransform": [
        2,
        1,
        3,
        0
      ]
    },
    {
      "x": 5,
      "y": 5,
      "z": 6,
      "block": "minecraft:brick_stairs",
      "worldMeta": 1,
      "stackMeta": 0,
      "needsSupportBlock": false,
      "rotationMetaTransform": [
        2,
        1,
        3,
        0
      ]
    },
    {
      "x": 5,
      "y": 5,
      "z": 7,
      "block": "minecraft:brick_stairs",
      "worldMeta": 1,
      "stackMeta": 0,
      "needsSupportBlock": false,
      "rotationMetaTransform": [
        2,
        1,
        3,
        0
      ]
    },
    {
      "x": 5,
      "y": 5,
      "z": 8,
      "block": "minecraft:brick_stairs",
      "worldMeta": 1,
      "stackMeta": 0,
      "needsSupportBlock": false,
      "rotationMetaTransform": [
        2,
        1,
        3,
        0
      ]
    },
    {
      "x": 6,
      "y": 4,
      "z": 0,
      "block": "minecraft:brick_stairs",
      "worldMeta": 1,
      "stackMeta": 0,
      "needsSupportBlock": false,
      "rotationMetaTransform": [
        2,
        1,
        3,
        0
      ]
    },
    {
      "x": 6,
      "y": 4,
      "z": 1,
      "block": "minecraft:brick_stairs",
      "worldMeta": 1,
      "stackMeta": 0,
      "needsSupportBlock": false,
      "rotationMetaTransform": [
        2,
        1,
        3,
        0
      ]
    },
    {
      "x": 6,
      "y": 4,
      "z": 2,
      "block": "minecraft:brick_stairs",
      "worldMeta": 1,
      "stackMeta": 0,
      "needsSupportBlock": false,
      "rotationMetaTransform": [
        2,
        1,
        3,
        0
      ]
    },
    {
      "x": 6,
      "y": 4,
      "z": 3,
      "block": "minecraft:brick_stairs",
      "worldMeta": 1,
      "stackMeta": 0,
      "needsSupportBlock": false,
      "rotationMetaTransform": [
        2,
        1,
        3,
        0
      ]
    },
    {
      "x": 6,
      "y": 4,
      "z": 4,
      "block": "minecraft:brick_stairs",
      "worldMeta": 1,
      "stackMeta": 0,
      "needsSupportBlock": false,
      "rotationMetaTransform": [
        2,
        1,
        3,
        0
      ]
    },
    {
      "x": 6,
      "y": 4,
      "z": 5,
      "block": "minecraft:brick_stairs",
      "worldMeta": 1,
      "stackMeta": 0,
      "needsSupportBlock": false,
      "rotationMetaTransform": [
        2,
        1,
        3,
        0
      ]
    },
    {
      "x": 6,
      "y": 4,
      "z": 6,
      "block": "minecraft:brick_stairs",
      "worldMeta": 1,
      "stackMeta": 0,
      "needsSupportBlock": false,
      "rotationMetaTransform": [
        2,
        1,
        3,
        0
      ]
    },
    {
      "x": 6,
      "y": 4,
      "z": 7,
      "block": "minecraft:brick_stairs",
      "worldMeta": 1,
      "stackMeta": 0,
      "needsSupportBlock": false,
      "rotationMetaTransform": [
        2,
        1,
        3,
        0
      ]
    },
    {
      "x": 6,
      "y": 4,
      "z": 8,
      "block": "minecraft:brick_stairs",
      "worldMeta": 1,
      "stackMeta": 0,
      "needsSupportBlock": false,
      "rotationMetaTransform": [
        2,
        1,
        3,
        0
      ]
    }
  ]
}