{
  "groundLevel": 0,
  "home": [
    4,
    1,
    5
  ],
  "blocks": [
    {
      "x": 0,
      "y": 0,
      "z": 1,
      "block": "minecraft:stone_stairs",
      "worldMeta": 0,
      "stackMeta": 0,
      "needsSupportBlock": false,
      "rotationMetaTransform": [
        2,
        1,
        3,
        0
      ]
    },
    {
      "x": 0,
      "y": 0,
      "z": 2,
      "block": "minecraft:stone_stairs",
      "worldMeta": 0,
      "stackMeta": 0,
      "needsSupportBlock": false,
      "rotationMetaTransform": [
        2,
        1,
        3,
        0
      ]
    },
    {
      "x": 0,
      "y": 0,
      "z": 3,
      "block": "minecraft:stone_stairs",
      "worldMeta": 0,
      "stackMeta": 0,
      "needsSupportBlock": false,
      "rotationMetaTransform": [
        2,
        1,
        3,
        0
      ]
    },
    {
      "x": 0,
      "y": 0,
      "z": 6,
      "block": "minecraft:trapdoor",
      "worldMeta": 14,
      "stackMeta": 0,
      "needsSupportBlock": true,
      "rotationMetaTransform": [
        15,
        13,
        14,
        12
      ]
    },
    {
      "x": 0,
      "y": 0,
      "z": 7,
      "block": "minecraft:log",
      "worldMeta": 0,
      "stackMeta": 0,
      "needsSupportBlock": false
    },
    {
      "x": 0,
      "y": 1,
      "z": 7,
      "block": "minecraft:log",
      "worldMeta": 0,
      "stackMeta": 0,
      "needsSupportBlock": false
    },
    {
      "x": 0,
      "y": 2,
      "z": 6,
      "block": "minecraft:torch",
      "worldMeta": 4,
      "stackMeta": 0,
      "needsSupportBlock": true,
      "rotationMetaTransform": [
        3,
        2,
        4,
        1
      ]
    },
    {
      "x": 0,
      "y": 2,
      "z": 7,
      "block": "minecraft:log",
      "worldMeta": 0,
      "stackMeta": 0,
      "needsSupportBlock": false
    },
    {
      "x": 0,
      "y": 3,
      "z": 7,
      "block": "minecraft:log",
      "worldMeta": 0,
      "stackMeta": 0,
      "needsSupportBlock": false
    },
    {
      "x": 1,
      "y": 0,
      "z": 1,
      "block": "minecraft:stone_stairs",
      "worldMeta": 2,
      "stackMeta": 0,
      "needsSupportBlock": false,
      "rotationMetaTransform": [
        2,
        1,
        3,
        0
      ]
    },
    {
      "x": 1,
      "y": 0,
      "z": 2,
      "block": "minecraft:water",
      "worldMeta": 0,
      "stackMeta": 0,
      "needsSupportBlock": false
    },
    {
      "x": 1,
      "y": 0,
      "z": 3,
      "block": "minecraft:stone_stairs",
      "worldMeta": 3,
      "stackMeta": 0,
      "needsSupportBlock": false,
      "rotationMetaTransform": [
        2,
        1,
        3,
        0
      ]
    },
    {
      "x": 1,
      "y": 0,
      "z": 5,
      "block": "minecraft:trapdoor",
      "worldMeta": 12,
      "stackMeta": 0,
      "needsSupportBlock": true,
      "rotationMetaTransform": [
        15,
        13,
        14,
        12
      ]
    },
    {
      "x": 1,
      "y": 0,
      "z": 6,
      "block": "minecraft:grass",
      "worldMeta": 0,
      "stackMeta": 0,
      "needsSupportBlock": false
    },
    {
      "x": 1,
      "y": 0,
      "z": 7,
      "block": "minecraft:stone_stairs",
      "worldMeta": 7,
      "stackMeta": 0,
      "needsSupportBlock": false,
      "rotationMetaTransform": [
        6,
        5,
        7,
        4
      ]
    },
    {
      "x": 1,
      "y": 1,
      "z": 6,
      "block": "minecraft:double_plant",
      "worldMeta": 4,
      "stackMeta": 4,
      "needsSupportBlock": false
    },
    {
      "x": 1,
      "y": 2,
      "z": 6,
      "block": "minecraft:double_plant",
      "worldMeta": 10,
      "stackMeta": 0,
      "needsSupportBlock": false
    },
    {
      "x": 1,
      "y": 2,
      "z": 7,
      "block": "minecraft:torch",
      "worldMeta": 1,
      "stackMeta": 0,
      "needsSupportBlock": true,
      "rotationMetaTransform": [
        3,
        2,
        4,
        1
      ]
    },
    {
      "x": 1,
      "y": 3,
      "z": 7,
      "block": "minecraft:fence",
      "worldMeta": 0,
      "stackMeta": 0,
      "needsSupportBlock": false
    },
    {
      "x": 2,
      "y": 0,
      "z": 1,
      "block": "minecraft:stone_stairs",
      "worldMeta": 2,
      "stackMeta": 0,
      "needsSupportBlock": false,
      "rotationMetaTransform": [
        2,
        1,
        3,
        0
      ]
    },
    {
      "x": 2,
      "y": 0,
      "z": 2,
      "block": "minecraft:stone_stairs",
      "worldMeta": 1,
      "stackMeta": 0,
      "needsSupportBlock": false,
      "rotationMetaTransform": [
        2,
        1,
        3,
        0
      ]
    },
    {
      "x": 2,
      "y": 0,
      "z": 3,
      "block": "minecraft:stone_stairs",
      "worldMeta": 3,
      "stackMeta": 0,
      "needsSupportBlock": false,
      "rotationMetaTransform": [
        2,
        1,
        3,
        0
      ]
    },
    {
      "x": 2,
      "y": 0,
      "z": 6,
      "block": "minecraft:trapdoor",
      "worldMeta": 15,
      "stackMeta": 0,
      "needsSupportBlock": true,
      "rotationMetaTransform": [
        15,
        13,
        14,
        12
      ]
    },
    {
      "x": 2,
      "y": 0,
      "z": 7,
      "block": "minecraft:stone_stairs",
      "worldMeta": 7,
      "stackMeta": 0,
      "needsSupportBlock": false,
      "rotationMetaTransform": [
        6,
        5,
        7,
        4
      ]
    },
    {
      "x": 2,
      "y": 3,
      "z": 7,
      "block": "minecraft:fence",
      "worldMeta": 0,
      "stackMeta": 0,
      "needsSupportBlock": false
    },
    {
      "x": 3,
      "y": 0,
      "z": 6,
      "block": "minecraft:spruce_stairs",
      "worldMeta": 2,
      "stackMeta": 0,
      "needsSupportBlock": false,
      "rotationMetaTransform": [
        2,
        1,
        3,
        0
      ]
    },
    {
      "x": 3,
      "y": 0,
      "z": 7,
      "block": "minecraft:stone_stairs",
      "worldMeta": 7,
      "stackMeta": 0,
      "needsSupportBlock": false,
      "rotationMetaTransform": [
        6,
        5,
        7,
        4
      ]
    },
    {
      "x": 3,
      "y": 3,
      "z": 7,
      "block": "minecraft:fence",
      "worldMeta": 0,
      "stackMeta": 0,
      "needsSupportBlock": false
    },
    {
      "x": 4,
      "y": 0,
      "z": 1,
      "block": "minecraft:trapdoor",
      "worldMeta": 14,
      "stackMeta": 0,
      "needsSupportBlock": true,
      "rotationMetaTransform": [
        15,
        13,
        14,
        12
      ]
    },
    {
      "x": 4,
      "y": 0,
      "z": 6,
      "block": "minecraft:spruce_stairs",
      "worldMeta": 2,
      "stackMeta": 0,
      "needsSupportBlock": false,
      "rotationMetaTransform": [
        2,
        1,
        3,
        0
      ]
    },
    {
      "x": 4,
      "y": 0,
      "z": 7,
      "block": "minecraft:stone_stairs",
      "worldMeta": 7,
      "stackMeta": 0,
      "needsSupportBlock": false,
      "rotationMetaTransform": [
        6,
        5,
        7,
        4
      ]
    },
    {
      "x": 4,
      "y": 3,
      "z": 7,
      "block": "minecraft:fence",
      "worldMeta": 0,
      "stackMeta": 0,
      "needsSupportBlock": false
    },
    {
      "x": 5,
      "y": 0,
      "z": 0,
      "block": "minecraft:trapdoor",
      "worldMeta": 12,
      "stackMeta": 0,
      "needsSupportBlock": true,
      "rotationMetaTransform": [
        15,
        13,
        14,
        12
      ]
    },
    {
      "x": 5,
      "y": 0,
      "z": 1,
      "block": "minecraft:grass",
      "worldMeta": 0,
      "stackMeta": 0,
      "needsSupportBlock": false
    },
    {
      "x": 5,
      "y": 0,
      "z": 2,
      "block": "minecraft:trapdoor",
      "worldMeta": 13,
      "stackMeta": 0,
      "needsSupportBlock": true,
      "rotationMetaTransform": [
        15,
        13,
        14,
        12
      ]
    },
    {
      "x": 5,
      "y": 0,
      "z": 3,
      "block": "minecraft:spruce_stairs",
      "worldMeta": 0,
      "stackMeta": 0,
      "needsSupportBlock": false,
      "rotationMetaTransform": [
        2,
        1,
        3,
        0
      ]
    },
    {
      "x": 5,
      "y": 0,
      "z": 4,
      "block": "minecraft:spruce_stairs",
      "worldMeta": 0,
      "stackMeta": 0,
      "needsSupportBlock": false,
      "rotationMetaTransform": [
        2,
        1,
        3,
        0
      ]
    },
    {
      "x": 5,
      "y": 0,
      "z": 5,
      "block": "minecraft:spruce_stairs",
      "worldMeta": 0,
      "stackMeta": 0,
      "needsSupportBlock": false,
      "rotationMetaTransform": [
        2,
        1,
        3,
        0
      ]
    },
    {
      "x": 5,
      "y": 0,
      "z": 6,
      "block": "minecraft:grass",
      "worldMeta": 0,
      "stackMeta": 0,
      "needsSupportBlock": false
    },
    {
      "x": 5,
      "y": 0,
      "z": 7,
      "block": "minecraft:stone_stairs",
      "worldMeta": 7,
      "stackMeta": 0,
      "needsSupportBlock": false,
      "rotationMetaTransform": [
        6,
        5,
        7,
        4
      ]
    },
    {
      "x": 5,
      "y": 1,
      "z": 1,
      "block": "minecraft:double_plant",
      "worldMeta": 4,
      "stackMeta": 4,
      "needsSupportBlock": false
    },
    {
      "x": 5,
      "y": 1,
      "z": 6,
      "block": "minecraft:double_plant",
      "worldMeta": 4,
      "stackMeta": 4,
      "needsSupportBlock": false
    },
    {
      "x": 5,
      "y": 2,
      "z": 0,
      "block": "minecraft:torch",
      "worldMeta": 2,
      "stackMeta": 0,
      "needsSupportBlock": true,
      "rotationMetaTransform": [
        3,
        2,
        4,
        1
      ]
    },
    {
      "x": 5,
      "y": 2,
      "z": 1,
      "block": "minecraft:double_plant",
      "worldMeta": 10,
      "stackMeta": 0,
      "needsSupportBlock": false
    },
    {
      "x": 5,
      "y": 2,
      "z": 6,
      "block": "minecraft:double_plant",
      "worldMeta": 10,
      "stackMeta": 0,
      "needsSupportBlock": false
    },
    {
      "x": 5,
      "y": 2,
      "z": 7,
      "block": "minecraft:torch",
      "worldMeta": 2,
      "stackMeta": 0,
      "needsSupportBlock": true,
      "rotationMetaTransform": [
        3,
        2,
        4,
        1
      ]
    },
    {
      "x": 5,
      "y": 3,
      "z": 7,
      "block": "minecraft:fence",
      "worldMeta": 0,
      "stackMeta": 0,
      "needsSupportBlock": false
    },
    {
      "x": 6,
      "y": 0,
      "z": 0,
      "block": "minecraft:log",
      "worldMeta": 0,
      "stackMeta": 0,
      "needsSupportBlock": false
    },
    {
      "x": 6,
      "y": 0,
      "z": 1,
      "block": "minecraft:stone_stairs",
      "worldMeta": 5,
      "stackMeta": 0,
      "needsSupportBlock": false,
      "rotationMetaTransform": [
        6,
        5,
        7,
        4
      ]
    },
    {
      "x": 6,
      "y": 0,
      "z": 2,
      "block": "minecraft:stone_stairs",
      "worldMeta": 5,
      "stackMeta": 0,
      "needsSupportBlock": false,
      "rotationMetaTransform": [
        6,
        5,
        7,
        4
      ]
    },
    {
      "x": 6,
      "y": 0,
      "z": 3,
      "block": "minecraft:stone_stairs",
      "worldMeta": 5,
      "stackMeta": 0,
      "needsSupportBlock": false,
      "rotationMetaTransform": [
        6,
        5,
        7,
        4
      ]
    },
    {
      "x": 6,
      "y": 0,
      "z": 4,
      "block": "minecraft:stone_stairs",
      "worldMeta": 5,
      "stackMeta": 0,
      "needsSupportBlock": false,
      "rotationMetaTransform": [
        6,
        5,
        7,
        4
      ]
    },
    {
      "x": 6,
      "y": 0,
      "z": 5,
      "block": "minecraft:stone_stairs",
      "worldMeta": 5,
      "stackMeta": 0,
      "needsSupportBlock": false,
      "rotationMetaTransform": [
        6,
        5,
        7,
        4
      ]
    },
    {
      "x": 6,
      "y": 0,
      "z": 6,
      "block": "minecraft:stone_stairs",
      "worldMeta": 5,
      "stackMeta": 0,
      "needsSupportBlock": false,
      "rotationMetaTransform": [
        6,
        5,
        7,
        4
      ]
    },
    {
      "x": 6,
      "y": 0,
      "z": 7,
      "block": "minecraft:log",
      "worldMeta": 0,
      "stackMeta": 0,
      "needsSupportBlock": false
    },
    {
      "x": 6,
      "y": 1,
      "z": 0,
      "block": "minecraft:log",
      "worldMeta": 0,
      "stackMeta": 0,
      "needsSupportBlock": false
    },
    {
      "x": 6,
      "y": 1,
      "z": 7,
      "block": "minecraft:log",
      "worldMeta": 0,
      "stackMeta": 0,
      "needsSupportBlock": false
    },
    {
      "x": 6,
      "y": 2,
      "z": 0,
      "block": "minecraft:log",
      "worldMeta": 0,
      "stackMeta": 0,
      "needsSupportBlock": false
    },
    {
      "x": 6,
      "y": 2,
      "z": 1,
      "block": "minecraft:torch",
      "worldMeta": 3,
      "stackMeta": 0,
      "needsSupportBlock": true,
      "rotationMetaTransform": [
        3,
        2,
        4,
        1
      ]
    },
    {
      "x": 6,
      "y": 2,
      "z": 6,
      "block": "minecraft:torch",
      "worldMeta": 4,
      "stackMeta": 0,
      "needsSupportBlock": true,
      "rotationMetaTransform": [
        3,
        2,
        4,
        1
      ]
    },
    {
      "x": 6,
      "y": 2,
      "z": 7,
      "block": "minecraft:log",
      "worldMeta": 0,
      "stackMeta": 0,
      "needsSupportBlock": false
    },
    {
      "x": 6,
      "y": 3,
      "z": 0,
      "block": "minecraft:log",
      "worldMeta": 0,
      "stackMeta": 0,
      "needsSupportBlock": false
    },
    {
      "x": 6,
      "y": 3,
      "z": 1,
      "block": "minecraft:fence",
      "worldMeta": 0,
      "stackMeta": 0,
      "needsSupportBlock": false
    },
    {
      "x": 6,
      "y": 3,
      "z": 2,
      "block": "minecraft:fence",
      "worldMeta": 0,
      "stackMeta": 0,
      "needsSupportBlock": false
    },
    {
      "x": 6,
      "y": 3,
      "z": 3,
      "block": "minecraft:fence",
      "worldMeta": 0,
      "stackMeta": 0,
      "needsSupportBlock": false
    },
    {
      "x": 6,
      "y": 3,
      "z": 4,
      "block": "minecraft:fence",
      "worldMeta": 0,
      "stackMeta": 0,
      "needsSupportBlock": false
    },
    {
      "x": 6,
      "y": 3,
      "z": 5,
      "block": "minecraft:fence",
      "worldMeta": 0,
      "stackMeta": 0,
      "needsSupportBlock": false
    },
    {
      "x": 6,
      "y": 3,
      "z": 6,
      "block": "minecraft:fence",
      "worldMeta": 0,
      "stackMeta": 0,
      "needsSupportBlock": false
    },
    {
      "x": 6,
      "y": 3,
      "z": 7,
      "block": "minecraft:log",
      "worldMeta": 0,
      "stackMeta": 0,
      "needsSupportBlock": false
    }
  ]
}